Workbook

Sheet الملخص
A1: ملخص إجمالي مبيعات المناديب – مزرعة الرياض
A2: الفترة: من 31-7-2025 إلى 31-7-2026 – مبيعات الجملة (عقود WHT/WHE/WHK) + مبيعات السيارات لشهري 6 و7 لسنة 2026
A4: المندوب | B4: مبيعات الجملة حسب المحاسب | C4: مبيعات الجملة بعد المراجعة | D4: الفرق | E4: مبيعات السيارة 6-7 (صافي بعد المرتجع) | F4: الإجمالي النهائي | G4: السيارة
A5: عصمت الله خان | B5: ='عصمت - جملة WHT'!D213 | C5: ='عصمت - جملة WHT'!E213 | D5: =C5-B5 | E5: =SUMIFS('مبيعات السيارات 6-7 2026'!H2:H57,'مبيعات السيارات 6-7 2026'!C2:C57,"VHC-1219") | F5: =C5+E5 | G5: VHC-1219
A6: عماد حمدي | B6: ='عماد - جملة WHE'!D47 | C6: ='عماد - جملة WHE'!E47 | D6: =C6-B6 | E6: =SUMIFS('مبيعات السيارات 6-7 2026'!H2:H57,'مبيعات السيارات 6-7 2026'!C2:C57,"VHC-3010") | F6: =C6+E6 | G6: VHC-3010
A7: م/ عادل أبو خالد | B7: ='أبو خالد - جملة WHK'!D49 | C7: ='أبو خالد - جملة WHK'!E49 | D7: =C7-B7 | E7: 0 | F7: =C7+E7 | G7: —
A8: الإجمالي | B8: =SUM(B5:B7) | C8: =SUM(C5:C7) | D8: =SUM(D5:D7) | E8: =SUM(E5:E7) | F8: =SUM(F5:F7)
A10: ملاحظات المراجعة (كل الأرقام بالقيمة الإجمالية كما هي بالمستندات):
A11: 1) عصمت (WHT): شيت المحاسب مكتوب "من 9-10-2025" لكنه أدرج عقوداً من يوليو–سبتمبر، وأسقط 4 عقود من 1 إلى 8 أكتوبر (WHT-2348/2358/2378/2408 = 21,087.50) فتمت إضافتها.
A12: 2) عصمت: عقدان WHT-2756 و WHT-2758 (16,810.00) موجودان في سجل العقود فقط، بدون فاتورة مبدئية ولا قيد في الكشف – تمت إضافتهما.
A13: 3) عصمت: 3 عقود مكررة الرقم في شيت المحاسب (WHT-3786 و WHT-4052 و WHT-4234) – القيم صحيحة والأرقام الصحيحة WHT-3804 و WHT-4062 و WHT-4243.
A14: 4) العقدان WHT-1908 (16,658.75) و WHK-1909 (11,570.00) بتاريخ 30-7-2025 (قبل بداية الفترة بيوم) – أُدرجا بناءً على طلبك.
A15: 5) أبو خالد (WHK): عقد عرعر WHK-2364 أُدرج بالقيمة الكاملة 440,000 بناءً على طلبك، علماً بأن المسجل بكشف الحساب 367,803.75 (الفرق 72,196.25 بدون قيد بالكشف).
A16: 6) أبو خالد: العقد WHK-3400 (505.00 – فاتورة 103) سقط من شيت المحاسب فتمت إضافته.
A17: 7) عماد (WHE): الشيت مطابق تماماً للفواتير المبدئية وسجل العقود (45 عقد).
A18: 8) مبيعات السيارات: السيارة 1219 = عصمت، والسيارة 3010 = عماد. إجمالي المحاسب للسيارة 1219 (38,733.08) لم يخصم 3 فواتير مرتجعة بالكامل (4,123.90) فالصافي 34,609.18. شيت المرتجعات فيه صفّان مكرران (WS-RET-0002 و 0003).
A19: 9) بعض التواريخ في ملفات المحاسب مقلوبة (يوم/شهر) مثل 2026-11-07 وهي 7-11 أي 11 يوليو – تم تصحيحها.

Sheet عصمت - جملة WHT
A1: م | B1: التاريخ | C1: رقم العقد | D1: القيمة بشيت المحاسب | E1: القيمة المعتمدة | F1: الحالة | G1: المستندات المؤيدة | H1: ملاحظة
A2: 1 | B2: 45868 | C2: WHT-1908 | D2: 16658.75 | E2: 16658.75 | F2: صحيح (ملاحظة) | G2: سجل العقود | H2: تاريخه 2025-07-30 قبل بداية الفترة 31-7-2025 بيوم – أُدرج بناءً على طلبك
A3: 2 | B3: 45878 | C3: WHT-1892 | D3: 150 | E3: 150 | F3: صحيح | G3: سجل العقود
A4: 3 | B4: 45885 | C4: WHT-1934 | D4: 162.5 | E4: 162.5 | F4: صحيح | G4: سجل العقود
A5: 4 | B5: 45885 | C5: WHT-1937 | D5: 50 | E5: 50 | F5: صحيح | G5: سجل العقود
A6: 5 | B6: 45887 | C6: WHT-1952 | D6: 450 | E6: 450 | F6: صحيح | G6: سجل العقود
A7: 6 | B7: 45889 | C7: WHT-1970 | D7: 125 | E7: 125 | F7: صحيح | G7: سجل العقود
A8: 7 | B8: 45890 | C8: WHT-1999 | D8: 800 | E8: 800 | F8: صحيح | G8: سجل العقود
A9: 8 | B9: 45892 | C9: WHT-2007 | D9: 155 | E9: 155 | F9: صحيح | G9: سجل العقود
A10: 9 | B10: 45894 | C10: WHT-2030 | D10: 350 | E10: 350 | F10: صحيح | G10: سجل العقود
A11: 10 | B11: 45895 | C11: WHT-2040 | D11: 205 | E11: 205 | F11: صحيح | G11: سجل العقود
A12: 11 | B12: 45897 | C12: WHT-2065 | D12: 62.5 | E12: 62.5 | F12: صحيح | G12: سجل العقود
A13: 12 | B13: 45901 | C13: WHT-2084 | D13: 202.5 | E13: 202.5 | F13: صحيح | G13: سجل العقود
A14: 13 | B14: 45904 | C14: WHT-2112 | D14: 517.5 | E14: 517.5 | F14: صحيح | G14: سجل العقود
... A31: 30 | B31: 45930 | C31: WHT-2344 | D31: 2485 | E31: 2485 | F31: صحيح | G31: سجل العقود
A32: 31 | B32: 45931 | C32: WHT-2348 | D32: 0 | E32: 3920 | F32: مضاف | G32: سجل العقود | H32: موجود في سجل العقود وسقط من شيت المحاسب (المحاسب بدأ من 9-10 رغم إدراجه عقود أقدم)
A33: 32 | B33: 45932 | C33: WHT-2358 | D33: 0 | E33: 4910 | F33: مضاف | G33: سجل العقود | H33: موجود في سجل العقود وسقط من شيت المحاسب (المحاسب بدأ من 9-10 رغم إدراجه عقود أقدم)
A34: 33 | B34: 45934 | C34: WHT-2378 | D34: 0 | E34: 4760 | F34: مضاف | G34: سجل العقود | H34: موجود في سجل العقود وسقط من شيت المحاسب (المحاسب بدأ من 9-10 رغم إدراجه عقود أقدم)
A35: 34 | B35: 45935 | C35: WHT-2756 | D35: 0 | E35: 3520 | F35: مضاف | G35: سجل العقود | H35: موجود في سجل العقود فقط (بدون فاتورة مبدئية وغير مسجل بالكشف) – يحتاج تأكيد
A36: 35 | B36: 45936 | C36: WHT-2758 | D36: 0 | E36: 13290 | F36: مضاف | G36: سجل العقود | H36: موجود في سجل العقود فقط (بدون فاتورة مبدئية وغير مسجل بالكشف) – يحتاج تأكيد
A37: 36 | B37: 45938 | C37: WHT-2408 | D37: 0 | E37: 7497.5 | F37: مضاف | G37: سجل العقود | H37: موجود في سجل العقود وسقط من شيت المحاسب (المحاسب بدأ من 9-10 رغم إدراجه عقود أقدم)
A38: 37 | B38: 45939 | C38: WHT-2423 | D38: 5790 | E38: 5790 | F38: صحيح | G38: سجل العقود
A39: 38 | B39: 45941 | C39: WHT-2437 | D39: 10270 | E39: 10270 | F39: صحيح | G39: سجل العقود
A40: 39 | B40: 45942 | C40: WHT-2454 | D40: 6282.5 | E40: 6282.5 | F40: صحيح | G40: سجل العقود
A41: 40 | B41: 45943 | C41: WHT-2471 | D41: 3275 | E41: 3275 | F41: صحيح | G41: سجل العقود
A42: 41 | B42: 45944 | C42: WHT-2483 | D42: 6077.5 | E42: 6077.5 | F42: صحيح | G42: سجل العقود
A43: 42 | B43: 45945 | C43: WHT-2501 | D43: 6087.5 | E43: 6087.5 | F43: صحيح | G43: سجل العقود
A44: 43 | B44: 45946 | C44: WHT-2511 | D44: 3365 | E44: 3365 | F44: صحيح | G44: سجل العقود
A45: 44 | B45: 45949 | C45: WHT-2541 | D45: 8378.75 | E45: 8378.75 | F45: صحيح | G45: سجل العقود
A46: 45 | B46: 45950 | C46: WHT-2549 | D46: 6680 | E46: 6680 | F46: صحيح | G46: سجل العقود
A47: 46 | B47: 45951 | C47: WHT-2585 | D47: 2355 | E47: 2355 | F47: صحيح | G47: سجل العقود
A48: 47 | B48: 45952 | C48: WHT-2596 | D48: 4715 | E48: 4715 | F48: صحيح | G48: سجل العقود
A49: 48 | B49: 45953 | C49: WHT-2607 | D49: 5998.75 | E49: 5998.75 | F49: صحيح | G49: سجل العقود
... A133: 132 | B133: 46062 | C133: WHT-3786 | D133: 6900 | E133: 6900 | F133: صحيح | G133: فاتورة مبدئية 147، سجل العقود، كشف الحساب
A134: 133 | B134: 46063 | C134: WHT-3804 | D134: 4472.5 | E134: 4472.5 | F134: صحيح (تصحيح رقم) | G134: فاتورة مبدئية 148، سجل العقود | H134: رقم العقد مكرر في شيت المحاسب – الصحيح WHT-3804
A135: 134 | B135: 46064 | C135: WHT-3814 | D135: 6267.5 | E135: 6267.5 | F135: صحيح | G135: فاتورة مبدئية 150، سجل العقود، كشف الحساب
A136: 135 | B136: 46065 | C136: WHT-3828 | D136: 5862.5 | E136: 5862.5 | F136: صحيح | G136: فاتورة مبدئية 151، سجل العقود، كشف الحساب
A137: 136 | B137: 46067 | C137: WHT-3837 | D137: 7380 | E137: 7380 | F137: صحيح | G137: فاتورة مبدئية 153، سجل العقود، كشف الحساب
A138: 137 | B138: 46068 | C138: WHT-3851 | D138: 5520 | E138: 5520 | F138: صحيح | G138: فاتورة مبدئية 155، سجل العقود، كشف الحساب
A139: 138 | B139: 46069 | C139: WHT-3857 | D139: 5447.75 | E139: 5447.75 | F139: صحيح | G139: فاتورة مبدئية 156، سجل العقود، كشف الحساب
...

Sheet عماد - جملة WHE
A1: م | B1: التاريخ | C1: رقم العقد | D1: القيمة بشيت المحاسب | E1: القيمة المعتمدة | F1: الحالة | G1: المستندات المؤيدة | H1: ملاحظة
A2: 1 | B2: 45983 | C2: WHE-2973 | D2: 6315 | E2: 6315 | F2: صحيح | G2: فاتورة مبدئية 62، سجل العقود، كشف الحساب
A3: 2 | B3: 45987 | C3: WHE-3011 | D3: 8300.5 | E3: 8300.5 | F3: صحيح | G3: فاتورة مبدئية 67، سجل العقود، كشف الحساب
A4: 3 | B4: 45989 | C4: WHE-3041 | D4: 7387.5 | E4: 7387.5 | F4: صحيح | G4: فاتورة مبدئية 70، سجل العقود، كشف الحساب
A5: 4 | B5: 45991 | C5: WHE-3076 | D5: 8400 | E5: 8400 | F5: صحيح | G5: فاتورة مبدئية 73، سجل العقود، كشف الحساب
A6: 5 | B6: 46002 | C6: WHE-3212 | D6: 10731.25 | E6: 10731.25 | F6: صحيح | G6: فاتورة مبدئية 85، سجل العقود، كشف الحساب
A7: 6 | B7: 46006 | C7: WHE-3245 | D7: 4845.5 | E7: 4845.5 | F7: صحيح | G7: فاتورة مبدئية 90، سجل العقود، كشف الحساب
A8: 7 | B8: 46008 | C8: WHE-3274 | D8: 6818.5 | E8: 6818.5 | F8: صحيح | G8: فاتورة مبدئية 94، سجل العقود، كشف الحساب
A9: 8 | B9: 46021 | C9: WHE-3402 | D9: 6097.5 | E9: 6097.5 | F9: صحيح | G9: فاتورة مبدئية 104، كشف الحساب
A10: 9 | B10: 46024 | C10: WHE-3424 | D10: 6577.5 | E10: 6577.5 | F10: صحيح | G10: فاتورة مبدئية 106، سجل العقود، كشف الحساب
A11: 10 | B11: 46027 | C11: WHE-3475 | D11: 8985 | E11: 8985 | F11: صحيح | G11: فاتورة مبدئية 111، سجل العقود، كشف الحساب
A12: 11 | B12: 46037 | C12: WHE-3570 | D12: 8562.5 | E12: 8562.5 | F12: صحيح | G12: فاتورة مبدئية 120، سجل العقود، كشف الحساب
A13: 12 | B13: 46042 | C13: WHE-3615 | D13: 6699.5 | E13: 6699.5 | F13: صحيح | G13: فاتورة مبدئية 124، سجل العقود، كشف الحساب
... A46: 45 | B46: 46176 | C46: WHE-4358 | D46: 4810 | E46: 4810 | F46: صحيح | G46: فاتورة مبدئية 262، كشف الحساب
C47: الإجمالي | D47: =SUM(D2:D46) | E47: =SUM(E2:E46)

Sheet أبو خالد - جملة WHK
A1: م | B1: التاريخ | C1: رقم العقد | D1: القيمة بشيت المحاسب | E1: القيمة المعتمدة | F1: الحالة | G1: المستندات المؤيدة | H1: ملاحظة
A2: 1 | B2: 45868 | C2: WHK-1909 | D2: 11570 | E2: 11570 | F2: صحيح (ملاحظة) | G2: لا يوجد مستند مؤيد | H2: تاريخه 2025-07-30 قبل بداية الفترة 31-7-2025 بيوم – أُدرج بناءً على طلبك
A3: 2 | B3: 45909 | C3: WHK-2148 | D3: 3320 | E3: 3320 | F3: صحيح | G3: لا يوجد مستند مؤيد
A4: 3 | B4: 45923 | C4: WHK-2271 | D4: 2400 | E4: 2400 | F4: صحيح | G4: لا يوجد مستند مؤيد
A5: 4 | B5: 45924 | C5: WHK-2283 | D5: 2800 | E5: 2800 | F5: صحيح | G5: لا يوجد مستند مؤيد
A6: 5 | B6: 45929 | C6: WHK-2328 | D6: 4550 | E6: 4550 | F6: صحيح | G6: لا يوجد مستند مؤيد
A7: 6 | B7: 45935 | C7: WHK-2364 | D7: 440000 | E7: 440000 | F7: صحيح (ملاحظة) | G7: كشف الحساب | H7: عقد عرعر – أُدرج بالقيمة الكاملة 440,000.00 بناءً على طلبك. المسجل بكشف الحساب (7 قيود) 367,803.75 – الفرق 72,196.25 بدون قيد بالكشف
A8: 7 | B8: 45938 | C8: WHK-2411 | D8: 4200 | E8: 4200 | F8: صحيح | G8: لا يوجد مستند مؤيد
A9: 8 | B9: 45939 | C9: WHK-2425 | D9: 11000 | E9: 11000 | F9: صحيح | G9: لا يوجد مستند مؤيد
A10: 9 | B10: 45941 | C10: WHK-2434 | D10: 70250 | E10: 70250 | F10: صحيح | G10: لا يوجد مستند مؤيد
A11: 10 | B11: 45943 | C11: WHK-2465 | D11: 1750 | E11: 1750 | F11: صحيح | G11: لا يوجد مستند مؤيد
A12: 11 | B12: 45944 | C12: WHK-2480 | D12: 412.5 | E12: 412.5 | F12: صحيح | G12: لا يوجد مستند مؤيد
A13: 12 | B13: 45945 | C13: WHK-2498 | D13: 17055 | E13: 17055 | F13: صحيح | G13: لا يوجد مستند مؤيد
A14: 13 | B14: 45946 | C14: WHK-2509 | D14: 3150 | E14: 3150 | F14: صحيح | G14: لا يوجد مستند مؤيد
A15: 14 | B15: 45948 | C15: WHK-2515 | D15: 6975 | E15: 6975 | F15: صحيح | G15: لا يوجد مستند مؤيد
A16: 15 | B16: 45951 | C16: WHK-2563 | D16: 2925 | E16: 2925 | F16: صحيح | G16: لا يوجد مستند مؤيد
A17: 16 | B17: 45952 | C17: WHK-2583 | D17: 4125 | E17: 4125 | F17: صحيح | G17: لا يوجد مستند مؤيد
A18: 17 | B18: 45953 | C18: WHK-2605 | D18: 1331.25 | E18: 1331.25 | F18: صحيح | G18: لا يوجد مستند مؤيد
A19: 18 | B19: 45955 | C19: WHK-2626 | D19: 2150 | E19: 2150 | F19: صحيح | G19: لا يوجد مستند مؤيد
... A36: 35 | B36: 46006 | C36: WHK-3243 | D36: 1875 | E36: 1875 | F36: صحيح | G36: فاتورة مبدئية 89، كشف الحساب
A37: 36 | B37: 46021 | C37: WHK-3400 | D37: 0 | E37: 505 | F37: مضاف | G37: فاتورة مبدئية 103، كشف الحساب | H37: فاتورة مبدئية 103 ومسجلة بكشف الحساب – سقطت من شيت المحاسب
A38: 37 | B38: 46058 | C38: WHK-3758 | D38: 20300 | E38: 20300 | F38: صحيح | G38: فاتورة مبدئية 140، كشف الحساب
A39: 38 | B39: 46058 | C39: WHK-3760 | D39: 30850 | E39: 30850 | F39: صحيح | G39: فاتورة مبدئية 141، كشف الحساب
A40: 39 | B40: 46064 | C40: WHK-3809 | D40: 3125 | E40: 3125 | F40: صحيح | G40: فاتورة مبدئية 149، كشف الحساب
A41: 40 | B41: 46072 | C41: WHK-3878 | D41: 2012.5 | E41: 2012.5 | F41: صحيح | G41: فاتورة مبدئية 160، كشف الحساب
A42: 41 | B42: 46084 | C42: WHK-3923 | D42: 6862.5 | E42: 6862.5 | F42: صحيح | G42: فاتورة مبدئية 166، كشف الحساب
A43: 42 | B43: 46085 | C43: WHK-3963 | D43: 2700 | E43: 2700 | F43: صحيح | G43: فاتورة مبدئية 174، كشف الحساب
A44: 43 | B44: 46145 | C44: WHK-4256 | D44: 19490 | E44: 19490 | F44: صحيح | G44: فاتورة مبدئية 227، كشف الحساب
A45: 44 | B45: 46147 | C45: WHK-4275 | D45: 21780 | E45: 21780 | F45: صحيح | G45: فاتورة مبدئية 231، كشف الحساب
A46: 45 | B46: 46152 | C46: WHK-4291 | D46: 3135 | E46: 3135 | F46: صحيح | G46: فاتورة مبدئية 239، كشف الحساب
A47: 46 | B47: 46154 | C47: WHK-4305 | D47: 3025 | E47: 3025 | F47: صحيح | G47: فاتورة مبدئية 243، كشف الحساب
A48: 47 | B48: 46160 | C48: WHK-4323 | D48: 750 | E48: 750 | F48: صحيح | G48: فاتورة مبدئية 250، كشف الحساب
C49: الإجمالي | D49: =SUM(D2:D48) | E49: =SUM(E2:E48)

Sheet مبيعات السيارات 6-7 2026
A1: رقم الفاتورة | B1: التاريخ | C1: السيارة | D1: المندوب | E1: العميل | F1: قيمة الفاتورة | G1: الحالة | H1: الصافي بعد المرتجع | I1: الشهر
A2: WS-INV-0038 | B2: 46186 | C2: VHC-1219 | D2: عصمت الله خان | E2: مشاتل طريق ملك عبدالله-الرياض | F2: 340.5 | G2: مكتمل | H2: 340.5 | I2: 6-2026
A3: WS-INV-0035 | B3: 46186 | C3: VHC-1219 | D3: عصمت الله خان | E3: مشاتل مخرج 15-الرياض | F3: 2135 | G3: مكتمل | H3: 2135 | I3: 6-2026
A4: WS-INV-0034 | B4: 46186 | C4: VHC-1219 | D4: عصمت الله خان | E4: مشتل سالم-الرياض | F4: 105 | G4: مكتمل | H4: 105 | I4: 6-2026
A5: WS-INV-0002 | B5: 46186 | C5: VHC-1219 | D5: عصمت الله خان | E5: مشتل نسيم الصبا - الرياض | F5: 310 | G5: مكتمل | H5: 310 | I5: 6-2026
A6: WS-INV-0001 | B6: 46186 | C6: VHC-1219 | D6: عصمت الله خان | E6: مشتل عبدالقادر-الرياض | F6: 2007.5 | G6: مكتمل | H6: 2007.5 | I6: 6-2026
A7: WS-INV-0048 | B7: 46187 | C7: VHC-1219 | D7: عصمت الله خان | E7: مشتل حي لبن - الرياض | F7: 2250 | G7: مكتمل | H7: 2250 | I7: 6-2026
A8: WS-INV-0040 | B8: 46187 | C8: VHC-1219 | D8: عصمت الله خان | E8: مشاتل طريق مخرج 8-الرياض | F8: 1967 | G8: مكتمل | H8: 1967 | I8: 6-2026
A9: WS-INV-0039 | B9: 46187 | C9: VHC-1219 | D9: عصمت الله خان | E9: مشاتل طريق خريص-الرياض | F9: 2310 | G9: مكتمل | H9: 2310 | I9: 6-2026
A10: WS-INV-0056 | B10: 46189 | C10: VHC-1219 | D10: عصمت الله خان | E10: مشاتل طريق خريص-الرياض | F10: 952.5 | G10: مكتمل | H10: 952.5 | I10: 6-2026
A11: WS-INV-0063 | B11: 46190 | C11: VHC-1219 | D11: عصمت الله خان | E11: مشتل سالم-الرياض | F11: 767 | G11: مكتمل | H11: 767 | I11: 6-2026
A12: WS-INV-0072 | B12: 46191 | C12: VHC-1219 | D12: عصمت الله خان | E12: مشاتل مخرج 15-الرياض | F12: 1167 | G12: مكتمل | H12: 1167 | I12: 6-2026
A13: WS-INV-0082 | B13: 46193 | C13: VHC-1219 | D13: عصمت الله خان | E13: مشتل زهور الرياض - الرياض | F13: 1688.2 | G13: مرتجع بالكامل | H13: 0 | I13: 6-2026
... A57: WS-INV-0255 | B57: 46233 | C57: VHC-3010 | D57: عماد حمدي | E57: مؤسسة فارس علي السالمي التجارية ( اسماعيل ) - الرياض | F57: 75 | G57: مكتمل | H57: 75 | I57: 7-2026
E58: الإجمالي | F58: =SUM(F2:F57) | H58: =SUM(H2:H57)
