Workbook

Sheet الفهرس
A1: ملف المراجعة الشامل – مزرعة الرياض (من التأسيس حتى 31-7-2026)
A2: م | B2: القسم | C2: الصفحة (اضغط للانتقال) | D2: المحتوى
A3: 1 | B3: عام | C3: الملخص العام | D3: الأرقام الرئيسية لكل الأقسام في صفحة واحدة
A4: 2 | B4: عام | C4: الأسئلة المطلوبة | D4: كل الأسئلة المفتوحة مع المبلغ المتأثر وخانة للإجابة
A5: 3 | B5: حساب الشريكين | C5: ملخص الشركاء | D5: مسحوبات ودعم وسدادات كل شريك والصافي
A6: 4 | B6: حساب الشريكين | C6: حساب أبو خالد | D6: تفصيل حساب أبو خالد / بساتين الرياض
A7: 5 | B7: حساب الشريكين | C7: حساب أبو مازن | D7: تفصيل حساب أبو مازن / نسما الشرق
A8: 6 | B8: حساب الشريكين | C8: إيرادات قبل الفترة | D8: تسوية إيرادات 610,688 قبل 30-7-2025
A9: 7 | B9: حساب الشريكين | C9: تحقق سند أبو خالد | D9: مطابقة سند مسحوبات بساتين 24.2–3.6.2026 مع الفواتير
A10: 8 | B10: المبيعات | C10: مبيعات - الملخص | D10: إجمالي مبيعات كل مندوب + ما قبل الفترة
A11: 9 | B11: المبيعات | C11: الحركة المدمجة | D11: كل حركات البيع (جملة + سيارات) مرتبة بالتاريخ
A12: 10 | B12: المبيعات | C12: مبيعات - شهري | D12: المبيعات الشهرية لكل مندوب من 10-2024
A13: 11 | B13: المبيعات | C13: مبيعات قبل 30.7.2025 | D13: مبيعات 10-2024 إلى 6-2025 شهرياً
A14: 12 | B14: المبيعات | C14: مبيعات عصمت | D14: كل عقود عصمت + فواتير سيارة 1219
... A49: 47 | B49: المصروفات | C49: ميزان الخزنة | D49: ميزان الخزنة القديمة قبل وبعد حذف الجزيرة ومطابقته مع رصيد النظام الجديد

Sheet الملخص العام
A1: مزرعة الرياض – الملخص العام من التأسيس (2024) حتى 31-7-2026
A2: الشركاء: م/ عادل أبو خالد (مؤسسة بساتين الرياض) – أبو مازن (شركة نسما الشرق / مزرعة تبوك)
A4: أولاً: المبيعات
A5: مبيعات قبل 30-7-2025 (1-10-2024 إلى 30-6-2025) | B5: ='مبيعات قبل 30.7.2025'!C12 | D5: إجمالي شهري غير موزع على المناديب
A6: مبيعات عصمت الله خان (جملة WHT + سيارة 1219) | B6: ='مبيعات - الملخص'!D5
A7: مبيعات عماد حمدي (جملة WHE + سيارة 3010) | B7: ='مبيعات - الملخص'!D6
A8: مبيعات م/ عادل أبو خالد (عقود WHK شاملة عرعر 440,000) | B8: ='مبيعات - الملخص'!D7
A9: إجمالي المبيعات من 1-10-2024 إلى 31-7-2026 | B9: =SUM(B5:B8)
A11: ثانياً: المصروفات
A12: مصروفات التأسيس الفعلية (أبو مازن 1,089,735.80 + أبو خالد 189,235) | B12: ='مصروفات التأسيس'!E29
A13: مصروفات تشغيل 2-2024 إلى 12-2024 | B13: ='مصروفات قبل 30.7.2025'!E28 | D13: من إيرادات المزرعة
A14: مصروفات تشغيل دفعها م/ عادل من المبيعات (10-2024 إلى 6-2025) | B14: ='مصروفات قبل 30.7.2025'!E42 | D14: من إيرادات المزرعة
A15: مصروفات 2025 (7-2025 إلى 12-2025) | B15: ='مصروفات 2025 - تفصيل'!H301 | D15: شاملة مشتريات عقد عرعر
A16: أوامر شراء 2026 بعد استبعاد سداد 2025 + تسويات العهد | B16: ='مصروفات - الملخص'!C15
A17: مصروفات الخزنة (كشف الحساب) (كشف الحساب) | B17: ='مصروفات الخزنة (كشف الحساب)'!F197 | D17: ⚠ متداخلة جزئياً مع أوامر الشراء والعهد ومصروفات 2025 – راجع عمود الارتباط
A18: المصاريف الإدارية والديزل المدفوعة من نسما | B18: ='مصاريف إدارية وديزل تبوك'!F48
A20: ثالثاً: حركات المواد (30-7-2025 إلى 31-7-2026)
A21: TNR ترحيل من تبوك إلى الرياض | B21: ='مواد - الملخص'!J5
A22: RNT ترحيل من الرياض إلى تبوك | B22: ='مواد - الملخص'!J6
A23: RNP ترحيل لقسم المشاريع تبوك | B23: ='مواد - الملخص'!J7
A24: RNO صرف للإنتاج | B24: ='مواد - الملخص'!J8
A25: RNL هالك ومفقود | B25: ='مواد - الملخص'!J9
A27: خامساً: الآجل
A28: المبالغ الآجلة لدى عملاء السيارات (31-7-2026) | B28: ='أرصدة العملاء والموردين'!F29 | D28: راجع صفحة أرصدة العملاء والموردين
A29: المستحق للموردين (حد أقصى) | B29: ='أرصدة العملاء والموردين'!F41 | D29: PO-1023 33,950 + باقي PO-0777 55,420
A31: رابعاً: حساب الشريكين
A32: البند | B32: أبو خالد – بساتين الرياض | C32: أبو مازن – نسما الشرق
A33: إجمالي المسحوبات (عليه) | B33: ='ملخص الشركاء'!B7 | C33: ='ملخص الشركاء'!C7
A34: سدادات مسجلة بكشف الخزنة | B34: ='ملخص الشركاء'!B8 | C34: ='ملخص الشركاء'!C8
A35: الدعم المقدم للمزرعة | B35: ='ملخص الشركاء'!B9 | C35: ='ملخص الشركاء'!C9
A36: الصافي (موجب = عليه للمزرعة / سالب = مستحق له) | B36: ='ملخص الشركاء'!B11 | C36: ='ملخص الشركاء'!C11 | D36: ⚠ نهائي بعد الإجابة على الأسئلة المفتوحة
A38: تنبيه: الأرقام تتحدّث تلقائياً من صفحات التفصيل. البنود التي تحتاج تأكيد مذكورة في صفحة "الأسئلة المطلوبة".

Sheet الأسئلة المطلوبة
A1: الأسئلة المطلوب الإجابة عليها لاعتماد الحسابات بنسبة 100%
A2: م | B2: القسم | C2: السؤال | D2: المبلغ المتأثر | E2: الإجابة
A3: 1 | B3: المبيعات | C3: لا توجد مبيعات من 1-7-2025 إلى 29-7-2025 (شيت ما قبل الفترة ينتهي 30-6-2025). هل توجد مبيعات لهذه الفترة؟ | D3: غير معروف
A4: 2 | B4: المبيعات | C4: الفواتير المبدئية من 1 إلى 24 (قبل 27-10-2025) لم تُرسل. هل تتوفر لمطابقة عقود أغسطس–أكتوبر 2025؟ | D4: —
A5: 3 | B5: المبيعات | C5: الفاتورتان 57 و 58 بنفس العقد WHT-2953 ونفس القيمة – هل إحداهما مكررة؟ (الكشف سجلها مرة واحدة) | D5: 12742.5
A6: 4 | B6: المبيعات | C6: العقدان WHT-2756 و WHT-2758 موجودان بسجل العقود فقط (بدون فاتورة ولا قيد بالكشف) – هل هما مبيعات فعلية؟ | D6: 16810
A7: 5 | B7: المبيعات | C7: الفاتورة 156: القيمة 5,448.75 وبالكشف 5,447.75 – أيهما الصحيح؟ | D7: 1
A8: 6 | B8: المبيعات | C8: مبيعات ما قبل الفترة 610,688: هل هي لكل المناديب معاً؟ وهل يلزم توزيعها على المناديب؟ | D8: 610,688
A9: 7 | B9: المبيعات | C9: كشف الخزنة يُظهر رصيد عصمت 63,832.57 وعماد 6,832.75 (مبيعات أكثر من السداد) – هل هي مديونيات قائمة على المناديب؟ | D9: 70665.32
A10: 8 | B10: المبيعات | C10: بند "تصفية مديونية أبو خالد حتى 31-10" 62,937 بكشف الخزنة – ما العقود التي يغطيها؟ (عقود WHK قبل نوفمبر بشيت المحاسب مجموعها أكبر) | D10: 62937
A11: 9 | B11: المواد | C11: لا توجد حركات مواد من 3-6-2026 إلى 12-6-2026 – هل توجد سندات لهذه الفترة؟ | D11: —
A12: 10 | B12: المواد | C12: لا يوجد أي ترحيل من تبوك للرياض (TNR) من فبراير إلى يونيو 2026 – هل يوجد سجل الوارد؟ وما هو PO-213 (بيتونيا 6,000 في 5-4-2026)؟ | D12: 3000
A13: 11 | B13: المواد | C13: بند "فرق PO الشجيرات" بشيت المحاسب (7 أسطر بدون تاريخ ولا سند) – ما مستنده؟ | D13: 2045
A14: 12 | B14: المواد | C14: السند RN-RAW-OUT#186-REV1: صرف أشجار 78,463.50 للإنتاج بغرض تبديل المراكن – هل أُعيدت الأشجار للمخزون؟ | D14: 78463.5
A15: 13 | B15: المواد | C15: الطلب 58991: فينكا 26,000 أُرسلت مع عماد (15,500) وعصمت (10,500) – هل هي ضمن مبيعاتهما؟ | D15: 14300
A16: 14 | B16: المواد | C16: سيسبانيا OD373: خرج 250 لتبوك (11-7) ورجع 250 ثم خرج 240 (14-7) – هل التحويل الأول أُلغي؟ | D16: 6375
A17: 15 | B17: المواد | C17: TNR-3441 / إذن صرف 319: الاكاليفا 60 أم 6؟ | D17: 135
A18: 16 | B18: المواد | C18: العقد RNO-3832: مجموع البنود 5,274.48 وإجمالي العقد 5,550.48 – ما سبب الفرق؟ | D18: 276
A19: 17 | B19: المواد | C19: السند ISV-0061 (مرتجع جزئي) – ما الكمية المرتجعة؟ والسند ISV-0075 (2,750 – رائد الخير) – ما أصنافه؟ | D19: —
A20: 18 | B20: المواد | C20: رقم العقد RNP-1787 مستخدم لحركتين (25-7-2025: 18,975 و 4-8-2025: 20,872.50 جهة WHOLESALE RIYADH) – أيهما صحيح؟ | D20: 20872.5
A21: 19 | B21: التسعير | C21: مسحوبات نسما من الرياض: هل تُحسب بأسعار النظام أم بأسعار التحويل الخاصة بالمحاسب؟ (بيتونيا 0.50 مقابل 0.55 ...) | D21: يؤثر على كامل RNT/RNP
A22: 20 | B22: التسعير | C22: الأساس الضريبي: النظام القديم شامل 15% والنظام الجديد وسجل الصرف بدون ضريبة – أي أساس يُعتمد لحساب الشريكين؟ | D22: —
A23: 21 | B23: التسعير | C23: أسعار أوامر ما قبل الفترة P00480–P00523 (102,875 حبة) – ما سعر الحبة المعتمد؟ | D23: غير مسعّر
A24: 22 | B24: التسعير | C24: تكاليف النقل والبراد لأوامر ما قبل الفترة (13,100 دفعتها نسما) – هل تُحتسب دعماً من نسما أم على مزرعة الرياض؟ | D24: 13100
A25: 23 | B25: التسعير | C25: مرجع الطلب NS-1466 مستخدم لأمرين P00481 (18,000 حبة) و P00522 (15,000) – هل هما شحنتان مختلفتان؟ | D25: —
A26: 24 | B26: المصروفات | C26: PO-0777 (بساتين الرياض 66,420) مدفوع جزئياً – كم المبلغ المسدد؟ | D26: 66420 | E26: مسدد 11,000 (DIS-Riyadh-0012 – 1-7-2026) والمتبقي 55,420
A27: 25 | B27: المصروفات | C27: المدارات: PO-267 و PO-309 بنفس القيمة 53,475 – هل هما توريدان مختلفان؟ | D27: 53475
A28: 26 | B28: المصروفات | C28: الديزل: هل ديزل العهد النقدية (سيارات 1219 و 3010) جزء من 24,888 المدفوعة من نسما في 2026؟ وهل يوجد ديزل أغسطس–أكتوبر 2025؟ | D28: —
A29: 27 | B29: المصروفات | C29: مشتريات 2025 المدفوعة من تبوك: الفلتر يعطي 226,679.26 والرقم اليدوي 269,099.26 – ما الحركات التي تكوّن الفرق 42,420؟ | D29: 42420
A30: 28 | B30: المصروفات | C30: مصروفات 2025 مكررة ظاهرياً: المدارات 50,600 مرتين في 23-10-2025 وأخرى – هل هي مكررة؟ | D30: 70600
A31: 29 | B31: المصروفات | C31: شركة الجزيرة الحديثة 21,250 غير مدفوعة (عقد عرعر) – من يسددها؟ | D31: 21250 | E31: لا توجد مديونية – كل مسحوبات الجزيرة مسددة وخاصة ببساتين الرياض (محذوفة من الحسابات)
A32: 30 | B32: المصروفات | C32: كشف الخزنة فيه 53 مصروف بمبلغ صفر (يناير–فبراير 2026) ورواتب شهر 5-2026 (29,457) مسجلة في خانة البيان – ما المبالغ الصحيحة؟ | D32: 29457
A33: 31 | B33: المصروفات | C33: مصروفات الخزنة (1,442,387.24) متداخلة مع أوامر الشراء والعهد ومصروفات 2025 – هل يُعتمد كشف الخزنة مصدراً رئيسياً للمصروفات من 11-2025؟ | D33: —
A34: 32 | B34: المصروفات | C34: كشف مصروفات التشغيل قبل الفترة: البندان 8 و 17 ناقصان، و3 فواتير كهرباء بدون تاريخ – هل توجد بنود ناقصة؟ | D34: —
A35: 33 | B35: المصروفات | C35: مصروفات التشغيل 2-2024 إلى 12-2024 (412,040.67) صُرفت من الإيرادات – أي إيرادات؟ (المبيعات المسجلة تبدأ من 10-2024 فقط) | D35: 412040.67
A36: 34 | B36: المصروفات | C36: مصروفات م/ عادل 413,236 إجماليات ربع سنوية – هل يوجد كشف تفصيلي بالمستندات؟ | D36: 413236
A37: 35 | B37: المصروفات | C37: التأسيس البند 23: دينة عماد 123,000 بتاريخ 1-11-2025 – هل هو تأسيس أم مصروف تشغيل 2025؟ | D37: 123000
A38: 36 | B38: المصروفات | C38: الإيجار: 300,000 لعامين من 9-1-2024 + 150,000 في 27-7-2026 – ما الفترة التي يغطيها كل منهما؟ | D38: 150000
A39: 37 | B39: المصروفات | C39: عهدة المصروفات الإدارية 2026 (174,142.15) بدون أي تسوية – هل توجد مستندات؟ وأرصدة العهد غير المسواة 1,543.91؟ | D39: 174142.15
A40: 38 | B40: الشركاء | C40: سدادات أبو خالد المسجلة بكشف الخزنة (763,323.81) تم احتسابها سداداً لمسحوباته – هل هذا صحيح؟ | D40: 763323.81
...

Sheet ملخص الشركاء
A1: ملخص حساب الشريكين مع مزرعة الرياض
A2: أبو خالد = مؤسسة بساتين الرياض | أبو مازن = شركة نسما الشرق (مزرعة تبوك)
A4: البند | B4: أبو خالد – بساتين الرياض | C4: أبو مازن – نسما الشرق | D4: ملاحظة
A5: 1) المسحوبات المباشرة | B5: ='حساب أبو خالد'!C8 | C5: ='حساب أبو مازن'!C9
A6: 2) المسحوبات النقدية | B6: ='حساب أبو خالد'!C14 | C6: ='حساب أبو مازن'!C16
A7: إجمالي المسحوبات (عليه) | B7: =B5+B6 | C7: =C5+C6
A8: 3) سدادات لمسحوباته مسجلة بكشف الخزنة | B8: ='حساب أبو خالد'!C19 | C8: 0 | D8: توريدات وسدادات أبو خالد
A9: 4) الدعم المقدم للمزرعة | B9: ='حساب أبو خالد'!C26 | C9: ='حساب أبو مازن'!C26
A10: إجمالي ما له (سدادات + دعم) | B10: =B8+B9 | C10: =C8+C9
A11: الصافي (موجب = مديونية عليه للمزرعة / سالب = مستحق له) | B11: =B7-B10 | C11: =C7-C10 | D11: ⚠ لم تُسعّر بعد مسحوبات تبوك قبل الفترة (102,875 حبة)

Sheet حساب أبو خالد
A1: حساب م/ عادل أبو خالد – مؤسسة بساتين الرياض مع مزرعة الرياض
A3: أولاً: المسحوبات المباشرة (مديونية على أبو خالد)
A4: م | B4: البند | C4: المبلغ | D4: المصدر | E4: ملاحظة
A5: 1 | B5: عقد عرعر WHK-2364 – الكميات المصروفة من الرياض والمحوّلة من تبوك × 0.50 | C5: ='مطابقة كميات عقد عرعر'!E11 | D5: صفحة مطابقة كميات عقد عرعر | E5: 275,375 حبة × 0.50 (بدل قيمة العقد 440,000)
A6: 2 | B6: مبيعات المندوب أبو خالد – باقي عقود WHK (46 عقد) من 30-7-2025 إلى 31-7-2026 | C6: ='مبيعات أبو خالد'!E49-'مطابقة كميات عقد عرعر'!E11 | D6: ملف المبيعات – مبيعات أبو خالد | E6: تشمل بنود سند المسحوبات 24.2–3.6.2026 (لا تُحسب مرتين)
A7: 3 | B7: فرق سعر زهور الجزيرة لعقد عرعر (ربح المزرعة): 392,450 × (0.55 − 0.50) − فلين 3,128 | C7: 16494.5 | D7: كشف الخزنة – قيود 28-2-2026 | E7: يُبقي رصيد أبو خالد بكشف الخزنة كما هو (160,988.56 له) بعد حذف عمليات الجزيرة
B8: الإجمالي | C8: =SUM(C5:C7)
A10: ثانياً: المسحوبات النقدية من خزنة المزرعة (مديونية على أبو خالد)
A11: م | B11: البند | C11: المبلغ | D11: المصدر | E11: ملاحظة
A12: 1 | B12: مبلغ مسدد نقداً لأبو خالد من مديونيته (18-5-2026) | C12: 2000 | D12: كشف الخزنة – مستند 156 | E12: مسجل بالكشف كفاتورة على حسابه (بمثابة مرتجع نقدي للعميل) لتخفيض رصيده الدائن
A13: 2 | B13: منصرف لأبو خالد بتعليمات أبو مازن (9-3-2026) | C13: 100000 | D13: كشف الخزنة – مصروف 131 | E13: ✓ مؤكد أن أبو خالد استلمه
B14: الإجمالي | C14: =SUM(C12:C13)
A16: ثالثاً: سدادات أبو خالد لمسحوباته (مسجلة لحسابه في كشف الخزنة)
A17: م | B17: البند | C17: المبلغ | D17: المصدر | E17: ملاحظة
A18: 1 | B18: توريدات نقدية وسدادات مسجلة لحسابه بكشف الخزنة (بعد حذف إيداعات الجزيرة) | C18: =763323.81-196225-3128 | D18: كشف الحساب – عميل 5000 | E18: الأصل 763,323.81 − زهور الجزيرة 196,225 − فلين مستعمل من الجزيرة 3,128 (خاصة بعقد بساتين الرياض – محذوفة)
B19: الإجمالي | C19: =SUM(C18:C18)
A21: رابعاً: دعم أبو خالد لمزرعة الرياض (حق له)
A22: م | B22: البند | C22: المبلغ | D22: المصدر | E22: ملاحظة
A23: 1 | B23: مساهمة أبو خالد في مصروفات التأسيس | C23: 189235 | D23: بيان صاحب الحساب | E23: مساهمة أبو خالد في التأسيس – تُضاف لمصروفات التأسيس (الإجمالي 1,278,970.80)
A24: 2 | B24: أوامر شراء بساتين الرياض غير مسددة – PO-1023 | C24: 33950 | D24: ملف أوامر الشراء 2026
A25: 3 | B25: أوامر شراء بساتين الرياض – PO-0777 (المتبقي بعد سداد 11,000) | C25: 55420 | D25: ملف أوامر الشراء 2026 | E25: قيمة الأمر 66,420 − مسدد 11,000 (سند الخزنة DIS-Riyadh-0012 بتاريخ 1-7-2026) = 55,420
B26: الإجمالي | C26: =SUM(C23:C25)
B28: ملاحظة: أوامر بساتين المسددة (PO-288 و PO-287-REV1 = 147,745.75 سُددت كتسوية على حسابه، و PO-146 و PO-255 و PO-0707 مدفوعة) لم تُحتسب كدعم لأنها سُددت.

Sheet مطابقة حساب أبو خالد
A1: مطابقة مسحوبات أبو خالد: قائمة العقود (ملف المبيعات) مقابل كشف حساب الخزنة (عميل 5000)
A3: أولاً: المقارنة الإجمالية
A4: م | B4: البند | C4: حسب قائمة العقود | D4: حسب كشف الخزنة | E4: الفرق | F4: التفسير
A5: 1 | B5: عقد عرعر WHK-2364 | C5: 440000 | D5: 367803.75 | E5: =C5-D5 | F5: الكشف سجّل المسلّم فقط (5 فواتير + زهور الجزيرة 215,847.50 + زهور تبوك 38,293.75). قائمة العقود بقيمة العقد كاملة (حسب قرارك السابق)
A6: 2 | B6: عقود ما قبل 1-11-2025 (19 عقد من WHK-1909 إلى WHK-2656) | C6: 151988.75 | D6: 62937 | E6: =C6-D6 | F6: الكشف سجّلها كقيد واحد "تصفية مديونية أبو خالد حتى 31-10" بقيمة 62,937 بتاريخ 17-12-2025 بدل قيمها الفعلية
A7: 3 | B7: باقي العقود من 1-11-2025 إلى 31-7-2026 (27 عقد) | C7: 169594.5 | D7: 169594.5 | E7: =C7-D7 | F7: مطابق تماماً عقداً بعقد
B8: إجمالي المسحوبات | C8: =SUM(C5:C7) | D8: =SUM(D5:D7) | E8: =SUM(E5:E7)
A10: ثانياً: ماذا يعني "سداد أبو خالد لمسحوباته"
B11: كشف الخزنة فيه لحساب أبو خالد (عميل 5000) جانبان: مدين = الفواتير/المسحوبات 600,335.25 + صرف 2,000، ودائن = "Cash Payment" 763,323.81 وهي كل المبالغ التي وردها أبو خالد نقداً للخزنة أو دفعها عن المزرعة لموردين (زهور الجزيرة 196,225 – بذور بساتين قديم 147,745.75 – بيتموس 53,475 – جهنمية 37,550 – مراكن 20,000 ...). هذه المبالغ الدائنة هي "السداد" لأنها تُخفض رصيده. رصيد الكشف = 600,335.25 + 2,000 − 763,323.81 = −160,988.56 أي دائن لصالح أبو خالد.
A13: ثالثاً: الخيارات – اختر أحدها
A14: م | B14: الخيار | C14: المسحوبات | D14: السدادات | E14: الرصيد | F14: الشرح
A15: 1 | B15: اعتماد كشف الخزنة كما هو | C15: 602335.25 | D15: 763323.81 | E15: =C15-D15 | F15: عرعر بالمسلّم + قيد التصفية 62,937 لما قبل نوفمبر
A16: 2 | B16: قائمة العقود كاملة (المعتمد حالياً بالملف) | C16: 763583.25 | D16: 763323.81 | E16: =C16-D16 | F16: عرعر 440,000 + عقود ما قبل نوفمبر بقيمها الفعلية 151,988.75
A17: 3 | B17: الكشف مع عرعر بالقيمة الكاملة | C17: 674531.5 | D17: 763323.81 | E17: =C17-D17 | F17: يُعتمد قيد التصفية 62,937 لما قبل نوفمبر
A18: 4 | B18: الكشف مع عقود ما قبل نوفمبر بقيمها الفعلية | C18: 691387 | D18: 763323.81 | E18: =C18-D18 | F18: عرعر بالمسلّم فقط
B19: ملاحظة: الرصيد الموجب = مديونية على أبو خالد، السالب = مستحق له. (يُضاف لاحقاً دعمه 189,235 + أوامر بساتين غير المسددة ويُطرح منه ما يخص أبو مازن)
A21: رابعاً: تفصيل عقود ما قبل 1-11-2025 غير الظاهرة بالكشف
A22: م | B22: العقد | C22: التاريخ | D22: القيمة
A23: 1 | B23: WHK-1909 | C23: 45868 | D23: 11570
A24: 2 | B24: WHK-2148 | C24: 45909 | D24: 3320
A25: 3 | B25: WHK-2271 | C25: 45923 | D25: 2400
A26: 4 | B26: WHK-2283 | C26: 45924 | D26: 2800
A27: 5 | B27: WHK-2328 | C27: 45929 | D27: 4550
A28: 6 | B28: WHK-2411 | C28: 45938 | D28: 4200
A29: 7 | B29: WHK-2425 | C29: 45939 | D29: 11000
A30: 8 | B30: WHK-2434 | C30: 45941 | D30: 70250
A31: 9 | B31: WHK-2465 | C31: 45943 | D31: 1750
A32: 10 | B32: WHK-2480 | C32: 45944 | D32: 412.5
A33: 11 | B33: WHK-2498 | C33: 45945 | D33: 17055
A34: 12 | B34: WHK-2509 | C34: 45946 | D34: 3150
... A41: 19 | B41: WHK-2656 | C41: 45957 | D41: 900
B42: الإجمالي | D42: =SUM(D23:D41)
B43: بالكشف: قيد تصفية مديونية أبو خالد حتى 31-10 (17-12-2025) | D43: 62937

Sheet مطابقة كميات عقد عرعر
A1: عقد عرعر WHK-2364 – مسحوبات أبو خالد (الكميات المصروفة من الرياض + المحوّلة من تبوك) بسعر 0.50
A3: م | B3: المصدر | C3: الكمية (حبة) | D3: السعر | E3: القيمة | F3: المستند | G3: ملاحظة
A4: 1 | B4: صرف من مزرعة الرياض – بيتونيا (8-11-2025) | C4: 40000 | D4: 0.5 | E4: =C4*D4 | F4: RN-INV#40
A5: 2 | B5: صرف من مزرعة الرياض – بيتونيا (11-11-2025) | C5: 41250 | D5: 0.5 | E5: =C5*D5 | F5: RN-INV#45
A6: 3 | B6: صرف من مزرعة الرياض – بيتونيا (20-11-2025) | C6: 42000 | D6: 0.5 | E6: =C6*D6 | F6: RN-INV#54
A7: 4 | B7: صرف من مزرعة الرياض – بيتونيا (11-12-2025) | C7: 42500 | D7: 0.5 | E7: =C7*D7 | F7: RN-INV#84
A8: 5 | B8: صرف من مزرعة الرياض – بيتونيا (28-12-2025) | C8: 30000 | D8: 0.5 | E8: =C8*D8 | F8: RN-INV#100
A9: 6 | B9: صرف من مزرعة الرياض – ماري جولد (28-12-2025) | C9: 10000 | D9: 0.5 | E9: =C9*D9 | F9: RN-INV#100 | G9: صنف ماري جولد – محسوب بنفس السعر 0.50
A10: 7 | B10: محوّل من مزرعة تبوك إلى الرياض للعقد (سندا TNR-2689 و TNR-2888) | C10: 69625 | D10: 0.5 | E10: =C10*D10 | F10: كشف الخزنة 28-2-2026 "زهور تبوك 69625" | G10: سندا الترحيل TNR-2689 و TNR-2888 بقيمة 72,625 حبة، منها 3,000 زهرة تالفة – الكمية الفعلية الموردة 69,625
B11: إجمالي مسحوبات أبو خالد لعقد عرعر | C11: =SUM(C4:C10) | E11: =SUM(E4:E10) | G11: =مديونية أبو خالد عن عقد عرعر
B12: بيان كمية تبوك: 72,625 بالسندات − 3,000 تالف = 69,625 حبة موردة فعلياً
A14: ملاحظات:
A15: 1) مشتريات الجزيرة الحديثة وإيداعاتها خاصة بعقد بساتين الرياض ومسددة بالكامل – تم حذفها من كل الحسابات (مصروفات 2025، كشف الخزنة، سدادات أبو خالد، أرصدة الموردين).
A16: 2) القيمة السابقة للعقد (440,000) مستبدلة بالقيمة المحسوبة بالكميات الفعلية × 0.50.

Sheet حساب أبو مازن
A1: حساب أبو مازن – شركة نسما الشرق (مزرعة تبوك) مع مزرعة الرياض
A3: أولاً: المسحوبات المباشرة (مديونية على أبو مازن)
A4: م | B4: البند | C4: المبلغ | D4: المصدر | E4: ملاحظة
A5: 1 | B5: ترحيلات من الرياض إلى تبوك RNT | C5: ='مواد - الملخص'!J6 | D5: ملف حركات المواد – بقيم النظام | E5: ⚠ بقيم النظام – شيت المحاسب بأسعار التحويل مختلف
A6: 2 | B6: ترحيلات إلى قسم المشاريع تبوك RNP | C6: ='مواد - الملخص'!J7 | D6: ملف حركات المواد – بقيم النظام
A7: 3 | B7: تكاليف نقل خارج الرياض لصالح تبوك (15,290 كم × 1.30) | C7: ='مصاريف إدارية وديزل تبوك'!F59 | D7: ملف مراجعة المسحوبات
A8: 4 | B8: مسحوبات قبل الفترة – أوامر P00480 إلى P00523 (102,875 حبة) | C8: 0 | D8: ملف مراجعة المسحوبات | E8: ⚠ بدون أسعار – تُدخل يدوياً
B9: الإجمالي | C9: =SUM(C5:C8)
A11: ثانياً: المسحوبات النقدية (مديونية على أبو مازن)
A12: م | B12: البند | C12: المبلغ | D12: المصدر | E12: ملاحظة
A13: 1 | B13: إيداع في حساب أبو مازن من إيرادات المناديب قبل الفترة | C13: 197452 | D13: بيان صاحب الحساب | E13: ✓ مؤكد – استُلم لحسابه الشخصي
A14: 2 | B14: (منقول لحساب أبو خالد) منصرف 100,000 بتاريخ 9-3-2026 | C14: 0 | D14: كشف الخزنة – مصروف 131 | E14: تأكد أن أبو خالد هو من استلمه
A15: 3 | B15: توريد نقدي للإدارة – أبو مازن (21-5-2026) | C15: 13000 | D15: كشف الخزنة – مصروف 157 | E15: ✓ مؤكد – استُلم لحسابه الشخصي
B16: الإجمالي | C16: =SUM(C13:C15)
A18: ثالثاً: دعم أبو مازن / نسما لمزرعة الرياض (حق له)
A19: م | B19: البند | C19: المبلغ | D19: المصدر | E19: ملاحظة
A20: 1 | B20: مصروفات التأسيس المدفوعة من أبو مازن / نسما | C20: ='مصروفات التأسيس'!E27 | D20: كشف مصروفات التأسيس | E20: كشف التأسيس 1,089,735.80 – مساهمة أبو خالد (189,235) منفصلة ومضافة عليها
A21: 2 | B21: ترحيلات من تبوك إلى الرياض TNR | C21: ='مواد - الملخص'!J5 | D21: ملف حركات المواد – بقيم النظام
A22: 3 | B22: مصروفات إدارية 2025 | C22: ='مصاريف إدارية وديزل تبوك'!D12 | D22: كشف المصاريف الإدارية
A23: 4 | B23: مصروفات إدارية وحكومية 2026 (تشمل إيجار المزرعة 150,000) | C23: ='مصاريف إدارية وديزل تبوك'!D36 | D23: تقرير العهدة الإدارية
A24: 5 | B24: ديزل مدفوع من نسما | C24: ='مصاريف إدارية وديزل تبوك'!F42 | D24: شيت الديزل | E24: ⚠ قد يتداخل مع ديزل العهد
A25: 6 | B25: مشتريات 2025 مدفوعة من نسما (تحويل بنكي) | C25: 226679.26 | D25: ملف مصروفات 2025 | E25: ⚠ الرقم اليدوي بالملف 269,099.26 (فرق 42,420 بدون حركات)
B26: الإجمالي | C26: =SUM(C20:C25)

Sheet إيرادات قبل الفترة
A1: إيرادات ومصروفات المزرعة قبل 30-7-2025 (ليست دعماً من أي شريك)
A3: التسوية
A4: م | B4: البند | C4: المبلغ | D4: المصدر | E4: ملاحظة
A5: 1 | B5: إيرادات المناديب (1-10-2024 إلى 30-6-2025) | C5: 610688 | D5: ملف المبيعات
A6: 2 | B6: يُخصم: مصروفات تشغيل دفعها م/ عادل من الإيرادات | C6: -413236 | D6: ملف المصاريف التشغيلية
A7: 3 | B7: يُخصم: المودع في حساب أبو مازن | C7: -197452 | D7: بيان صاحب الحساب | E7: مُدرج كمسحوبات نقدية على أبو مازن
B8: الإجمالي | C8: =SUM(C5:C7)
E9: الصافي = صفر ✓
B11: مصروفات تشغيل 2-2024 إلى 12-2024 (412,040.67) صُرفت من إيرادات المزرعة – لا تُحتسب دعماً لأي شريك.

Sheet تحقق سند أبو خالد
A1: مراجعة سند "مسحوبات بساتين الرياض من 24.2.2026 حتى 3.6.2026" مقابل فواتير أبو خالد
A2: سند الصرف | B2: العقد | C2: الفاتورة | D2: الصنف | E2: الكمية بالسند | F2: الكمية بالفاتورة | G2: سعر السند | H2: سعر الفاتورة | I2: الفرق بالقيمة | J2: الحالة
A3: #141 | B3: WHK-3923 | C3: RN-INV#166 | D3: OD696 أقحوان | E3: 2075 | F3: 2075 | G3: 1.5 | H3: 1.5 | I3: =E3*G3-F3*H3 | J3: الكمية مطابقة والسعر مطابق
A4: #141 | B4: WHK-3923 | C4: RN-INV#166 | D4: OD603 جرانيوم 9 | E4: 3000 | F4: 3000 | G4: 0.95 | H4: 1.25 | I4: =E4*G4-F4*H4 | J4: الكمية مطابقة – السعر مختلف
A5: #261 | B5: WHK-4256 | C5: RN-INV#227 | D5: OD562 زينيا | E5: 25625 | F5: 25625 | G5: 0.55 | H5: 0.5 | I5: =E5*G5-F5*H5 | J5: الكمية مطابقة – السعر مختلف
A6: #261 | B6: WHK-4256 | C6: RN-INV#227 | D6: OD563 سيلوزيا | E6: 3000 | F6: 3000 | G6: 0.55 | H6: 0.5 | I6: =E6*G6-F6*H6 | J6: الكمية مطابقة – السعر مختلف
A7: #261 | B7: WHK-4256 | C7: RN-INV#227 | D7: OD564 امرانتس | E7: 5000 | F7: 5000 | G7: 0.55 | H7: 0.5 | I7: =E7*G7-F7*H7 | J7: الكمية مطابقة – السعر مختلف
A8: #261 | B8: WHK-4256 | C8: RN-INV#227 | D8: OD565 جازانيا | E8: 4475 | F8: 4475 | G8: 0.55 | H8: 0.5 | I8: =E8*G8-F8*H8 | J8: الكمية مطابقة – السعر مختلف
A9: #261 | B9: WHK-4256 | C9: RN-INV#227 | D9: OD454 تيكوماريا | E9: 50 | F9: 50 | G9: 2.5 | H9: 4 | I9: =E9*G9-F9*H9 | J9: الكمية مطابقة – السعر مختلف
A10: #261 | B10: WHK-4256 | C10: RN-INV#227 | D10: OD623 تيسبيسيا | E10: 4 | F10: 4 | G10: 49.5 | H10: 60 | I10: =E10*G10-F10*H10 | J10: الكمية مطابقة – السعر مختلف
A11: #269 | B11: WHK-4275 | C11: RN-INV#231 | D11: OD569 فينكا | E11: 37400 | F11: 37400 | G11: 0.55 | H11: 0.55 | I11: =E11*G11-F11*H11 | J11: الكمية مطابقة والسعر مطابق
A12: #269 | B12: WHK-4275 | C12: RN-INV#231 | D12: OD567 كيليوس | E12: 2200 | F12: 2200 | G12: 0.55 | H12: 0.55 | I12: =E12*G12-F12*H12 | J12: الكمية مطابقة والسعر مطابق
A13: #279 | B13: WHK-4291 | C13: RN-INV#239 | D13: OD569 فينكا | E13: 5700 | F13: 5700 | G13: 0.55 | H13: 0.55 | I13: =E13*G13-F13*H13 | J13: الكمية مطابقة والسعر مطابق
A14: #285 | B14: WHK-4305 | C14: RN-INV#243 | D14: OD569 فينكا | E14: 5500 | F14: 5500 | G14: 0.55 | H14: 0.55 | I14: =E14*G14-F14*H14 | J14: الكمية مطابقة والسعر مطابق
A15: #296 | B15: WHK-4323 | C15: RN-INV#250 | D15: OD564 امرانتس | E15: 1500 | F15: 1500 | G15: 0.55 | H15: 0.5 | I15: =E15*G15-F15*H15 | J15: الكمية مطابقة – السعر مختلف
A16: الإجمالي | I16: =SUM(I3:I15)
A18: النتيجة: كل بنود السند (13 بند، 6 عقود) هي مسحوبات عقود أبو خالد WHK ومطابقة للكميات في الفواتير المبدئية 166 و227 و231 و239 و243 و250، وكلها مدرجة بالفعل في مبيعات أبو خالد.
A19: إجمالي السند 56,005.50 مقابل 55,042.50 بالفواتير (فرق 963) بسبب اختلاف الأسعار في 3 سندات: #141 الجرانيوم 0.95 بدل 1.25 (−900)، #261 أسعار السند 0.55 بدل 0.50 وتيكوماريا وتيسبيسيا أقل (+1,788)، #296 الامرانتس 0.55 بدل 0.50 (+75).
A20: عنوان السند مكتوب "حتى 3.7.2026" بينما اسم الملف "3.6.2026" – آخر حركة بالسند 18-5-2026.

Sheet مبيعات - الملخص
A1: ملخص إجمالي مبيعات المناديب – مزرعة الرياض
A2: الفترة كاملة: من 1-10-2024 إلى 31-7-2026 – مبيعات ما قبل 30-7-2025 (إجمالي شهري غير موزع على المناديب) + شيت المبيعات (عقود الجملة من 30-7-2025 حتى 3-6-2026) + النظام الجديد برقم السيارة (شهري 6 و7 لسنة 2026)
A4: المندوب | B4: عقود الجملة (30-7-2025 إلى 3-6-2026) | C4: النظام الجديد – السيارة (6 و7 لسنة 2026) | D4: إجمالي مبيعات المندوب | E4: الإجمالي حسب المحاسب | F4: الفرق | G4: السيارة
A5: عصمت الله خان | B5: =SUMIFS('مبيعات عصمت'!E2:E255,'مبيعات عصمت'!I2:I255,"شيت المبيعات (عقود الجملة)") | C5: =SUMIFS('مبيعات عصمت'!E2:E255,'مبيعات عصمت'!I2:I255,"النظام الجديد*") | D5: ='مبيعات عصمت'!E256 | E5: ='مبيعات عصمت'!D256 | F5: =D5-E5 | G5: VHC-1219
A6: عماد حمدي | B6: =SUMIFS('مبيعات عماد'!E2:E59,'مبيعات عماد'!I2:I59,"شيت المبيعات (عقود الجملة)") | C6: =SUMIFS('مبيعات عماد'!E2:E59,'مبيعات عماد'!I2:I59,"النظام الجديد*") | D6: ='مبيعات عماد'!E60 | E6: ='مبيعات عماد'!D60 | F6: =D6-E6 | G6: VHC-3010
A7: م/ عادل أبو خالد | B7: =SUMIFS('مبيعات أبو خالد'!E2:E48,'مبيعات أبو خالد'!I2:I48,"شيت المبيعات (عقود الجملة)") | C7: =SUMIFS('مبيعات أبو خالد'!E2:E48,'مبيعات أبو خالد'!I2:I48,"النظام الجديد*") | D7: ='مبيعات أبو خالد'!E49 | E7: ='مبيعات أبو خالد'!D49 | F7: =D7-E7 | G7: —
A8: مبيعات قبل 30.7.2025 (1-10-2024 إلى 30-6-2025) – غير موزعة على المناديب | D8: ='مبيعات قبل 30.7.2025'!C12 | G8: —
A9: الإجمالي الكلي (1-10-2024 إلى 31-7-2026) | B9: =SUM(B5:B8) | C9: =SUM(C5:C8) | D9: =SUM(D5:D8) | E9: =SUM(E5:E8) | F9: =SUM(F5:F8)
A11: ملاحظات المراجعة (كل الأرقام بالقيمة الإجمالية كما هي بالمستندات):
A12: 1) عصمت (WHT): شيت المحاسب مكتوب "من 9-10-2025" لكنه أدرج عقوداً من يوليو–سبتمبر، وأسقط 4 عقود من 1 إلى 8 أكتوبر (WHT-2348/2358/2378/2408 = 21,087.50) فتمت إضافتها.
A13: 2) عصمت: عقدان WHT-2756 و WHT-2758 (16,810.00) موجودان في سجل العقود فقط، بدون فاتورة مبدئية ولا قيد في الكشف – تمت إضافتهما.
A14: 3) عصمت: 3 عقود مكررة الرقم في شيت المحاسب (WHT-3786 و WHT-4052 و WHT-4234) – القيم صحيحة والأرقام الصحيحة WHT-3804 و WHT-4062 و WHT-4243.
A15: 4) العقدان WHT-1908 (16,658.75) و WHK-1909 (11,570.00) بتاريخ 30-7-2025 – بداية الفترة.
A16: 5) أبو خالد (WHK): عقد عرعر WHK-2364 أُدرج بالقيمة الكاملة 440,000 بناءً على طلبك، علماً بأن المسجل بكشف الحساب 367,803.75 (الفرق 72,196.25 بدون قيد بالكشف).
A17: 6) أبو خالد: العقد WHK-3400 (505.00 – فاتورة 103) سقط من شيت المحاسب فتمت إضافته.
A18: 7) عماد (WHE): الشيت مطابق تماماً للفواتير المبدئية وسجل العقود (45 عقد).
A19: 8) مبيعات النظام الجديد (برقم السيارة) مدمجة في صفحة كل مندوب: السيارة 1219 = عصمت، والسيارة 3010 = عماد. المحاسب لم يخصم 3 فواتير مرتجعة بالكامل لسيارة 1219 (4,123.90). شيت المرتجعات فيه صفّان مكرران (WS-RET-0002 و 0003).
A20: 9) بعض التواريخ في ملفات المحاسب مقلوبة (يوم/شهر) مثل 2026-11-07 وهي 7-11 أي 11 يوليو – تم تصحيحها.

Sheet الحركة المدمجة
A1: م | B1: التاريخ | C1: المندوب | D1: المصدر | E1: رقم العقد / الفاتورة | F1: السيارة | G1: العميل | H1: القيمة | I1: الحالة | J1: ملاحظة
A2: 1 | B2: 45868 | C2: عصمت الله خان | D2: شيت المبيعات (عقود الجملة) | E2: WHT-1908 | F2: VHC-1219 | H2: 16658.75 | I2: صحيح (ملاحظة) | J2: تاريخه 2025-07-30 قبل بداية الفترة 31-7-2025 بيوم – أُدرج بناءً على طلبك
A3: 2 | B3: 45868 | C3: م/ عادل أبو خالد | D3: شيت المبيعات (عقود الجملة) | E3: WHK-1909 | F3: — | H3: 11570 | I3: صحيح (ملاحظة) | J3: تاريخه 2025-07-30 قبل بداية الفترة 31-7-2025 بيوم – أُدرج بناءً على طلبك
A4: 3 | B4: 45878 | C4: عصمت الله خان | D4: شيت المبيعات (عقود الجملة) | E4: WHT-1892 | F4: VHC-1219 | H4: 150
A5: 4 | B5: 45885 | C5: عصمت الله خان | D5: شيت المبيعات (عقود الجملة) | E5: WHT-1934 | F5: VHC-1219 | H5: 162.5
A6: 5 | B6: 45885 | C6: عصمت الله خان | D6: شيت المبيعات (عقود الجملة) | E6: WHT-1937 | F6: VHC-1219 | H6: 50
A7: 6 | B7: 45887 | C7: عصمت الله خان | D7: شيت المبيعات (عقود الجملة) | E7: WHT-1952 | F7: VHC-1219 | H7: 450
A8: 7 | B8: 45889 | C8: عصمت الله خان | D8: شيت المبيعات (عقود الجملة) | E8: WHT-1970 | F8: VHC-1219 | H8: 125
A9: 8 | B9: 45890 | C9: عصمت الله خان | D9: شيت المبيعات (عقود الجملة) | E9: WHT-1999 | F9: VHC-1219 | H9: 800
A10: 9 | B10: 45892 | C10: عصمت الله خان | D10: شيت المبيعات (عقود الجملة) | E10: WHT-2007 | F10: VHC-1219 | H10: 155
A11: 10 | B11: 45894 | C11: عصمت الله خان | D11: شيت المبيعات (عقود الجملة) | E11: WHT-2030 | F11: VHC-1219 | H11: 350
A12: 11 | B12: 45895 | C12: عصمت الله خان | D12: شيت المبيعات (عقود الجملة) | E12: WHT-2040 | F12: VHC-1219 | H12: 205
A13: 12 | B13: 45897 | C13: عصمت الله خان | D13: شيت المبيعات (عقود الجملة) | E13: WHT-2065 | F13: VHC-1219 | H13: 62.5
A14: 13 | B14: 45901 | C14: عصمت الله خان | D14: شيت المبيعات (عقود الجملة) | E14: WHT-2084 | F14: VHC-1219 | H14: 202.5
A15: 14 | B15: 45904 | C15: عصمت الله خان | D15: شيت المبيعات (عقود الجملة) | E15: WHT-2112 | F15: VHC-1219 | H15: 517.5
... A36: 35 | B36: 45930 | C36: عصمت الله خان | D36: شيت المبيعات (عقود الجملة) | E36: WHT-2344 | F36: VHC-1219 | H36: 2485
A37: 36 | B37: 45931 | C37: عصمت الله خان | D37: شيت المبيعات (عقود الجملة) | E37: WHT-2348 | F37: VHC-1219 | H37: 3920 | I37: مضاف | J37: موجود في سجل العقود وسقط من شيت المحاسب (المحاسب بدأ من 9-10 رغم إدراجه عقود أقدم)
A38: 37 | B38: 45932 | C38: عصمت الله خان | D38: شيت المبيعات (عقود الجملة) | E38: WHT-2358 | F38: VHC-1219 | H38: 4910 | I38: مضاف | J38: موجود في سجل العقود وسقط من شيت المحاسب (المحاسب بدأ من 9-10 رغم إدراجه عقود أقدم)
A39: 38 | B39: 45934 | C39: عصمت الله خان | D39: شيت المبيعات (عقود الجملة) | E39: WHT-2378 | F39: VHC-1219 | H39: 4760 | I39: مضاف | J39: موجود في سجل العقود وسقط من شيت المحاسب (المحاسب بدأ من 9-10 رغم إدراجه عقود أقدم)
A40: 39 | B40: 45935 | C40: عصمت الله خان | D40: شيت المبيعات (عقود الجملة) | E40: WHT-2756 | F40: VHC-1219 | H40: 3520 | I40: مضاف | J40: موجود في سجل العقود فقط (بدون فاتورة مبدئية وغير مسجل بالكشف) – يحتاج تأكيد
A41: 40 | B41: 45935 | C41: م/ عادل أبو خالد | D41: شيت المبيعات (عقود الجملة) | E41: WHK-2364 | F41: — | H41: ='مطابقة كميات عقد عرعر'!E11 | I41: صحيح (ملاحظة) | J41: عقد عرعر بالكميات الفعلية × 0.50 (بدل 440,000)
A42: 41 | B42: 45936 | C42: عصمت الله خان | D42: شيت المبيعات (عقود الجملة) | E42: WHT-2758 | F42: VHC-1219 | H42: 13290 | I42: مضاف | J42: موجود في سجل العقود فقط (بدون فاتورة مبدئية وغير مسجل بالكشف) – يحتاج تأكيد
A43: 42 | B43: 45938 | C43: عصمت الله خان | D43: شيت المبيعات (عقود الجملة) | E43: WHT-2408 | F43: VHC-1219 | H43: 7497.5 | I43: مضاف | J43: موجود في سجل العقود وسقط من شيت المحاسب (المحاسب بدأ من 9-10 رغم إدراجه عقود أقدم)
A44: 43 | B44: 45938 | C44: م/ عادل أبو خالد | D44: شيت المبيعات (عقود الجملة) | E44: WHK-2411 | F44: — | H44: 4200
A45: 44 | B45: 45939 | C45: عصمت الله خان | D45: شيت المبيعات (عقود الجملة) | E45: WHT-2423 | F45: VHC-1219 | H45: 5790
A46: 45 | B46: 45939 | C46: م/ عادل أبو خالد | D46: شيت المبيعات (عقود الجملة) | E46: WHK-2425 | F46: — | H46: 11000
A47: 46 | B47: 45941 | C47: عصمت الله خان | D47: شيت المبيعات (عقود الجملة) | E47: WHT-2437 | F47: VHC-1219 | H47: 10270
A48: 47 | B48: 45941 | C48: م/ عادل أبو خالد | D48: شيت المبيعات (عقود الجملة) | E48: WHK-2434 | F48: — | H48: 70250
A49: 48 | B49: 45942 | C49: عصمت الله خان | D49: شيت المبيعات (عقود الجملة) | E49: WHT-2454 | F49: VHC-1219 | H49: 6282.5
A50: 49 | B50: 45943 | C50: عصمت الله خان | D50: شيت المبيعات (عقود الجملة) | E50: WHT-2471 | F50: VHC-1219 | H50: 3275
A51: 50 | B51: 45943 | C51: م/ عادل أبو خالد | D51: شيت المبيعات (عقود الجملة) | E51: WHK-2465 | F51: — | H51: 1750
A52: 51 | B52: 45944 | C52: عصمت الله خان | D52: شيت المبيعات (عقود الجملة) | E52: WHT-2483 | F52: VHC-1219 | H52: 6077.5
A53: 52 | B53: 45944 | C53: م/ عادل أبو خالد | D53: شيت المبيعات (عقود الجملة) | E53: WHK-2480 | F53: — | H53: 412.5
A54: 53 | B54: 45945 | C54: عصمت الله خان | D54: شيت المبيعات (عقود الجملة) | E54: WHT-2501 | F54: VHC-1219 | H54: 6087.5
A55: 54 | B55: 45945 | C55: م/ عادل أبو خالد | D55: شيت المبيعات (عقود الجملة) | E55: WHK-2498 | F55: — | H55: 17055
... A145: 144 | B145: 46021 | C145: عماد حمدي | D145: شيت المبيعات (عقود الجملة) | E145: WHE-3402 | F145: VHC-3010 | H145: 6097.5
A146: 145 | B146: 46021 | C146: م/ عادل أبو خالد | D146: شيت المبيعات (عقود الجملة) | E146: WHK-3400 | F146: — | H146: 505 | I146: مضاف | J146: فاتورة مبدئية 103 ومسجلة بكشف الحساب – سقطت من شيت المحاسب
A147: 146 | B147: 46023 | C147: عصمت الله خان | D147: شيت المبيعات (عقود الجملة) | E147: WHT-3426 | F147: VHC-1219 | H147: 790
A148: 147 | B148: 46024 | C148: عماد حمدي | D148: شيت المبيعات (عقود الجملة) | E148: WHE-3424 | F148: VHC-3010 | H148: 6577.5
A149: 148 | B149: 46025 | C149: عصمت الله خان | D149: شيت المبيعات (عقود الجملة) | E149: WHT-3431 | F149: VHC-1219 | H149: 1412.5
...

Sheet مبيعات - شهري
A1: الشهر | B1: عصمت الله خان | C1: عماد حمدي | D1: م/ عادل أبو خالد | E1: الإجمالي | F1: منها: النظام الجديد (السيارات)
A2: أكتوبر 2024 | E2: 103500 | F2: 0
A3: نوفمبر 2024 | E3: 137450 | F3: 0
A4: ديسمبر 2024 | E4: 95230 | F4: 0
A5: يناير 2025 | E5: 55300 | F5: 0
A6: فبراير 2025 | E6: 35920 | F6: 0
A7: مارس 2025 | E7: 15100 | F7: 0
A8: إبريل 2025 | E8: 90160 | F8: 0
A9: مايو 2025 | E9: 50310 | F9: 0
A10: يونيه 2025 | E10: 27718 | F10: 0
A11: 07-2025 | B11: =SUMIFS('الحركة المدمجة'!H:H,'الحركة المدمجة'!C:C,"عصمت الله خان",'الحركة المدمجة'!B:B,">="&DATE(2025,7,1),'الحركة المدمجة'!B:B,"<"&DATE(2025,8,1)) | C11: =SUMIFS('الحركة المدمجة'!H:H,'الحركة المدمجة'!C:C,"عماد حمدي",'الحركة المدمجة'!B:B,">="&DATE(2025,7,1),'الحركة المدمجة'!B:B,"<"&DATE(2025,8,1)) | D11: =SUMIFS('الحركة المدمجة'!H:H,'الحركة المدمجة'!C:C,"م/ عادل أبو خالد",'الحركة المدمجة'!B:B,">="&DATE(2025,7,1),'الحركة المدمجة'!B:B,"<"&DATE(2025,8,1)) | E11: =SUM(B11:D11) | F11: =SUMIFS('الحركة المدمجة'!H:H,'الحركة المدمجة'!D:D,"النظام الجديد (السيارات)",'الحركة المدمجة'!B:B,">="&DATE(2025,7,1),'الحركة المدمجة'!B:B,"<"&DATE(2025,8,1))
A12: 08-2025 | B12: =SUMIFS('الحركة المدمجة'!H:H,'الحركة المدمجة'!C:C,"عصمت الله خان",'الحركة المدمجة'!B:B,">="&DATE(2025,8,1),'الحركة المدمجة'!B:B,"<"&DATE(2025,9,1)) | C12: =SUMIFS('الحركة المدمجة'!H:H,'الحركة المدمجة'!C:C,"عماد حمدي",'الحركة المدمجة'!B:B,">="&DATE(2025,8,1),'الحركة المدمجة'!B:B,"<"&DATE(2025,9,1)) | D12: =SUMIFS('الحركة المدمجة'!H:H,'الحركة المدمجة'!C:C,"م/ عادل أبو خالد",'الحركة المدمجة'!B:B,">="&DATE(2025,8,1),'الحركة المدمجة'!B:B,"<"&DATE(2025,9,1)) | E12: =SUM(B12:D12) | F12: =SUMIFS('الحركة المدمجة'!H:H,'الحركة المدمجة'!D:D,"النظام الجديد (السيارات)",'الحركة المدمجة'!B:B,">="&DATE(2025,8,1),'الحركة المدمجة'!B:B,"<"&DATE(2025,9,1))
A13: 09-2025 | B13: =SUMIFS('الحركة المدمجة'!H:H,'الحركة المدمجة'!C:C,"عصمت الله خان",'الحركة المدمجة'!B:B,">="&DATE(2025,9,1),'الحركة المدمجة'!B:B,"<"&DATE(2025,10,1)) | C13: =SUMIFS('الحركة المدمجة'!H:H,'الحركة المدمجة'!C:C,"عماد حمدي",'الحركة المدمجة'!B:B,">="&DATE(2025,9,1),'الحركة المدمجة'!B:B,"<"&DATE(2025,10,1)) | D13: =SUMIFS('الحركة المدمجة'!H:H,'الحركة المدمجة'!C:C,"م/ عادل أبو خالد",'الحركة المدمجة'!B:B,">="&DATE(2025,9,1),'الحركة المدمجة'!B:B,"<"&DATE(2025,10,1)) | E13: =SUM(B13:D13) | F13: =SUMIFS('الحركة المدمجة'!H:H,'الحركة المدمجة'!D:D,"النظام الجديد (السيارات)",'الحركة المدمجة'!B:B,">="&DATE(2025,9,1),'الحركة المدمجة'!B:B,"<"&DATE(2025,10,1))
A14: 10-2025 | B14: =SUMIFS('الحركة المدمجة'!H:H,'الحركة المدمجة'!C:C,"عصمت الله خان",'الحركة المدمجة'!B:B,">="&DATE(2025,10,1),'الحركة المدمجة'!B:B,"<"&DATE(2025,11,1)) | C14: =SUMIFS('الحركة المدمجة'!H:H,'الحركة المدمجة'!C:C,"عماد حمدي",'الحركة المدمجة'!B:B,">="&DATE(2025,10,1),'الحركة المدمجة'!B:B,"<"&DATE(2025,11,1)) | D14: =SUMIFS('الحركة المدمجة'!H:H,'الحركة المدمجة'!C:C,"م/ عادل أبو خالد",'الحركة المدمجة'!B:B,">="&DATE(2025,10,1),'الحركة المدمجة'!B:B,"<"&DATE(2025,11,1)) | E14: =SUM(B14:D14) | F14: =SUMIFS('الحركة المدمجة'!H:H,'الحركة المدمجة'!D:D,"النظام الجديد (السيارات)",'الحركة المدمجة'!B:B,">="&DATE(2025,10,1),'الحركة المدمجة'!B:B,"<"&DATE(2025,11,1))
A15: 11-2025 | B15: =SUMIFS('الحركة المدمجة'!H:H,'الحركة المدمجة'!C:C,"عصمت الله خان",'الحركة المدمجة'!B:B,">="&DATE(2025,11,1),'الحركة المدمجة'!B:B,"<"&DATE(2025,12,1)) | C15: =SUMIFS('الحركة المدمجة'!H:H,'الحركة المدمجة'!C:C,"عماد حمدي",'الحركة المدمجة'!B:B,">="&DATE(2025,11,1),'الحركة المدمجة'!B:B,"<"&DATE(2025,12,1)) | D15: =SUMIFS('الحركة المدمجة'!H:H,'الحركة المدمجة'!C:C,"م/ عادل أبو خالد",'الحركة المدمجة'!B:B,">="&DATE(2025,11,1),'الحركة المدمجة'!B:B,"<"&DATE(2025,12,1)) | E15: =SUM(B15:D15) | F15: =SUMIFS('الحركة المدمجة'!H:H,'الحركة المدمجة'!D:D,"النظام الجديد (السيارات)",'الحركة المدمجة'!B:B,">="&DATE(2025,11,1),'الحركة المدمجة'!B:B,"<"&DATE(2025,12,1))
A16: 12-2025 | B16: =SUMIFS('الحركة المدمجة'!H:H,'الحركة المدمجة'!C:C,"عصمت الله خان",'الحركة المدمجة'!B:B,">="&DATE(2025,12,1),'الحركة المدمجة'!B:B,"<"&DATE(2026,1,1)) | C16: =SUMIFS('الحركة المدمجة'!H:H,'الحركة المدمجة'!C:C,"عماد حمدي",'الحركة المدمجة'!B:B,">="&DATE(2025,12,1),'الحركة المدمجة'!B:B,"<"&DATE(2026,1,1)) | D16: =SUMIFS('الحركة المدمجة'!H:H,'الحركة المدمجة'!C:C,"م/ عادل أبو خالد",'الحركة المدمجة'!B:B,">="&DATE(2025,12,1),'الحركة المدمجة'!B:B,"<"&DATE(2026,1,1)) | E16: =SUM(B16:D16) | F16: =SUMIFS('الحركة المدمجة'!H:H,'الحركة المدمجة'!D:D,"النظام الجديد (السيارات)",'الحركة المدمجة'!B:B,">="&DATE(2025,12,1),'الحركة المدمجة'!B:B,"<"&DATE(2026,1,1))
A17: 01-2026 | B17: =SUMIFS('الحركة المدمجة'!H:H,'الحركة المدمجة'!C:C,"عصمت الله خان",'الحركة المدمجة'!B:B,">="&DATE(2026,1,1),'الحركة المدمجة'!B:B,"<"&DATE(2026,2,1)) | C17: =SUMIFS('الحركة المدمجة'!H:H,'الحركة المدمجة'!C:C,"عماد حمدي",'الحركة المدمجة'!B:B,">="&DATE(2026,1,1),'الحركة المدمجة'!B:B,"<"&DATE(2026,2,1)) | D17: =SUMIFS('الحركة المدمجة'!H:H,'الحركة المدمجة'!C:C,"م/ عادل أبو خالد",'الحركة المدمجة'!B:B,">="&DATE(2026,1,1),'الحركة المدمجة'!B:B,"<"&DATE(2026,2,1)) | E17: =SUM(B17:D17) | F17: =SUMIFS('الحركة المدمجة'!H:H,'الحركة المدمجة'!D:D,"النظام الجديد (السيارات)",'الحركة المدمجة'!B:B,">="&DATE(2026,1,1),'الحركة المدمجة'!B:B,"<"&DATE(2026,2,1))
A18: 02-2026 | B18: =SUMIFS('الحركة المدمجة'!H:H,'الحركة المدمجة'!C:C,"عصمت الله خان",'الحركة المدمجة'!B:B,">="&DATE(2026,2,1),'الحركة المدمجة'!B:B,"<"&DATE(2026,3,1)) | C18: =SUMIFS('الحركة المدمجة'!H:H,'الحركة المدمجة'!C:C,"عماد حمدي",'الحركة المدمجة'!B:B,">="&DATE(2026,2,1),'الحركة المدمجة'!B:B,"<"&DATE(2026,3,1)) | D18: =SUMIFS('الحركة المدمجة'!H:H,'الحركة المدمجة'!C:C,"م/ عادل أبو خالد",'الحركة المدمجة'!B:B,">="&DATE(2026,2,1),'الحركة المدمجة'!B:B,"<"&DATE(2026,3,1)) | E18: =SUM(B18:D18) | F18: =SUMIFS('الحركة المدمجة'!H:H,'الحركة المدمجة'!D:D,"النظام الجديد (السيارات)",'الحركة المدمجة'!B:B,">="&DATE(2026,2,1),'الحركة المدمجة'!B:B,"<"&DATE(2026,3,1))
A19: 03-2026 | B19: =SUMIFS('الحركة المدمجة'!H:H,'الحركة المدمجة'!C:C,"عصمت الله خان",'الحركة المدمجة'!B:B,">="&DATE(2026,3,1),'الحركة المدمجة'!B:B,"<"&DATE(2026,4,1)) | C19: =SUMIFS('الحركة المدمجة'!H:H,'الحركة المدمجة'!C:C,"عماد حمدي",'الحركة المدمجة'!B:B,">="&DATE(2026,3,1),'الحركة المدمجة'!B:B,"<"&DATE(2026,4,1)) | D19: =SUMIFS('الحركة المدمجة'!H:H,'الحركة المدمجة'!C:C,"م/ عادل أبو خالد",'الحركة المدمجة'!B:B,">="&DATE(2026,3,1),'الحركة المدمجة'!B:B,"<"&DATE(2026,4,1)) | E19: =SUM(B19:D19) | F19: =SUMIFS('الحركة المدمجة'!H:H,'الحركة المدمجة'!D:D,"النظام الجديد (السيارات)",'الحركة المدمجة'!B:B,">="&DATE(2026,3,1),'الحركة المدمجة'!B:B,"<"&DATE(2026,4,1))
A20: 04-2026 | B20: =SUMIFS('الحركة المدمجة'!H:H,'الحركة المدمجة'!C:C,"عصمت الله خان",'الحركة المدمجة'!B:B,">="&DATE(2026,4,1),'الحركة المدمجة'!B:B,"<"&DATE(2026,5,1)) | C20: =SUMIFS('الحركة المدمجة'!H:H,'الحركة المدمجة'!C:C,"عماد حمدي",'الحركة المدمجة'!B:B,">="&DATE(2026,4,1),'الحركة المدمجة'!B:B,"<"&DATE(2026,5,1)) | D20: =SUMIFS('الحركة المدمجة'!H:H,'الحركة المدمجة'!C:C,"م/ عادل أبو خالد",'الحركة المدمجة'!B:B,">="&DATE(2026,4,1),'الحركة المدمجة'!B:B,"<"&DATE(2026,5,1)) | E20: =SUM(B20:D20) | F20: =SUMIFS('الحركة المدمجة'!H:H,'الحركة المدمجة'!D:D,"النظام الجديد (السيارات)",'الحركة المدمجة'!B:B,">="&DATE(2026,4,1),'الحركة المدمجة'!B:B,"<"&DATE(2026,5,1))
A21: 05-2026 | B21: =SUMIFS('الحركة المدمجة'!H:H,'الحركة المدمجة'!C:C,"عصمت الله خان",'الحركة المدمجة'!B:B,">="&DATE(2026,5,1),'الحركة المدمجة'!B:B,"<"&DATE(2026,6,1)) | C21: =SUMIFS('الحركة المدمجة'!H:H,'الحركة المدمجة'!C:C,"عماد حمدي",'الحركة المدمجة'!B:B,">="&DATE(2026,5,1),'الحركة المدمجة'!B:B,"<"&DATE(2026,6,1)) | D21: =SUMIFS('الحركة المدمجة'!H:H,'الحركة المدمجة'!C:C,"م/ عادل أبو خالد",'الحركة المدمجة'!B:B,">="&DATE(2026,5,1),'الحركة المدمجة'!B:B,"<"&DATE(2026,6,1)) | E21: =SUM(B21:D21) | F21: =SUMIFS('الحركة المدمجة'!H:H,'الحركة المدمجة'!D:D,"النظام الجديد (السيارات)",'الحركة المدمجة'!B:B,">="&DATE(2026,5,1),'الحركة المدمجة'!B:B,"<"&DATE(2026,6,1))
A22: 06-2026 | B22: =SUMIFS('الحركة المدمجة'!H:H,'الحركة المدمجة'!C:C,"عصمت الله خان",'الحركة المدمجة'!B:B,">="&DATE(2026,6,1),'الحركة المدمجة'!B:B,"<"&DATE(2026,7,1)) | C22: =SUMIFS('الحركة المدمجة'!H:H,'الحركة المدمجة'!C:C,"عماد حمدي",'الحركة المدمجة'!B:B,">="&DATE(2026,6,1),'الحركة المدمجة'!B:B,"<"&DATE(2026,7,1)) | D22: =SUMIFS('الحركة المدمجة'!H:H,'الحركة المدمجة'!C:C,"م/ عادل أبو خالد",'الحركة المدمجة'!B:B,">="&DATE(2026,6,1),'الحركة المدمجة'!B:B,"<"&DATE(2026,7,1)) | E22: =SUM(B22:D22) | F22: =SUMIFS('الحركة المدمجة'!H:H,'الحركة المدمجة'!D:D,"النظام الجديد (السيارات)",'الحركة المدمجة'!B:B,">="&DATE(2026,6,1),'الحركة المدمجة'!B:B,"<"&DATE(2026,7,1))
A23: 07-2026 | B23: =SUMIFS('الحركة المدمجة'!H:H,'الحركة المدمجة'!C:C,"عصمت الله خان",'الحركة المدمجة'!B:B,">="&DATE(2026,7,1),'الحركة المدمجة'!B:B,"<"&DATE(2026,8,1)) | C23: =SUMIFS('الحركة المدمجة'!H:H,'الحركة المدمجة'!C:C,"عماد حمدي",'الحركة المدمجة'!B:B,">="&DATE(2026,7,1),'الحركة المدمجة'!B:B,"<"&DATE(2026,8,1)) | D23: =SUMIFS('الحركة المدمجة'!H:H,'الحركة المدمجة'!C:C,"م/ عادل أبو خالد",'الحركة المدمجة'!B:B,">="&DATE(2026,7,1),'الحركة المدمجة'!B:B,"<"&DATE(2026,8,1)) | E23: =SUM(B23:D23) | F23: =SUMIFS('الحركة المدمجة'!H:H,'الحركة المدمجة'!D:D,"النظام الجديد (السيارات)",'الحركة المدمجة'!B:B,">="&DATE(2026,7,1),'الحركة المدمجة'!B:B,"<"&DATE(2026,8,1))
A24: الإجمالي | B24: =SUM(B2:B23) | C24: =SUM(C2:C23) | D24: =SUM(D2:D23) | E24: =SUM(E2:E23) | F24: =SUM(F2:F23)

Sheet مبيعات قبل 30.7.2025
A1: مبيعات مزرعة الرياض من 2024-10-01 إلى 2025-06-30
A2: م | B2: البيان | C2: المبلغ
A3: 1 | B3: مبيعات شهر أكتوبر 2024 | C3: 103500
A4: 2 | B4: مبيعات شهر نوفمبر 2024 | C4: 137450
A5: 3 | B5: مبيعات شهر ديسمبر 2024 | C5: 95230
A6: 4 | B6: مبيعات شهر يناير 2025 | C6: 55300
A7: 5 | B7: مبيعات شهر فبراير 2025 | C7: 35920
A8: 6 | B8: مبيعات شهر مارس 2025 | C8: 15100
A9: 7 | B9: مبيعات شهر إبريل 2025 | C9: 90160
A10: 8 | B10: مبيعات شهر مايو 2025 | C10: 50310
A11: 9 | B11: مبيعات شهر يونيه 2025 | C11: 27718
B12: إجمالي المبيعات | C12: =SUM(C3:C11)
A14: ملاحظات: الإجمالي 610,688.00 مطابق لمجموع الأشهر. المبيعات غير موزعة على المناديب. لا توجد بيانات مبيعات للفترة من 1-7-2025 إلى 29-7-2025.

Sheet مبيعات عصمت
A1: م | B1: التاريخ | C1: رقم العقد | D1: القيمة بشيت المحاسب | E1: القيمة المعتمدة | F1: الحالة | G1: المستندات المؤيدة | H1: ملاحظة | I1: المصدر
A2: 1 | B2: 45868 | C2: WHT-1908 | D2: 16658.75 | E2: 16658.75 | F2: صحيح | G2: سجل العقود | H2: بداية الفترة 30-7-2025 | I2: شيت المبيعات (عقود الجملة)
A3: 2 | B3: 45878 | C3: WHT-1892 | D3: 150 | E3: 150 | F3: صحيح | G3: سجل العقود | I3: شيت المبيعات (عقود الجملة)
A4: 3 | B4: 45885 | C4: WHT-1934 | D4: 162.5 | E4: 162.5 | F4: صحيح | G4: سجل العقود | I4: شيت المبيعات (عقود الجملة)
A5: 4 | B5: 45885 | C5: WHT-1937 | D5: 50 | E5: 50 | F5: صحيح | G5: سجل العقود | I5: شيت المبيعات (عقود الجملة)
A6: 5 | B6: 45887 | C6: WHT-1952 | D6: 450 | E6: 450 | F6: صحيح | G6: سجل العقود | I6: شيت المبيعات (عقود الجملة)
A7: 6 | B7: 45889 | C7: WHT-1970 | D7: 125 | E7: 125 | F7: صحيح | G7: سجل العقود | I7: شيت المبيعات (عقود الجملة)
A8: 7 | B8: 45890 | C8: WHT-1999 | D8: 800 | E8: 800 | F8: صحيح | G8: سجل العقود | I8: شيت المبيعات (عقود الجملة)
A9: 8 | B9: 45892 | C9: WHT-2007 | D9: 155 | E9: 155 | F9: صحيح | G9: سجل العقود | I9: شيت المبيعات (عقود الجملة)
A10: 9 | B10: 45894 | C10: WHT-2030 | D10: 350 | E10: 350 | F10: صحيح | G10: سجل العقود | I10: شيت المبيعات (عقود الجملة)
A11: 10 | B11: 45895 | C11: WHT-2040 | D11: 205 | E11: 205 | F11: صحيح | G11: سجل العقود | I11: شيت المبيعات (عقود الجملة)
A12: 11 | B12: 45897 | C12: WHT-2065 | D12: 62.5 | E12: 62.5 | F12: صحيح | G12: سجل العقود | I12: شيت المبيعات (عقود الجملة)
A13: 12 | B13: 45901 | C13: WHT-2084 | D13: 202.5 | E13: 202.5 | F13: صحيح | G13: سجل العقود | I13: شيت المبيعات (عقود الجملة)
A14: 13 | B14: 45904 | C14: WHT-2112 | D14: 517.5 | E14: 517.5 | F14: صحيح | G14: سجل العقود | I14: شيت المبيعات (عقود الجملة)
... A31: 30 | B31: 45930 | C31: WHT-2344 | D31: 2485 | E31: 2485 | F31: صحيح | G31: سجل العقود | I31: شيت المبيعات (عقود الجملة)
A32: 31 | B32: 45931 | C32: WHT-2348 | D32: 0 | E32: 3920 | F32: مضاف | G32: سجل العقود | H32: موجود في سجل العقود وسقط من شيت المحاسب (المحاسب بدأ من 9-10 رغم إدراجه عقود أقدم) | I32: شيت المبيعات (عقود الجملة)
A33: 32 | B33: 45932 | C33: WHT-2358 | D33: 0 | E33: 4910 | F33: مضاف | G33: سجل العقود | H33: موجود في سجل العقود وسقط من شيت المحاسب (المحاسب بدأ من 9-10 رغم إدراجه عقود أقدم) | I33: شيت المبيعات (عقود الجملة)
A34: 33 | B34: 45934 | C34: WHT-2378 | D34: 0 | E34: 4760 | F34: مضاف | G34: سجل العقود | H34: موجود في سجل العقود وسقط من شيت المحاسب (المحاسب بدأ من 9-10 رغم إدراجه عقود أقدم) | I34: شيت المبيعات (عقود الجملة)
A35: 34 | B35: 45935 | C35: WHT-2756 | D35: 0 | E35: 3520 | F35: مضاف | G35: سجل العقود | H35: موجود في سجل العقود فقط (بدون فاتورة مبدئية وغير مسجل بالكشف) – يحتاج تأكيد | I35: شيت المبيعات (عقود الجملة)
A36: 35 | B36: 45936 | C36: WHT-2758 | D36: 0 | E36: 13290 | F36: مضاف | G36: سجل العقود | H36: موجود في سجل العقود فقط (بدون فاتورة مبدئية وغير مسجل بالكشف) – يحتاج تأكيد | I36: شيت المبيعات (عقود الجملة)
A37: 36 | B37: 45938 | C37: WHT-2408 | D37: 0 | E37: 7497.5 | F37: مضاف | G37: سجل العقود | H37: موجود في سجل العقود وسقط من شيت المحاسب (المحاسب بدأ من 9-10 رغم إدراجه عقود أقدم) | I37: شيت المبيعات (عقود الجملة)
A38: 37 | B38: 45939 | C38: WHT-2423 | D38: 5790 | E38: 5790 | F38: صحيح | G38: سجل العقود | I38: شيت المبيعات (عقود الجملة)
A39: 38 | B39: 45941 | C39: WHT-2437 | D39: 10270 | E39: 10270 | F39: صحيح | G39: سجل العقود | I39: شيت المبيعات (عقود الجملة)
A40: 39 | B40: 45942 | C40: WHT-2454 | D40: 6282.5 | E40: 6282.5 | F40: صحيح | G40: سجل العقود | I40: شيت المبيعات (عقود الجملة)
A41: 40 | B41: 45943 | C41: WHT-2471 | D41: 3275 | E41: 3275 | F41: صحيح | G41: سجل العقود | I41: شيت المبيعات (عقود الجملة)
A42: 41 | B42: 45944 | C42: WHT-2483 | D42: 6077.5 | E42: 6077.5 | F42: صحيح | G42: سجل العقود | I42: شيت المبيعات (عقود الجملة)
A43: 42 | B43: 45945 | C43: WHT-2501 | D43: 6087.5 | E43: 6087.5 | F43: صحيح | G43: سجل العقود | I43: شيت المبيعات (عقود الجملة)
A44: 43 | B44: 45946 | C44: WHT-2511 | D44: 3365 | E44: 3365 | F44: صحيح | G44: سجل العقود | I44: شيت المبيعات (عقود الجملة)
A45: 44 | B45: 45949 | C45: WHT-2541 | D45: 8378.75 | E45: 8378.75 | F45: صحيح | G45: سجل العقود | I45: شيت المبيعات (عقود الجملة)
A46: 45 | B46: 45950 | C46: WHT-2549 | D46: 6680 | E46: 6680 | F46: صحيح | G46: سجل العقود | I46: شيت المبيعات (عقود الجملة)
A47: 46 | B47: 45951 | C47: WHT-2585 | D47: 2355 | E47: 2355 | F47: صحيح | G47: سجل العقود | I47: شيت المبيعات (عقود الجملة)
A48: 47 | B48: 45952 | C48: WHT-2596 | D48: 4715 | E48: 4715 | F48: صحيح | G48: سجل العقود | I48: شيت المبيعات (عقود الجملة)
A49: 48 | B49: 45953 | C49: WHT-2607 | D49: 5998.75 | E49: 5998.75 | F49: صحيح | G49: سجل العقود | I49: شيت المبيعات (عقود الجملة)
... A133: 132 | B133: 46062 | C133: WHT-3786 | D133: 6900 | E133: 6900 | F133: صحيح | G133: فاتورة مبدئية 147، سجل العقود، كشف الحساب | I133: شيت المبيعات (عقود الجملة)
A134: 133 | B134: 46063 | C134: WHT-3804 | D134: 4472.5 | E134: 4472.5 | F134: صحيح (تصحيح رقم) | G134: فاتورة مبدئية 148، سجل العقود | H134: رقم العقد مكرر في شيت المحاسب – الصحيح WHT-3804 | I134: شيت المبيعات (عقود الجملة)
A135: 134 | B135: 46064 | C135: WHT-3814 | D135: 6267.5 | E135: 6267.5 | F135: صحيح | G135: فاتورة مبدئية 150، سجل العقود، كشف الحساب | I135: شيت المبيعات (عقود الجملة)
A136: 135 | B136: 46065 | C136: WHT-3828 | D136: 5862.5 | E136: 5862.5 | F136: صحيح | G136: فاتورة مبدئية 151، سجل العقود، كشف الحساب | I136: شيت المبيعات (عقود الجملة)
A137: 136 | B137: 46067 | C137: WHT-3837 | D137: 7380 | E137: 7380 | F137: صحيح | G137: فاتورة مبدئية 153، سجل العقود، كشف الحساب | I137: شيت المبيعات (عقود الجملة)
A138: 137 | B138: 46068 | C138: WHT-3851 | D138: 5520 | E138: 5520 | F138: صحيح | G138: فاتورة مبدئية 155، سجل العقود، كشف الحساب | I138: شيت المبيعات (عقود الجملة)
A139: 138 | B139: 46069 | C139: WHT-3857 | D139: 5447.75 | E139: 5447.75 | F139: صحيح | G139: فاتورة مبدئية 156، سجل العقود، كشف الحساب | I139: شيت المبيعات (عقود الجملة)
...

Sheet مبيعات عماد
A1: م | B1: التاريخ | C1: رقم العقد | D1: القيمة بشيت المحاسب | E1: القيمة المعتمدة | F1: الحالة | G1: المستندات المؤيدة | H1: ملاحظة | I1: المصدر
A2: 1 | B2: 45983 | C2: WHE-2973 | D2: 6315 | E2: 6315 | F2: صحيح | G2: فاتورة مبدئية 62، سجل العقود، كشف الحساب | I2: شيت المبيعات (عقود الجملة)
A3: 2 | B3: 45987 | C3: WHE-3011 | D3: 8300.5 | E3: 8300.5 | F3: صحيح | G3: فاتورة مبدئية 67، سجل العقود، كشف الحساب | I3: شيت المبيعات (عقود الجملة)
A4: 3 | B4: 45989 | C4: WHE-3041 | D4: 7387.5 | E4: 7387.5 | F4: صحيح | G4: فاتورة مبدئية 70، سجل العقود، كشف الحساب | I4: شيت المبيعات (عقود الجملة)
A5: 4 | B5: 45991 | C5: WHE-3076 | D5: 8400 | E5: 8400 | F5: صحيح | G5: فاتورة مبدئية 73، سجل العقود، كشف الحساب | I5: شيت المبيعات (عقود الجملة)
A6: 5 | B6: 46002 | C6: WHE-3212 | D6: 10731.25 | E6: 10731.25 | F6: صحيح | G6: فاتورة مبدئية 85، سجل العقود، كشف الحساب | I6: شيت المبيعات (عقود الجملة)
A7: 6 | B7: 46006 | C7: WHE-3245 | D7: 4845.5 | E7: 4845.5 | F7: صحيح | G7: فاتورة مبدئية 90، سجل العقود، كشف الحساب | I7: شيت المبيعات (عقود الجملة)
A8: 7 | B8: 46008 | C8: WHE-3274 | D8: 6818.5 | E8: 6818.5 | F8: صحيح | G8: فاتورة مبدئية 94، سجل العقود، كشف الحساب | I8: شيت المبيعات (عقود الجملة)
A9: 8 | B9: 46021 | C9: WHE-3402 | D9: 6097.5 | E9: 6097.5 | F9: صحيح | G9: فاتورة مبدئية 104، كشف الحساب | I9: شيت المبيعات (عقود الجملة)
A10: 9 | B10: 46024 | C10: WHE-3424 | D10: 6577.5 | E10: 6577.5 | F10: صحيح | G10: فاتورة مبدئية 106، سجل العقود، كشف الحساب | I10: شيت المبيعات (عقود الجملة)
A11: 10 | B11: 46027 | C11: WHE-3475 | D11: 8985 | E11: 8985 | F11: صحيح | G11: فاتورة مبدئية 111، سجل العقود، كشف الحساب | I11: شيت المبيعات (عقود الجملة)
A12: 11 | B12: 46037 | C12: WHE-3570 | D12: 8562.5 | E12: 8562.5 | F12: صحيح | G12: فاتورة مبدئية 120، سجل العقود، كشف الحساب | I12: شيت المبيعات (عقود الجملة)
A13: 12 | B13: 46042 | C13: WHE-3615 | D13: 6699.5 | E13: 6699.5 | F13: صحيح | G13: فاتورة مبدئية 124، سجل العقود، كشف الحساب | I13: شيت المبيعات (عقود الجملة)
... A59: 58 | B59: 46233 | C59: WS-INV-0255 | D59: 75 | E59: 75 | F59: النظام الجديد | G59: النظام الجديد – سيارة 3010 – مؤسسة فارس علي السالمي التجارية ( اسماعيل ) - الرياض | I59: النظام الجديد (سيارة 3010)
C60: الإجمالي | D60: =SUM(D2:D59) | E60: =SUM(E2:E59)

Sheet مبيعات أبو خالد
A1: م | B1: التاريخ | C1: رقم العقد | D1: القيمة بشيت المحاسب | E1: القيمة المعتمدة | F1: الحالة | G1: المستندات المؤيدة | H1: ملاحظة | I1: المصدر
A2: 1 | B2: 45868 | C2: WHK-1909 | D2: 11570 | E2: 11570 | F2: صحيح | G2: لا يوجد مستند مؤيد | H2: بداية الفترة 30-7-2025 | I2: شيت المبيعات (عقود الجملة)
A3: 2 | B3: 45909 | C3: WHK-2148 | D3: 3320 | E3: 3320 | F3: صحيح | G3: لا يوجد مستند مؤيد | I3: شيت المبيعات (عقود الجملة)
A4: 3 | B4: 45923 | C4: WHK-2271 | D4: 2400 | E4: 2400 | F4: صحيح | G4: لا يوجد مستند مؤيد | I4: شيت المبيعات (عقود الجملة)
A5: 4 | B5: 45924 | C5: WHK-2283 | D5: 2800 | E5: 2800 | F5: صحيح | G5: لا يوجد مستند مؤيد | I5: شيت المبيعات (عقود الجملة)
A6: 5 | B6: 45929 | C6: WHK-2328 | D6: 4550 | E6: 4550 | F6: صحيح | G6: لا يوجد مستند مؤيد | I6: شيت المبيعات (عقود الجملة)
A7: 6 | B7: 45935 | C7: WHK-2364 | D7: 440000 | E7: ='مطابقة كميات عقد عرعر'!E11 | F7: معدّل | G7: كشف الحساب | H7: عقد عرعر: الكميات الفعلية (205,750 من الرياض + 69,625 من تبوك) × 0.50 = 137,687.50 – بدل قيمة العقد 440,000. مشتريات الجزيرة خاصة ببساتين الرياض. | I7: شيت المبيعات (عقود الجملة)
A8: 7 | B8: 45938 | C8: WHK-2411 | D8: 4200 | E8: 4200 | F8: صحيح | G8: لا يوجد مستند مؤيد | I8: شيت المبيعات (عقود الجملة)
A9: 8 | B9: 45939 | C9: WHK-2425 | D9: 11000 | E9: 11000 | F9: صحيح | G9: لا يوجد مستند مؤيد | I9: شيت المبيعات (عقود الجملة)
A10: 9 | B10: 45941 | C10: WHK-2434 | D10: 70250 | E10: 70250 | F10: صحيح | G10: لا يوجد مستند مؤيد | I10: شيت المبيعات (عقود الجملة)
A11: 10 | B11: 45943 | C11: WHK-2465 | D11: 1750 | E11: 1750 | F11: صحيح | G11: لا يوجد مستند مؤيد | I11: شيت المبيعات (عقود الجملة)
A12: 11 | B12: 45944 | C12: WHK-2480 | D12: 412.5 | E12: 412.5 | F12: صحيح | G12: لا يوجد مستند مؤيد | I12: شيت المبيعات (عقود الجملة)
A13: 12 | B13: 45945 | C13: WHK-2498 | D13: 17055 | E13: 17055 | F13: صحيح | G13: لا يوجد مستند مؤيد | I13: شيت المبيعات (عقود الجملة)
A14: 13 | B14: 45946 | C14: WHK-2509 | D14: 3150 | E14: 3150 | F14: صحيح | G14: لا يوجد مستند مؤيد | I14: شيت المبيعات (عقود الجملة)
A15: 14 | B15: 45948 | C15: WHK-2515 | D15: 6975 | E15: 6975 | F15: صحيح | G15: لا يوجد مستند مؤيد | I15: شيت المبيعات (عقود الجملة)
A16: 15 | B16: 45951 | C16: WHK-2563 | D16: 2925 | E16: 2925 | F16: صحيح | G16: لا يوجد مستند مؤيد | I16: شيت المبيعات (عقود الجملة)
A17: 16 | B17: 45952 | C17: WHK-2583 | D17: 4125 | E17: 4125 | F17: صحيح | G17: لا يوجد مستند مؤيد | I17: شيت المبيعات (عقود الجملة)
A18: 17 | B18: 45953 | C18: WHK-2605 | D18: 1331.25 | E18: 1331.25 | F18: صحيح | G18: لا يوجد مستند مؤيد | I18: شيت المبيعات (عقود الجملة)
A19: 18 | B19: 45955 | C19: WHK-2626 | D19: 2150 | E19: 2150 | F19: صحيح | G19: لا يوجد مستند مؤيد | I19: شيت المبيعات (عقود الجملة)
... A36: 35 | B36: 46006 | C36: WHK-3243 | D36: 1875 | E36: 1875 | F36: صحيح | G36: فاتورة مبدئية 89، كشف الحساب | I36: شيت المبيعات (عقود الجملة)
A37: 36 | B37: 46021 | C37: WHK-3400 | D37: 0 | E37: 505 | F37: مضاف | G37: فاتورة مبدئية 103، كشف الحساب | H37: فاتورة مبدئية 103 ومسجلة بكشف الحساب – سقطت من شيت المحاسب | I37: شيت المبيعات (عقود الجملة)
A38: 37 | B38: 46058 | C38: WHK-3758 | D38: 20300 | E38: 20300 | F38: صحيح | G38: فاتورة مبدئية 140، كشف الحساب | I38: شيت المبيعات (عقود الجملة)
A39: 38 | B39: 46058 | C39: WHK-3760 | D39: 30850 | E39: 30850 | F39: صحيح | G39: فاتورة مبدئية 141، كشف الحساب | I39: شيت المبيعات (عقود الجملة)
A40: 39 | B40: 46064 | C40: WHK-3809 | D40: 3125 | E40: 3125 | F40: صحيح | G40: فاتورة مبدئية 149، كشف الحساب | I40: شيت المبيعات (عقود الجملة)
A41: 40 | B41: 46072 | C41: WHK-3878 | D41: 2012.5 | E41: 2012.5 | F41: صحيح | G41: فاتورة مبدئية 160، كشف الحساب | I41: شيت المبيعات (عقود الجملة)
A42: 41 | B42: 46084 | C42: WHK-3923 | D42: 6862.5 | E42: 6862.5 | F42: صحيح | G42: فاتورة مبدئية 166، كشف الحساب | I42: شيت المبيعات (عقود الجملة)
A43: 42 | B43: 46085 | C43: WHK-3963 | D43: 2700 | E43: 2700 | F43: صحيح | G43: فاتورة مبدئية 174، كشف الحساب | I43: شيت المبيعات (عقود الجملة)
A44: 43 | B44: 46145 | C44: WHK-4256 | D44: 19490 | E44: 19490 | F44: صحيح | G44: فاتورة مبدئية 227، كشف الحساب | I44: شيت المبيعات (عقود الجملة)
A45: 44 | B45: 46147 | C45: WHK-4275 | D45: 21780 | E45: 21780 | F45: صحيح | G45: فاتورة مبدئية 231، كشف الحساب | I45: شيت المبيعات (عقود الجملة)
A46: 45 | B46: 46152 | C46: WHK-4291 | D46: 3135 | E46: 3135 | F46: صحيح | G46: فاتورة مبدئية 239، كشف الحساب | I46: شيت المبيعات (عقود الجملة)
A47: 46 | B47: 46154 | C47: WHK-4305 | D47: 3025 | E47: 3025 | F47: صحيح | G47: فاتورة مبدئية 243، كشف الحساب | I47: شيت المبيعات (عقود الجملة)
A48: 47 | B48: 46160 | C48: WHK-4323 | D48: 750 | E48: 750 | F48: صحيح | G48: فاتورة مبدئية 250، كشف الحساب | I48: شيت المبيعات (عقود الجملة)
C49: الإجمالي | D49: =SUM(D2:D48) | E49: =SUM(E2:E48)

Sheet أبو خالد - تفصيل البنود
A1: رقم العقد | B1: تاريخ العقد | C1: رقم الفاتورة المبدئية | D1: كود الصنف | E1: اسم الصنف | F1: الكمية | G1: الوحدة | H1: سعر الوحدة | I1: الإجمالي | J1: ملاحظة
A2: WHK-1909 | B2: 45868 | C2: — | D2: — | E2: لا توجد بنود تفصيلية | I2: 11570 | J2: لا توجد فاتورة مبدئية لهذا العقد (القيمة من شيت المحاسب WHK2025)
A3: إجمالي العقد WHK-1909 | I3: =SUM(I2:I2) | J3: تاريخه 2025-07-30 قبل بداية الفترة 31-7-2025 بيوم – أُدرج بناءً على طلبك
A4: WHK-2148 | B4: 45909 | C4: — | D4: — | E4: لا توجد بنود تفصيلية | I4: 3320 | J4: لا توجد فاتورة مبدئية لهذا العقد (القيمة من شيت المحاسب WHK2025)
A5: إجمالي العقد WHK-2148 | I5: =SUM(I4:I4)
A6: WHK-2271 | B6: 45923 | C6: — | D6: — | E6: لا توجد بنود تفصيلية | I6: 2400 | J6: لا توجد فاتورة مبدئية لهذا العقد (القيمة من شيت المحاسب WHK2025)
A7: إجمالي العقد WHK-2271 | I7: =SUM(I6:I6)
A8: WHK-2283 | B8: 45924 | C8: — | D8: — | E8: لا توجد بنود تفصيلية | I8: 2800 | J8: لا توجد فاتورة مبدئية لهذا العقد (القيمة من شيت المحاسب WHK2025)
A9: إجمالي العقد WHK-2283 | I9: =SUM(I8:I8)
A10: WHK-2328 | B10: 45929 | C10: — | D10: — | E10: لا توجد بنود تفصيلية | I10: 4550 | J10: لا توجد فاتورة مبدئية لهذا العقد (القيمة من شيت المحاسب WHK2025)
A11: إجمالي العقد WHK-2328 | I11: =SUM(I10:I10)
A12: WHK-2364 | B12: 45935 | C12: RN-INV#40 | D12: RN-OD560 | E12: زهور بيتونيا | F12: 40000 | G12: EA | H12: 0.5 | I12: =F12*H12 | J12: بالفاتورة رقم العقد WHK-2807 – مسجلة بالكشف على عقد عرعر
A13: WHK-2364 | B13: 45935 | C13: RN-INV#45 | D13: RN-OD560 | E13: زهور بيتونيا | F13: 41250 | G13: EA | H13: 0.5 | I13: =F13*H13 | J13: بالفاتورة رقم العقد RNW-2842 – مسجلة بالكشف على عقد عرعر
A14: WHK-2364 | B14: 45935 | C14: RN-INV#54 | D14: RN-OD560 | E14: زهور بيتونيا | F14: 42000 | G14: EA | H14: 0.5 | I14: =F14*H14 | J14: بالفاتورة رقم العقد RNW-2945 – مسجلة بالكشف على عقد عرعر
A15: WHK-2364 | B15: 45935 | C15: RN-INV#84 | D15: RN-OD560 | E15: زهور بيتونيا | F15: 42500 | G15: EA | H15: 0.5 | I15: =F15*H15 | J15: بالفاتورة رقم العقد RNW-3210 – مسجلة بالكشف على عقد عرعر
A16: WHK-2364 | B16: 45935 | C16: RN-INV#100 | D16: RN-OD560 | E16: زهور بيتونيا | F16: 30000 | G16: EA | H16: 0.5 | I16: =F16*H16 | J16: بالفاتورة رقم العقد RNW-3357 – مسجلة بالكشف على عقد عرعر
A17: WHK-2364 | B17: 45935 | C17: RN-INV#100 | D17: RN-OD561 | E17: زهور مارى جولد | F17: 10000 | G17: EA | H17: 0.5 | I17: =F17*H17 | J17: بالفاتورة رقم العقد RNW-3357 – مسجلة بالكشف على عقد عرعر
A18: WHK-2364 | B18: 45935 | C18: ترحيل من تبوك | D18: RN-OD560 | E18: زهور بيتونيا | F18: 69625 | G18: EA | H18: 0.5 | I18: =F18*H18 | J18: محوّل من مزرعة تبوك (سندا TNR-2689 و TNR-2888 = 72,625 حبة − 3,000 تالف)
A19: إجمالي العقد WHK-2364 | I19: =SUM(I12:I18) | J19: عقد عرعر = الكميات المصروفة من الرياض + المحوّلة من تبوك × 0.50 (مشتريات الجزيرة خاصة ببساتين – محذوفة)
A20: WHK-2411 | B20: 45938 | C20: — | D20: — | E20: لا توجد بنود تفصيلية | I20: 4200 | J20: لا توجد فاتورة مبدئية لهذا العقد (القيمة من شيت المحاسب WHK2025)
A21: إجمالي العقد WHK-2411 | I21: =SUM(I20:I20)
A22: WHK-2425 | B22: 45939 | C22: — | D22: — | E22: لا توجد بنود تفصيلية | I22: 11000 | J22: لا توجد فاتورة مبدئية لهذا العقد (القيمة من شيت المحاسب WHK2025)
A23: إجمالي العقد WHK-2425 | I23: =SUM(I22:I22)
A24: WHK-2434 | B24: 45941 | C24: — | D24: — | E24: لا توجد بنود تفصيلية | I24: 70250 | J24: لا توجد فاتورة مبدئية لهذا العقد (القيمة من شيت المحاسب WHK2025)
A25: إجمالي العقد WHK-2434 | I25: =SUM(I24:I24)
A26: WHK-2465 | B26: 45943 | C26: — | D26: — | E26: لا توجد بنود تفصيلية | I26: 1750 | J26: لا توجد فاتورة مبدئية لهذا العقد (القيمة من شيت المحاسب WHK2025)
A27: إجمالي العقد WHK-2465 | I27: =SUM(I26:I26)
A28: WHK-2480 | B28: 45944 | C28: — | D28: — | E28: لا توجد بنود تفصيلية | I28: 412.5 | J28: لا توجد فاتورة مبدئية لهذا العقد (القيمة من شيت المحاسب WHK2025)
A29: إجمالي العقد WHK-2480 | I29: =SUM(I28:I28)
A30: WHK-2498 | B30: 45945 | C30: — | D30: — | E30: لا توجد بنود تفصيلية | I30: 17055 | J30: لا توجد فاتورة مبدئية لهذا العقد (القيمة من شيت المحاسب WHK2025)
A31: إجمالي العقد WHK-2498 | I31: =SUM(I30:I30)
A32: WHK-2509 | B32: 45946 | C32: — | D32: — | E32: لا توجد بنود تفصيلية | I32: 3150 | J32: لا توجد فاتورة مبدئية لهذا العقد (القيمة من شيت المحاسب WHK2025)
A33: إجمالي العقد WHK-2509 | I33: =SUM(I32:I32)
A34: WHK-2515 | B34: 45948 | C34: — | D34: — | E34: لا توجد بنود تفصيلية | I34: 6975 | J34: لا توجد فاتورة مبدئية لهذا العقد (القيمة من شيت المحاسب WHK2025)
A35: إجمالي العقد WHK-2515 | I35: =SUM(I34:I34)
A36: WHK-2563 | B36: 45951 | C36: — | D36: — | E36: لا توجد بنود تفصيلية | I36: 2925 | J36: لا توجد فاتورة مبدئية لهذا العقد (القيمة من شيت المحاسب WHK2025)
A37: إجمالي العقد WHK-2563 | I37: =SUM(I36:I36)
A38: WHK-2583 | B38: 45952 | C38: — | D38: — | E38: لا توجد بنود تفصيلية | I38: 4125 | J38: لا توجد فاتورة مبدئية لهذا العقد (القيمة من شيت المحاسب WHK2025)
A39: إجمالي العقد WHK-2583 | I39: =SUM(I38:I38)
