Workbook

Sheet الملخص
A1: المصاريف التشغيلية – مزرعة الرياض (1-1-2026 إلى 31-7-2026)
A3: البند | B3: العدد | C3: المبلغ | D3: ملاحظة
A4: أولاً: أوامر الشراء (مشتريات المزرعة)
A5: أوامر مدفوعة بالكامل | B5: 29 | C5: 497518.61
A6: أوامر مدفوعة جزئياً | B6: 1 | C6: 66420 | D6: PO-0777 (بساتين الرياض) – المبلغ المدفوع غير موضح
A7: أوامر غير مدفوعة | B7: 1 | C7: 33950 | D7: PO-1023 (بساتين الرياض)
A8: إجمالي أوامر الشراء | B8: 31 | C8: 597888.61
A9: المديونية القائمة للموردين (حد أقصى) | B9: 2 | C9: 100370 | D9: =غير المدفوع + المدفوع جزئياً بالكامل لحين معرفة المسدد من PO-0777
A10: ثانياً: مصروفات العهد النقدية (تسويات معتمدة)
A11: داخل الفترة حتى 31-7-2026 | B11: 147 | C11: 44851.46 | D11: تفصيلها حسب البند والسيارة في شيت "العهد - ملخص"
A12: بعد 31-7-2026 (خارج الفترة) | B12: 31 | C12: 4966.02
A13: أرصدة عهد لم تُسوَّ بعد | C13: 1543.91 | D13: مبالغ صُرفت لأصحاب العهد ولم تُقدم بها مستندات حتى تاريخ التقارير 9-8-2026
A14: يُخصم: أوامر 2026 هي سداد لمشتريات 2025 (PO-288، PO-287-REV1، PO-296، PO-295) | B14: 4 | C14: -211811.25 | D14: مصروفات تخص 2025 وسُددت في 2026 – مدرجة في شيت مصروفات 2025
A15: إجمالي المصاريف التشغيلية 2026 (أوامر الشراء + العهد، بعد استبعاد سداد 2025) | C15: =C8+C11+C14
A17: ملاحظات المراجعة:
A18: 1) كل تقارير العهد الأربعة مطابقة: مجموع التسويات = "TOTAL SETTLED" بكل تقرير، ومجموع الإضافات = "TOTAL GRANTED".
A19: 2) ⚠ مديونية قائمة: PO-1023 (33,950 غير مدفوع) و PO-0777 (66,420 مدفوع جزئياً) – كلاهما لمؤسسة بساتين الرياض وتم استلامهما بالكامل.
A20: 3) ⚠ 27 أمر شراء حالة الاستلام فيها "Not Issued" رغم أنها مدفوعة بالكامل – يعني الاستلام لم يُسجل بالنظام.
A21: 4) ⚠ المدارات: أمران بنفس القيمة 53,475 (PO-267 و PO-309) – يلزم التأكد أنهما توريدان مختلفان.
A22: 5) أوامر PO-288 و PO-287-REV1 و PO-295 و PO-296 (211,811.25) هي سداد لمشتريات 2025 غير مدفوعة – تم استبعادها من مصاريف 2026.
A23: 6) ⚠ تداخل محتمل: مصروفات الديزل بالعهد (سيارات 1219 و 3010) قد تكون جزءاً من إجمالي الديزل 2026 (24,888) في شيت "الديزل المدفوع من نسما الشرق" – يلزم التأكد لتجنب الاحتساب مرتين.
A24: 7) عهدة حسين مصطفى تشمل إضافات "نقداً" بقيمة 39,518.39 (عمود المنصرف = 0) – أي أنها صُرفت نقداً من خارج النظام.
A25: 8) مصروفات 2025 مضافة في شيتي "مصروفات 2025 - تفصيل" و"مصروفات 2025 - ملخص".

Sheet أوامر الشراء
A1: م | B1: رقم أمر الشراء | C1: التاريخ | D1: المورد | E1: المرجع | F1: القيمة قبل الضريبة | G1: الضريبة | H1: الإجمالي بعد الضريبة | I1: حالة الاستلام | J1: حالة الدفع | K1: المديونية القائمة | L1: ملاحظة
A2: 1 | B2: PO-288 | C2: 46024 | D2: بساتين الرياض | E2: RN-711 | F2: 75005 | G2: 11250.75 | H2: 86255.75 | I2: لم يُسجل الاستلام | J2: مدفوع بالكامل | K2: 0 | L2: ⚠ سداد لمشتريات 2025 غير مدفوعة: PO711 + PO748 (بساتين الرياض – 2025) – لا يُحتسب كمصروف 2026 | حالة الاستلام "Not Issued" رغم أنه مدفوع بالكامل – لم يُسجل استلام بالنظام | ⚠ تاريخ الأمر (يناير 2026) لا يتناسب مع تسلسل الرقم (بين أوامر فبراير–مارس) – ربما سُجل بأثر رجعي
A3: 2 | B3: PO-287-REV1 | C3: 46025 | D3: بساتين الرياض | E3: RN-838 | F3: 53470 | G3: 8020.5 | H3: 61490.5 | I3: لم يُسجل الاستلام | J3: مدفوع بالكامل | K3: 0 | L3: ⚠ سداد لمشتريات 2025 غير مدفوعة: PO838 + PO876 (بساتين الرياض – 2025) – لا يُحتسب كمصروف 2026 | حالة الاستلام "Not Issued" رغم أنه مدفوع بالكامل – لم يُسجل استلام بالنظام | ⚠ تاريخ الأمر (يناير 2026) لا يتناسب مع تسلسل الرقم (بين أوامر فبراير–مارس) – ربما سُجل بأثر رجعي | أمر معدّل (REV1)
A4: 3 | B4: PO-9 | C4: 46025 | D4: شركة مصنع الديكور والبولستيرين | E4: RN-2 | F4: 4200 | G4: 630 | H4: 4830 | I4: لم يُسجل الاستلام | J4: مدفوع بالكامل | K4: 0 | L4: حالة الاستلام "Not Issued" رغم أنه مدفوع بالكامل – لم يُسجل استلام بالنظام | ⚠ نفس المورد ونفس القيمة في أمرين (المدارات 53,475: PO-267 في 19-2 و PO-309 في 3-3) – يلزم التأكد أنهما توريدان مختلفان
A5: 4 | B5: PO-296 | C5: 46027 | D5: مشتل الجودة المطلقة | E5: RN-877 | F5: 49550 | G5: 0 | H5: 49550 | I5: لم يُسجل الاستلام | J5: مدفوع بالكامل | K5: 0 | L5: ⚠ سداد لمشتريات 2025 غير مدفوعة: PO877 + PO878 (مشتل الجودة – 2025) – لا يُحتسب كمصروف 2026 | حالة الاستلام "Not Issued" رغم أنه مدفوع بالكامل – لم يُسجل استلام بالنظام | ⚠ تاريخ الأمر (يناير 2026) لا يتناسب مع تسلسل الرقم (بين أوامر فبراير–مارس) – ربما سُجل بأثر رجعي
A6: 5 | B6: PO-295 | C6: 46027 | D6: شركة غرس نجد | E6: RN-1606 | F6: 14515 | G6: 0 | H6: 14515 | I6: لم يُسجل الاستلام | J6: مدفوع بالكامل | K6: 0 | L6: ⚠ سداد لمشتريات 2025 غير مدفوعة: فاتورة غرس نجد 4-8-2025 – لا يُحتسب كمصروف 2026 | حالة الاستلام "Not Issued" رغم أنه مدفوع بالكامل – لم يُسجل استلام بالنظام | ⚠ تاريخ الأمر (يناير 2026) لا يتناسب مع تسلسل الرقم (بين أوامر فبراير–مارس) – ربما سُجل بأثر رجعي
A7: 6 | B7: PO-67 | C7: 46032 | D7: شركة مصنع الديكور والبولستيرين | E7: RN-3 | F7: 2100 | G7: 315 | H7: 2415 | I7: لم يُسجل الاستلام | J7: مدفوع بالكامل | K7: 0 | L7: حالة الاستلام "Not Issued" رغم أنه مدفوع بالكامل – لم يُسجل استلام بالنظام
A8: 7 | B8: PO-121 | C8: 46043 | D8: شركة مصنع الديكور والبولستيرين | E8: RN-5 | F8: 4200 | G8: 630 | H8: 4830 | I8: لم يُسجل الاستلام | J8: مدفوع بالكامل | K8: 0 | L8: حالة الاستلام "Not Issued" رغم أنه مدفوع بالكامل – لم يُسجل استلام بالنظام | ⚠ نفس المورد ونفس القيمة في أمرين (المدارات 53,475: PO-267 في 19-2 و PO-309 في 3-3) – يلزم التأكد أنهما توريدان مختلفان
A9: 8 | B9: PO-146 | C9: 46049 | D9: بساتين الرياض | E9: RN-8 | F9: 32750 | G9: 0 | H9: 32750 | I9: لم يُسجل الاستلام | J9: مدفوع بالكامل | K9: 0 | L9: حالة الاستلام "Not Issued" رغم أنه مدفوع بالكامل – لم يُسجل استلام بالنظام
A10: 9 | B10: PO-181 | C10: 46054 | D10: شركة مصنع الديكور والبولستيرين | E10: RN-158 | F10: 8148 | G10: 1222.2 | H10: 9370.2 | I10: لم يُسجل الاستلام | J10: مدفوع بالكامل | K10: 0 | L10: حالة الاستلام "Not Issued" رغم أنه مدفوع بالكامل – لم يُسجل استلام بالنظام
A11: 10 | B11: PO-210 | C11: 46060 | D11: مصتع قطاف للاسمدة (البقرة السودة ) | E11: RN-PR-191 | F11: 1739.13 | G11: 260.87 | H11: 2000 | I11: لم يُسجل الاستلام | J11: مدفوع بالكامل | K11: 0 | L11: حالة الاستلام "Not Issued" رغم أنه مدفوع بالكامل – لم يُسجل استلام بالنظام
A12: 11 | B12: PO-228-REV1 | C12: 46063 | D12: شركة مصنع الديكور والبولستيرين | E12: RN-PR#203 | F12: 8400 | G12: 1260 | H12: 9660 | I12: لم يُسجل الاستلام | J12: مدفوع بالكامل | K12: 0 | L12: حالة الاستلام "Not Issued" رغم أنه مدفوع بالكامل – لم يُسجل استلام بالنظام | ⚠ نفس المورد ونفس القيمة في أمرين (المدارات 53,475: PO-267 في 19-2 و PO-309 في 3-3) – يلزم التأكد أنهما توريدان مختلفان | أمر معدّل (REV1)
A13: 12 | B13: PO-267 | C13: 46072 | D13: المدارات | E13: RN-249 | F13: 46500 | G13: 6975 | H13: 53475 | I13: لم يُسجل الاستلام | J13: مدفوع بالكامل | K13: 0 | L13: حالة الاستلام "Not Issued" رغم أنه مدفوع بالكامل – لم يُسجل استلام بالنظام | ⚠ نفس المورد ونفس القيمة في أمرين (المدارات 53,475: PO-267 في 19-2 و PO-309 في 3-3) – يلزم التأكد أنهما توريدان مختلفان
... A28: 27 | B28: PO-585 | C28: 46147 | D28: موسسة دنيا الري للتجارة | E28: RN-520 | F28: 700 | G28: 0 | H28: 700 | I28: لم يُسجل الاستلام | J28: مدفوع بالكامل | K28: 0 | L28: حالة الاستلام "Not Issued" رغم أنه مدفوع بالكامل – لم يُسجل استلام بالنظام
A29: 28 | B29: PO-0707 | C29: 46181 | D29: بساتين الرياض | F29: 1500 | G29: 0 | H29: 1500 | I29: تم الاستلام بالكامل | J29: مدفوع بالكامل | K29: 0
A30: 29 | B30: PO-0706 | C30: 46181 | D30: شركة ايراد المتحدة | F30: 2754 | G30: 413.1 | H30: 3167.1 | I30: تم الاستلام بالكامل | J30: مدفوع بالكامل | K30: 0 | L30: تمت مراجعة سعر من الإدارة: 6/13/2026 1:42:33 PM by ahmed.strc@gmail.com] Cost updated for: FR1023 (Base: 270 Add: 0)
A31: 30 | B31: PO-0777 | C31: 46197 | D31: بساتين الرياض | F31: 66420 | G31: 0 | H31: 66420 | I31: تم الاستلام بالكامل | J31: مدفوع جزئياً | K31: =H31 | L31: ⚠ مدفوع جزئياً – المبلغ المدفوع غير موضح بالملف، المديونية المعروضة = كامل القيمة لحين تحديد المدفوع | تمت مراجعة سعر من الإدارة: 6/27/2026 6:29:59 PM by ahmed.strc@gmail.com] Cost updated for: FR1028 (Base: 123 Add: 0)
A32: 31 | B32: PO-1023 | C32: 46231 | D32: بساتين الرياض | F32: 33950 | G32: 0 | H32: 33950 | I32: تم الاستلام بالكامل | J32: غير مدفوع | K32: =H32 | L32: ⚠ غير مدفوع – مديونية قائمة للمورد
D33: الإجمالي | F33: =SUM(F2:F32) | G33: =SUM(G2:G32) | H33: =SUM(H2:H32) | K33: =SUM(K2:K32)

Sheet العهد - تفصيل المصروفات
A1: م | B1: صاحب العهدة | C1: التاريخ | D1: البيان | E1: المستفيد / السيارة | F1: البند | G1: المبلغ | H1: داخل الفترة | I1: ملاحظة
A2: 1 | B2: حسين مصطفى – مستودع الرياض | C2: 46064 | D2: بنزين س الوانيت رقم 5564 + غيار زيت | E2: VHC-5564 | F2: وقود (ديزل/بنزين) | G2: 345 | H2: نعم
A3: 2 | B3: حسين مصطفى – مستودع الرياض | C3: 46064 | D3: غيار زيت وفالتر وغسيل وتشحيم س عماد رقم 3010 | E3: VHC-3010 | F3: صيانة سيارات | G3: 990 | H3: نعم
A4: 3 | B4: حسين مصطفى – مستودع الرياض | C4: 46064 | D4: سوالر س عصمت رقم 1219 + غيار +زيت صيانة السيارة | E4: VHC-1219 | F4: صيانة سيارات | G4: 1599.24 | H4: نعم
A5: 4 | B5: حسين مصطفى – مستودع الرياض | C5: 46064 | D5: كهرباء مزرعة الرياض عن شهر 2026-1 | E5: EXP.RN.NURSERY | F5: خدمات ومرافق (كهرباء/مياه/إنترنت/إنشاءات) | G5: 2633 | H5: نعم
A6: 5 | B6: حسين مصطفى – مستودع الرياض | C6: 46064 | D6: انتقال عماد من الرياض الي تبوك | E6: VHC-3010 | F6: رواتب وعمولات وانتقالات | G6: 460 | H6: نعم
A7: 6 | B7: حسين مصطفى – مستودع الرياض | C7: 46064 | D7: عصمت الله عمولة)72( عصمت عن شهر 2025-12 + صيانة +السيارة غسيل | E7: عصمتRN الله #72 | F7: رواتب وعمولات وانتقالات | G7: 925 | H7: نعم
A8: 7 | B8: حسين مصطفى – مستودع الرياض | C8: 46064 | D8: عماد حمدى عمولة)24( عماد حمدي عن شهر 2025-12 + الردود | E8: عمادRN حمدى #24 | F8: رواتب وعمولات وانتقالات | G8: 711 | H8: نعم
A9: 8 | B9: حسين مصطفى – مستودع الرياض | C9: 46064 | D9: عماد حمدى شحن)24( الت جو - حسين ومحمد عبدالمجيد وعصمت وعماد | E9: عمادRN حمدى #24 | F9: رواتب وعمولات وانتقالات | G9: 408.25 | H9: نعم
A10: 9 | B10: حسين مصطفى – مستودع الرياض | C10: 46064 | D10: نولون نقلة سماد معالج | E10: EXP.RN.NURSERY | F10: مصروفات تشغيل المزرعة | G10: 400 | H10: نعم
A11: 10 | B11: حسين مصطفى – مستودع الرياض | C11: 46064 | D11: مياه للشرب - 3 نقلة | E11: RN-DEPARTMENT | F11: خدمات ومرافق (كهرباء/مياه/إنترنت/إنشاءات) | G11: 210 | H11: نعم
A12: 11 | B12: حسين مصطفى – مستودع الرياض | C12: 46064 | D12: مصنعية تركيب سباكة وكهرباء للمطبخ والحمام | E12: EXP.RN.NURSERY | F12: خدمات ومرافق (كهرباء/مياه/إنترنت/إنشاءات) | G12: 600 | H12: نعم
A13: 12 | B13: حسين مصطفى – مستودع الرياض | C13: 46064 | D13: مصنعية بناء مطبخ وحمام وصرف ومحارة | E13: EXP.RN.NURSERY | F13: خدمات ومرافق (كهرباء/مياه/إنترنت/إنشاءات) | G13: 1190 | H13: نعم
... A42: 41 | B42: حسين مصطفى – مستودع الرياض | C42: 46118 | D42: شراء 2 لفة شكرتون | E42: RN-DEPARTMENT | F42: خدمات ومرافق (كهرباء/مياه/إنترنت/إنشاءات) | G42: 50 | H42: نعم
A43: 42 | B43: حسين مصطفى – مستودع الرياض | C43: 46121 | D43: شحن الت جو ونت شحن واي فاي - النت 6 شهور | F43: خدمات ومرافق (كهرباء/مياه/إنترنت/إنشاءات) | G43: 750 | H43: نعم
A44: 43 | B44: حسين مصطفى – مستودع الرياض | C44: 46121 | D44: شراء ورق طباعة وفايل | E44: RN-DEPARTMENT | F44: خدمات ومرافق (كهرباء/مياه/إنترنت/إنشاءات) | G44: 46.17 | H44: نعم
A45: 44 | B45: حسين مصطفى – مستودع الرياض | C45: 46121 | D45: غيار زيت وفلتر س عماد | E45: VHC-3010 | F45: صيانة سيارات | G45: 280 | H45: نعم
A46: 45 | B46: حسين مصطفى – مستودع الرياض | C46: 46123 | D46: سوالر س - عماد | E46: VHC-3010 | F46: وقود (ديزل/بنزين) | G46: 150.02 | H46: نعم
A47: 46 | B47: حسين مصطفى – مستودع الرياض | C47: 46125 | D47: سوالر س - عماد | E47: VHC-3010 | F47: وقود (ديزل/بنزين) | G47: 150.01 | H47: نعم
A48: 47 | B48: حسين مصطفى – مستودع الرياض | C48: 46126 | D48: سوالر س - عصمت | E48: VHC-1219 | F48: وقود (ديزل/بنزين) | G48: 150.01 | H48: نعم
A49: 48 | B49: حسين مصطفى – مستودع الرياض | C49: 46126 | D49: ترصيص س عصمت | E49: VHC-1219 | F49: صيانة سيارات | G49: 150.01 | H49: نعم
A50: 49 | B50: حسين مصطفى – مستودع الرياض | C50: 46127 | D50: سوالر س - عماد | E50: VHC-3010 | F50: وقود (ديزل/بنزين) | G50: 150.01 | H50: نعم
A51: 50 | B51: حسين مصطفى – مستودع الرياض | C51: 46129 | D51: شراء غراء سباكة | E51: EXP.RN.NURSERY | F51: خدمات ومرافق (كهرباء/مياه/إنترنت/إنشاءات) | G51: 45 | H51: نعم
A52: 51 | B52: حسين مصطفى – مستودع الرياض | C52: 46129 | D52: غسيل س عصمت | E52: VHC-1219 | F52: صيانة سيارات | G52: 60 | H52: نعم
A53: 52 | B53: حسين مصطفى – مستودع الرياض | C53: 46129 | D53: غيار زيت وفلتر س عماد | E53: VHC-3010 | F53: صيانة سيارات | G53: 280 | H53: نعم
A54: 53 | B54: حسين مصطفى – مستودع الرياض | C54: 46129 | D54: غسيل وتشحيم س عماد + اصالح ماكينة رش المزرعة MOSTAFA HUSSEIN | E54: VHC-3010 | F54: صيانة سيارات | G54: 250 | H54: نعم
A55: 54 | B55: حسين مصطفى – مستودع الرياض | C55: 46129 | D55: سوالر س عصمت | E55: VHC-1219 | F55: وقود (ديزل/بنزين) | G55: 200 | H55: نعم
... A148: 147 | B148: إسماعيل جان حبيب – سيارة 3010 | C148: 46233 | D148: سوالر س - اسماعيل | E148: VHC-3010 | F148: وقود (ديزل/بنزين) | G148: 100.01 | H148: نعم
A149: 148 | B149: إسماعيل جان حبيب – سيارة 3010 | C149: 46236 | D149: سوالر س اسماعيل | E149: VHC-3010 | F149: وقود (ديزل/بنزين) | G149: 100 | H149: لا | I149: بعد 31-7-2026 – خارج الفترة
A150: 149 | B150: إسماعيل جان حبيب – سيارة 3010 | C150: 46236 | D150: غيار زيت وفلتر وتشحيم س اسماعيل | E150: VHC-3010 | F150: صيانة سيارات | G150: 300 | H150: لا | I150: بعد 31-7-2026 – خارج الفترة
A151: 150 | B151: عظمت الله خان – سيارة 1219 | C151: 46236 | D151: غيار زيت وفالتر للسيارة | E151: VHC-1219 | F151: صيانة سيارات | G151: 245 | H151: لا | I151: بعد 31-7-2026 – خارج الفترة
A152: 151 | B152: عظمت الله خان – سيارة 1219 | C152: 46236 | D152: سوالر س - عصمت 1219 | E152: VHC-1219 | F152: وقود (ديزل/بنزين) | G152: 200 | H152: لا | I152: بعد 31-7-2026 – خارج الفترة
A153: 152 | B153: حسين مصطفى – مستودع الرياض | C153: 46238 | D153: إسماعيل محمد مصروفات)61( السائق إسماعيل توصيل طلبية نجران - توجيه من أبوخالد | E153: إسماعيلRN محمد #61 | F153: رواتب وعمولات وانتقالات | G153: 100 | H153: لا | I153: بعد 31-7-2026 – خارج الفترة
A154: 153 | B154: حسين مصطفى – مستودع الرياض | C154: 46238 | D154: SUPPLIES COFFEE & مياهTEA للشرب للعمال | F154: خدمات ومرافق (كهرباء/مياه/إنترنت/إنشاءات) | G154: 70 | H154: لا | I154: بعد 31-7-2026 – خارج الفترة
A155: 154 | B155: حسين مصطفى – مستودع الرياض | C155: 46238 | D155: شراء 3 لفة خيط لتربيط الشجار | E155: RN-DEPARTMENT | F155: مصروفات تشغيل المزرعة | G155: 150 | H155: لا | I155: بعد 31-7-2026 – خارج الفترة
A156: 155 | B156: حسين مصطفى – مستودع الرياض | C156: 46238 | D156: SUPPLIES شراءCLEANING سم فئران | F156: خدمات ومرافق (كهرباء/مياه/إنترنت/إنشاءات) | G156: 20 | H156: لا | I156: بعد 31-7-2026 – خارج الفترة
A157: 156 | B157: حسين مصطفى – مستودع الرياض | C157: 46238 | D157: شراء خالط دش وخالط وضوء للعمال | E157: EQUIP. & DEVICE MAINTENANCE | F157: خدمات ومرافق (كهرباء/مياه/إنترنت/إنشاءات) | G157: 184 | H157: لا | I157: بعد 31-7-2026 – خارج الفترة
A158: 157 | B158: حسين مصطفى – مستودع الرياض | C158: 46238 | D158: شراء مقصات للشجر | E158: RN-DEPARTMENT | F158: مصروفات تشغيل المزرعة | G158: 45 | H158: لا | I158: بعد 31-7-2026 – خارج الفترة
A159: 158 | B159: حسين مصطفى – مستودع الرياض | C159: 46238 | D159: شراء شطرطون ومفكات | E159: RN-DEPARTMENT | F159: مصروفات تشغيل المزرعة | G159: 46 | H159: لا | I159: بعد 31-7-2026 – خارج الفترة
A160: 159 | B160: حسين مصطفى – مستودع الرياض | C160: 46238 | D160: شراء مسدس رش مياه وسيلكون | E160: RN-DEPARTMENT | F160: مصروفات تشغيل المزرعة | G160: 40 | H160: لا | I160: بعد 31-7-2026 – خارج الفترة
...

Sheet العهد - ملخص
A1: صاحب العهدة | B1: المنصرف له (إجمالي العهدة) | C1: المسوّى بمستندات | D1: الرصيد المتبقي بدون تسوية | E1: منها داخل الفترة حتى 31-7 | F1: منها بعد 31-7
A2: حسين مصطفى – مستودع الرياض | B2: 46018.39 | C2: 45136.41 | D2: 881.98 | E2: 41615.39 | F2: 3521.02
A3: إسماعيل جان حبيب – سيارة 3010 | B3: 2153 | C3: 2003.05 | D3: 149.95 | E3: 1253.05 | F3: 750
A4: عظمت الله خان – سيارة 1219 | B4: 2500 | C4: 1988.02 | D4: 511.98 | E4: 1293.02 | F4: 695
A5: عماد حمدي – سيارة 3010 | B5: 690 | C5: 690 | D5: 0 | E5: 690 | F5: 0
A6: الإجمالي | B6: =SUM(B2:B5) | C6: =SUM(C2:C5) | D6: =SUM(D2:D5) | E6: =SUM(E2:E5) | F6: =SUM(F2:F5)
A8: المصروفات حسب البند (داخل الفترة حتى 31-7-2026)
A9: البند | B9: المبلغ | C9: عدد الحركات
A10: وقود (ديزل/بنزين) | B10: 13997.32 | C10: 64
A11: صيانة سيارات | B11: 13421.86 | C11: 39
A12: خدمات ومرافق (كهرباء/مياه/إنترنت/إنشاءات) | B12: 11253.65 | C12: 23
A13: مصروفات تشغيل المزرعة | B13: 3674.38 | C13: 17
A14: رواتب وعمولات وانتقالات | B14: 2504.25 | C14: 4
A15: الإجمالي | B15: =SUM(B10:B14) | C15: =SUM(C10:C14)
A17: المصروفات حسب السيارة / المستفيد (داخل الفترة)
A18: المستفيد | B18: المبلغ | C18: عدد الحركات
A19: سيارة 3010 (عماد) | B19: 14033.16 | C19: 52
A20: مصروفات المزرعة | B20: 11747.11 | C20: 22
A21: سيارة 1219 (عصمت) | B21: 11176.31 | C21: 42
A22: أفراد (عمولات/انتقالات) | B22: 2794.25 | C22: 4
A23: سيارة 5564 (الوانيت) | B23: 2669.71 | C23: 10
A24: قسم مزرعة الرياض | B24: 2430.92 | C24: 17
A25: الإجمالي | B25: =SUM(B19:B24) | C25: =SUM(C19:C24)

Sheet مصروفات 2025 - تفصيل
A1: م | B1: التاريخ | C1: المورد / البيان | D1: أمر الشراء / الاسم | E1: المرجع | F1: قبل الضريبة | G1: الضريبة % | H1: الإجمالي | I1: مدفوع | J1: جهة الدفع | K1: التصنيف | L1: ملاحظة
A2: 1 | B2: 45809 | C2: الشركة السعوديه للكهرباء | D2: RIYADH NURSERY | E2: فاتوره كهرباء شهر 6 | F2: 5220.27 | G2: 15 | H2: 6003.31 | I2: نعم | J2: مزرعة الرياض (عهدة/صندوق) | K2: خدمات (كهرباء/مياه/اتصالات) | L2: قبل 1-7-2025 (فاتورة كهرباء شهر 6)
A3: 2 | B3: 45839 | C3: الشركة السعوديه للكهرباء | D3: RIYADH NURSERY | E3: ايصال الكهرباء شهر 7 | F3: 3955.58 | G3: 15 | H3: 4548.92 | I3: نعم | J3: مزرعة الرياض (عهدة/صندوق) | K3: خدمات (كهرباء/مياه/اتصالات)
A4: 3 | B4: 45839 | C4: رواتب | D4: RIYADH NURSERY | E4: رواتب شهر 7 | F4: 24332.17 | G4: 15 | H4: 27982 | I4: نعم | J4: مزرعة الرياض (عهدة/صندوق) | K4: رواتب وعمولات
A5: 4 | B5: 45840 | C5: الوقود | D5: RIYADH NURSERY | F5: 217.42 | G5: 15 | H5: 250.03 | I5: نعم | J5: مزرعة الرياض (عهدة/صندوق) | K5: وقود
A6: 5 | B6: 45840 | C6: ينابع المئويه لتحلية المياه | D6: RIYADH NURSERY | E6: رد مياه | F6: 52.17 | G6: 15 | H6: 60 | I6: نعم | J6: مزرعة الرياض (عهدة/صندوق) | K6: خدمات (كهرباء/مياه/اتصالات)
A7: 6 | B7: 45840 | C7: الوقود | D7: RIYADH NURSERY | E7: غسيل سياره | F7: 52.17 | G7: 15 | H7: 60 | I7: نعم | J7: مزرعة الرياض (عهدة/صندوق) | K7: وقود
A8: 7 | B8: 45840 | C8: محطة المجمع لخدمات السيارات | D8: RIYADH NURSERY | E8: بنشر كفر السياره | F8: 13.04 | G8: 15 | H8: 15 | I8: نعم | J8: مزرعة الرياض (عهدة/صندوق) | K8: صيانة سيارات ومعدات
A9: 8 | B9: 45841 | C9: الوقود | D9: RIYADH NURSERY | F9: 93.04 | G9: 15 | H9: 107 | I9: نعم | J9: مزرعة الرياض (عهدة/صندوق) | K9: وقود
A10: 9 | B10: 45841 | C10: الوقود | D10: RIYADH NURSERY | F10: 111.3 | G10: 15 | H10: 128 | I10: نعم | J10: مزرعة الرياض (عهدة/صندوق) | K10: وقود
A11: 10 | B11: 45842 | C11: الوقود | D11: RIYADH NURSERY | F11: 185.22 | G11: 15 | H11: 213 | I11: نعم | J11: مزرعة الرياض (عهدة/صندوق) | K11: وقود
A12: 11 | B12: 45843 | C12: الوقود | D12: RIYADH NURSERY | F12: 132.17 | G12: 15 | H12: 152 | I12: نعم | J12: مزرعة الرياض (عهدة/صندوق) | K12: وقود
A13: 12 | B13: 45843 | C13: الوقود | D13: RIYADH NURSERY | F13: 204.35 | G13: 15 | H13: 235 | I13: نعم | J13: مزرعة الرياض (عهدة/صندوق) | K13: وقود
A14: 13 | B14: 45843 | C14: الوقود | D14: RIYADH NURSERY | F14: 78.29 | G14: 15 | H14: 90.03 | I14: نعم | J14: مزرعة الرياض (عهدة/صندوق) | K14: وقود
A15: 14 | B15: 45848 | C15: الوقود | D15: RIYADH NURSERY | F15: 173.91 | G15: 15 | H15: 200 | I15: نعم | J15: مزرعة الرياض (عهدة/صندوق) | K15: وقود
A16: 15 | B16: 45852 | C16: الوقود | D16: RIYADH NURSERY | F16: 191.3 | G16: 15 | H16: 220 | I16: نعم | J16: مزرعة الرياض (عهدة/صندوق) | K16: وقود
A17: 16 | B17: 45854 | C17: ينابع المئويه لتحلية المياه | D17: RIYADH NURSERY | F17: 52.17 | G17: 15 | H17: 60 | I17: نعم | J17: مزرعة الرياض (عهدة/صندوق) | K17: خدمات (كهرباء/مياه/اتصالات)
A18: 17 | B18: 45854 | C18: مؤسسة بساتين الرياض | D18: RIYADH NURSERY-PO876 | E18: شراء بذور | F18: 17180 | G18: 15 | H18: 19757 | I18: لا | J18: مزرعة الرياض (عهدة/صندوق) | K18: مشتريات نباتات وبذور | L18: غير مدفوع في 2025 – تم سداده في 2026 ضمن أمر PO-287-REV1
A19: 18 | B19: 45855 | C19: الوقود | D19: RIYADH NURSERY | F19: 173.91 | G19: 15 | H19: 200 | I19: نعم | J19: مزرعة الرياض (عهدة/صندوق) | K19: وقود
A20: 19 | B20: 45859 | C20: الوقود | D20: RIYADH NURSERY | F20: 173.91 | G20: 15 | H20: 200 | I20: نعم | J20: مزرعة الرياض (عهدة/صندوق) | K20: وقود
A21: 20 | B21: 45860 | C21: الأمور الإدارية | D21: RIYADH NURSERY | E21: ادوات كهربائيه | F21: 30.43 | G21: 15 | H21: 35 | I21: نعم | J21: مزرعة الرياض (عهدة/صندوق) | K21: مصروفات إدارية وأخرى
A22: 21 | B22: 45860 | C22: الوقود | D22: RIYADH NURSERY | F22: 60.87 | G22: 15 | H22: 70 | I22: نعم | J22: مزرعة الرياض (عهدة/صندوق) | K22: وقود
A23: 22 | B23: 45862 | C23: الوقود | D23: RIYADH NURSERY | F23: 173.91 | G23: 15 | H23: 200 | I23: نعم | J23: مزرعة الرياض (عهدة/صندوق) | K23: وقود
A24: 23 | B24: 45865 | C24: الأمور الإدارية | D24: RIYADH NURSERY | E24: ادوات كهرباء | F24: 837.39 | G24: 15 | H24: 963 | I24: نعم | J24: مزرعة الرياض (عهدة/صندوق) | K24: مصروفات إدارية وأخرى
A25: 24 | B25: 45865 | C25: الوقود | D25: RIYADH NURSERY | F25: 173.91 | G25: 15 | H25: 200 | I25: نعم | J25: مزرعة الرياض (عهدة/صندوق) | K25: وقود
A26: 25 | B26: 45866 | C26: مصنعيات | D26: RIYADH NURSERY | E26: اجره كهربائى | F26: 434.78 | G26: 15 | H26: 500 | I26: نعم | J26: مزرعة الرياض (عهدة/صندوق) | K26: صيانة وإنشاءات المزرعة
A27: 26 | B27: 45866 | C27: الوقود | D27: RIYADH NURSERY | F27: 213.04 | G27: 15 | H27: 245 | I27: نعم | J27: مزرعة الرياض (عهدة/صندوق) | K27: وقود
A28: 27 | B28: 45866 | C28: الأمور الإدارية | D28: RIYADH NURSERY | E28: ادوات سباكه | F28: 2865.22 | G28: 15 | H28: 3295 | I28: نعم | J28: مزرعة الرياض (عهدة/صندوق) | K28: مصروفات إدارية وأخرى
A29: 28 | B29: 45867 | C29: الأمور الإدارية | D29: RIYADH NURSERY | E29: قفل + سلسله | F29: 143.48 | G29: 15 | H29: 165 | I29: نعم | J29: مزرعة الرياض (عهدة/صندوق) | K29: مصروفات إدارية وأخرى
A30: 29 | B30: 45868 | C30: ينابع المئويه لتحلية المياه | D30: RIYADH NURSERY | F30: 52.17 | G30: 15 | H30: 60 | I30: نعم | J30: مزرعة الرياض (عهدة/صندوق) | K30: خدمات (كهرباء/مياه/اتصالات)
A31: 30 | B31: 45868 | C31: الأمور الإدارية | D31: RIYADH NURSERY | F31: 165 | G31: 15 | H31: 189.75 | I31: نعم | J31: مزرعة الرياض (عهدة/صندوق) | K31: مصروفات إدارية وأخرى
A32: 31 | B32: 45868 | C32: الوقود | D32: RIYADH NURSERY | E32: توصيل 2 مكيف مع التركيب | F32: 260.87 | G32: 15 | H32: 300 | I32: نعم | J32: مزرعة الرياض (عهدة/صندوق) | K32: وقود
A33: 32 | B33: 45869 | C33: الوقود | D33: RIYADH NURSERY | F33: 232.17 | G33: 15 | H33: 267 | I33: نعم | J33: مزرعة الرياض (عهدة/صندوق) | K33: وقود
A34: 33 | B34: 45869 | C34: الوقود | D34: RIYADH NURSERY | F34: 210.65 | G34: 15 | H34: 242.25 | I34: نعم | J34: مزرعة الرياض (عهدة/صندوق) | K34: وقود
A35: 34 | B35: 45870 | C35: الوقود | D35: RIYADH NURSERY | F35: 221.75 | G35: 15 | H35: 255.01 | I35: نعم | J35: مزرعة الرياض (عهدة/صندوق) | K35: وقود
A36: 35 | B36: 45870 | C36: الطعام | D36: RIYADH NURSERY | E36: وجبة سفر تيمور من تبوك ال | F36: 30.43 | G36: 15 | H36: 35 | I36: نعم | J36: مزرعة الرياض (عهدة/صندوق) | K36: مصروفات إدارية وأخرى
A37: 36 | B37: 45870 | C37: الشركة السعوديه للكهرباء | D37: RIYADH NURSERY | F37: 3931.59 | G37: 15 | H37: 4521.33 | I37: نعم | J37: مزرعة الرياض (عهدة/صندوق) | K37: خدمات (كهرباء/مياه/اتصالات)
A38: 37 | B38: 45871 | C38: الطعام | D38: RIYADH NURSERY | E38: وجبة سفر تيمور من تبوك ال | F38: 13.91 | G38: 15 | H38: 16 | I38: نعم | J38: مزرعة الرياض (عهدة/صندوق) | K38: مصروفات إدارية وأخرى
A39: 38 | B39: 45871 | C39: الطعام | D39: RIYADH NURSERY | E39: وجبة سفر تيمور من تبوك ال | F39: 14.78 | G39: 15 | H39: 17 | I39: نعم | J39: مزرعة الرياض (عهدة/صندوق) | K39: مصروفات إدارية وأخرى
A40: 39 | B40: 45871 | C40: الوقود | D40: RIYADH NURSERY | E40: صيانة الاونيت فى المزرعه | F40: 260.87 | G40: 15 | H40: 300 | I40: نعم | J40: مزرعة الرياض (عهدة/صندوق) | K40: وقود
...

Sheet مصروفات 2025 - ملخص
A1: ملخص مصروفات مزرعة الرياض 2025 (1-7-2025 إلى 31-12-2025)
A3: التصنيف | B3: الإجمالي | C3: عدد الحركات | D3: منها مدفوع عن طريق تبوك | E3: منها غير مدفوع
A4: مشتريات نباتات وبذور | B4: =SUMIFS('مصروفات 2025 - تفصيل'!H2:H307,'مصروفات 2025 - تفصيل'!K2:K307,A4) | C4: =COUNTIFS('مصروفات 2025 - تفصيل'!K2:K307,A4) | D4: =SUMIFS('مصروفات 2025 - تفصيل'!H2:H307,'مصروفات 2025 - تفصيل'!K2:K307,A4,'مصروفات 2025 - تفصيل'!J2:J307,"مزرعة تبوك*") | E4: =SUMIFS('مصروفات 2025 - تفصيل'!H2:H307,'مصروفات 2025 - تفصيل'!K2:K307,A4,'مصروفات 2025 - تفصيل'!I2:I307,"لا")
A5: مواد زراعية (بيتموس/بيرلايت/أسمدة/مبيدات) | B5: =SUMIFS('مصروفات 2025 - تفصيل'!H2:H307,'مصروفات 2025 - تفصيل'!K2:K307,A5) | C5: =COUNTIFS('مصروفات 2025 - تفصيل'!K2:K307,A5) | D5: =SUMIFS('مصروفات 2025 - تفصيل'!H2:H307,'مصروفات 2025 - تفصيل'!K2:K307,A5,'مصروفات 2025 - تفصيل'!J2:J307,"مزرعة تبوك*") | E5: =SUMIFS('مصروفات 2025 - تفصيل'!H2:H307,'مصروفات 2025 - تفصيل'!K2:K307,A5,'مصروفات 2025 - تفصيل'!I2:I307,"لا")
A6: مشتريات زهور لعقد عرعر (WHK-2364) | B6: =SUMIFS('مصروفات 2025 - تفصيل'!H2:H307,'مصروفات 2025 - تفصيل'!K2:K307,A6) | C6: =COUNTIFS('مصروفات 2025 - تفصيل'!K2:K307,A6) | D6: =SUMIFS('مصروفات 2025 - تفصيل'!H2:H307,'مصروفات 2025 - تفصيل'!K2:K307,A6,'مصروفات 2025 - تفصيل'!J2:J307,"مزرعة تبوك*") | E6: =SUMIFS('مصروفات 2025 - تفصيل'!H2:H307,'مصروفات 2025 - تفصيل'!K2:K307,A6,'مصروفات 2025 - تفصيل'!I2:I307,"لا")
A7: رواتب وعمولات | B7: =SUMIFS('مصروفات 2025 - تفصيل'!H2:H307,'مصروفات 2025 - تفصيل'!K2:K307,A7) | C7: =COUNTIFS('مصروفات 2025 - تفصيل'!K2:K307,A7) | D7: =SUMIFS('مصروفات 2025 - تفصيل'!H2:H307,'مصروفات 2025 - تفصيل'!K2:K307,A7,'مصروفات 2025 - تفصيل'!J2:J307,"مزرعة تبوك*") | E7: =SUMIFS('مصروفات 2025 - تفصيل'!H2:H307,'مصروفات 2025 - تفصيل'!K2:K307,A7,'مصروفات 2025 - تفصيل'!I2:I307,"لا")
A8: مستلزمات إنتاج (مراكن/فلين/مفارش) | B8: =SUMIFS('مصروفات 2025 - تفصيل'!H2:H307,'مصروفات 2025 - تفصيل'!K2:K307,A8) | C8: =COUNTIFS('مصروفات 2025 - تفصيل'!K2:K307,A8) | D8: =SUMIFS('مصروفات 2025 - تفصيل'!H2:H307,'مصروفات 2025 - تفصيل'!K2:K307,A8,'مصروفات 2025 - تفصيل'!J2:J307,"مزرعة تبوك*") | E8: =SUMIFS('مصروفات 2025 - تفصيل'!H2:H307,'مصروفات 2025 - تفصيل'!K2:K307,A8,'مصروفات 2025 - تفصيل'!I2:I307,"لا")
A9: خدمات (كهرباء/مياه/اتصالات) | B9: =SUMIFS('مصروفات 2025 - تفصيل'!H2:H307,'مصروفات 2025 - تفصيل'!K2:K307,A9) | C9: =COUNTIFS('مصروفات 2025 - تفصيل'!K2:K307,A9) | D9: =SUMIFS('مصروفات 2025 - تفصيل'!H2:H307,'مصروفات 2025 - تفصيل'!K2:K307,A9,'مصروفات 2025 - تفصيل'!J2:J307,"مزرعة تبوك*") | E9: =SUMIFS('مصروفات 2025 - تفصيل'!H2:H307,'مصروفات 2025 - تفصيل'!K2:K307,A9,'مصروفات 2025 - تفصيل'!I2:I307,"لا")
A10: مصروفات إدارية وأخرى | B10: =SUMIFS('مصروفات 2025 - تفصيل'!H2:H307,'مصروفات 2025 - تفصيل'!K2:K307,A10) | C10: =COUNTIFS('مصروفات 2025 - تفصيل'!K2:K307,A10) | D10: =SUMIFS('مصروفات 2025 - تفصيل'!H2:H307,'مصروفات 2025 - تفصيل'!K2:K307,A10,'مصروفات 2025 - تفصيل'!J2:J307,"مزرعة تبوك*") | E10: =SUMIFS('مصروفات 2025 - تفصيل'!H2:H307,'مصروفات 2025 - تفصيل'!K2:K307,A10,'مصروفات 2025 - تفصيل'!I2:I307,"لا")
A11: صيانة سيارات ومعدات | B11: =SUMIFS('مصروفات 2025 - تفصيل'!H2:H307,'مصروفات 2025 - تفصيل'!K2:K307,A11) | C11: =COUNTIFS('مصروفات 2025 - تفصيل'!K2:K307,A11) | D11: =SUMIFS('مصروفات 2025 - تفصيل'!H2:H307,'مصروفات 2025 - تفصيل'!K2:K307,A11,'مصروفات 2025 - تفصيل'!J2:J307,"مزرعة تبوك*") | E11: =SUMIFS('مصروفات 2025 - تفصيل'!H2:H307,'مصروفات 2025 - تفصيل'!K2:K307,A11,'مصروفات 2025 - تفصيل'!I2:I307,"لا")
A12: صيانة وإنشاءات المزرعة | B12: =SUMIFS('مصروفات 2025 - تفصيل'!H2:H307,'مصروفات 2025 - تفصيل'!K2:K307,A12) | C12: =COUNTIFS('مصروفات 2025 - تفصيل'!K2:K307,A12) | D12: =SUMIFS('مصروفات 2025 - تفصيل'!H2:H307,'مصروفات 2025 - تفصيل'!K2:K307,A12,'مصروفات 2025 - تفصيل'!J2:J307,"مزرعة تبوك*") | E12: =SUMIFS('مصروفات 2025 - تفصيل'!H2:H307,'مصروفات 2025 - تفصيل'!K2:K307,A12,'مصروفات 2025 - تفصيل'!I2:I307,"لا")
A13: وقود | B13: =SUMIFS('مصروفات 2025 - تفصيل'!H2:H307,'مصروفات 2025 - تفصيل'!K2:K307,A13) | C13: =COUNTIFS('مصروفات 2025 - تفصيل'!K2:K307,A13) | D13: =SUMIFS('مصروفات 2025 - تفصيل'!H2:H307,'مصروفات 2025 - تفصيل'!K2:K307,A13,'مصروفات 2025 - تفصيل'!J2:J307,"مزرعة تبوك*") | E13: =SUMIFS('مصروفات 2025 - تفصيل'!H2:H307,'مصروفات 2025 - تفصيل'!K2:K307,A13,'مصروفات 2025 - تفصيل'!I2:I307,"لا")
A14: تخليص جمركي | B14: =SUMIFS('مصروفات 2025 - تفصيل'!H2:H307,'مصروفات 2025 - تفصيل'!K2:K307,A14) | C14: =COUNTIFS('مصروفات 2025 - تفصيل'!K2:K307,A14) | D14: =SUMIFS('مصروفات 2025 - تفصيل'!H2:H307,'مصروفات 2025 - تفصيل'!K2:K307,A14,'مصروفات 2025 - تفصيل'!J2:J307,"مزرعة تبوك*") | E14: =SUMIFS('مصروفات 2025 - تفصيل'!H2:H307,'مصروفات 2025 - تفصيل'!K2:K307,A14,'مصروفات 2025 - تفصيل'!I2:I307,"لا")
A15: الإجمالي | B15: =SUM(B4:B14) | C15: =SUM(C4:C14) | D15: =SUM(D4:D14) | E15: =SUM(E4:E14)
A17: حسب الشهر
A18: الشهر | B18: الإجمالي | C18: عدد الحركات
A19: 06-2025 | B19: =SUMIFS('مصروفات 2025 - تفصيل'!H2:H307,'مصروفات 2025 - تفصيل'!B2:B307,">="&DATE(2025,6,1),'مصروفات 2025 - تفصيل'!B2:B307,"<"&DATE(2025,7,1)) | C19: =COUNTIFS('مصروفات 2025 - تفصيل'!B2:B307,">="&DATE(2025,6,1),'مصروفات 2025 - تفصيل'!B2:B307,"<"&DATE(2025,7,1))
A20: 07-2025 | B20: =SUMIFS('مصروفات 2025 - تفصيل'!H2:H307,'مصروفات 2025 - تفصيل'!B2:B307,">="&DATE(2025,7,1),'مصروفات 2025 - تفصيل'!B2:B307,"<"&DATE(2025,8,1)) | C20: =COUNTIFS('مصروفات 2025 - تفصيل'!B2:B307,">="&DATE(2025,7,1),'مصروفات 2025 - تفصيل'!B2:B307,"<"&DATE(2025,8,1))
A21: 08-2025 | B21: =SUMIFS('مصروفات 2025 - تفصيل'!H2:H307,'مصروفات 2025 - تفصيل'!B2:B307,">="&DATE(2025,8,1),'مصروفات 2025 - تفصيل'!B2:B307,"<"&DATE(2025,9,1)) | C21: =COUNTIFS('مصروفات 2025 - تفصيل'!B2:B307,">="&DATE(2025,8,1),'مصروفات 2025 - تفصيل'!B2:B307,"<"&DATE(2025,9,1))
A22: 09-2025 | B22: =SUMIFS('مصروفات 2025 - تفصيل'!H2:H307,'مصروفات 2025 - تفصيل'!B2:B307,">="&DATE(2025,9,1),'مصروفات 2025 - تفصيل'!B2:B307,"<"&DATE(2025,10,1)) | C22: =COUNTIFS('مصروفات 2025 - تفصيل'!B2:B307,">="&DATE(2025,9,1),'مصروفات 2025 - تفصيل'!B2:B307,"<"&DATE(2025,10,1))
A23: 10-2025 | B23: =SUMIFS('مصروفات 2025 - تفصيل'!H2:H307,'مصروفات 2025 - تفصيل'!B2:B307,">="&DATE(2025,10,1),'مصروفات 2025 - تفصيل'!B2:B307,"<"&DATE(2025,11,1)) | C23: =COUNTIFS('مصروفات 2025 - تفصيل'!B2:B307,">="&DATE(2025,10,1),'مصروفات 2025 - تفصيل'!B2:B307,"<"&DATE(2025,11,1))
A24: 11-2025 | B24: =SUMIFS('مصروفات 2025 - تفصيل'!H2:H307,'مصروفات 2025 - تفصيل'!B2:B307,">="&DATE(2025,11,1),'مصروفات 2025 - تفصيل'!B2:B307,"<"&DATE(2025,12,1)) | C24: =COUNTIFS('مصروفات 2025 - تفصيل'!B2:B307,">="&DATE(2025,11,1),'مصروفات 2025 - تفصيل'!B2:B307,"<"&DATE(2025,12,1))
A25: 12-2025 | B25: =SUMIFS('مصروفات 2025 - تفصيل'!H2:H307,'مصروفات 2025 - تفصيل'!B2:B307,">="&DATE(2025,12,1),'مصروفات 2025 - تفصيل'!B2:B307,"<"&DATE(2026,1,1)) | C25: =COUNTIFS('مصروفات 2025 - تفصيل'!B2:B307,">="&DATE(2025,12,1),'مصروفات 2025 - تفصيل'!B2:B307,"<"&DATE(2026,1,1))
A26: الإجمالي | B26: =SUM(B19:B25) | C26: =SUM(C19:C25)
A28: مبالغ دفعتها مزرعة تبوك عن مزرعة الرياض في 2025 (مديونية على مزرعة الرياض)
A29: المورد | B29: التاريخ | C29: أمر الشراء | D29: المبلغ
A30: شركة المدارات السعودية للتجارة والاستيراد | B30: 45880 | C30: RIYADH NURSERY-PO599 | D30: 4600
A31: Arabian Vermiculite Industries (AVI) | B31: 45887 | C31: RIYADH NURSERY | D31: 17043
A32: شركة التاج المميزة التجارية | B32: 45887 | C32: RIYADH NURSERY-PO#627 | D32: 27025
A33: شركة التكامل | B33: 45901 | C33: RIYADH NURSERYpo-747 | D33: 22356
A34: شركة سائح لى للبلاستيك المحدوده | B34: 45913 | C34: RIYADH NURSERY-PO749 | D34: 2260.44
A35: شركة سائح لى للبلاستيك المحدوده | B35: 45913 | C35: RIYADH NURSERY-PO-736 | D35: 2260.44
A36: شركة التاج المميزة التجارية | B36: 45920 | C36: RIYADH NURSERY PO-743 | D36: 28750
A37: شركة المدارات السعودية للتجارة والاستيراد | B37: 45921 | C37: RIYADH NURSERY-PO785 | D37: 9200
A38: شركة سائح لى للبلاستيك المحدوده | B38: 45926 | C38: RIYADH NURSERY | D38: 4520.88
A39: شركة الياسين الزراعية | B39: 45930 | C39: RIYADH NURSERY | D39: 58063.5
A40: شركة المدارات السعودية للتجارة والاستيراد | B40: 45953 | C40: RIYADH NURSERY - PO1040 | D40: 50600
A41: الإجمالي | D41: =SUM(D30:D40)
A43: ملاحظات المراجعة:
A44: 1) ملفا 2025 متطابقان: الملف الثاني فيه كل حركات الأول + 6 حركات مشتريات من شركة الجزيرة الحديثة الزراعية لعقد عرعر WHK-2364. إجمالي مشتريات الجزيرة لعقد عرعر 7 حركات = 198,102.50 (منها 21,250 غير مدفوع). كل الحركات صحيحة ضريبياً.
...
