Workbook

Sheet ملخص التسعير
A1: ملخص التسعير الموحد بين الطرفين (بدون ضريبة)
A2: البند | B2: الإجمالي المسجل | C2: الإجمالي بالسعر الموحد | D2: الفرق | E2: الأثر
A3: فرق أسعار أبو خالد (عقود من 11-2025) | B3: ='فرق أسعار أبو خالد'!H61 | C3: ='فرق أسعار أبو خالد'!J61 | D3: ='فرق أسعار أبو خالد'!K61 | E3: فرق مرتجع لصالح أبو خالد (يُخصم من مسحوباته)
A4: مسحوبات نسما من الرياض | B4: ='مسحوبات نسما من الرياض'!G122 | C4: ='مسحوبات نسما من الرياض'!I122 | D4: ='مسحوبات نسما من الرياض'!J122 | E4: مديونية على أبو مازن
A5: مسحوبات نسما قبل الفترة | B5: ='مسحوبات نسما قبل الفترة'!G14 | C5: ='مسحوبات نسما قبل الفترة'!I14 | D5: ='مسحوبات نسما قبل الفترة'!J14 | E5: مديونية على أبو مازن
A6: ترحيل تبوك إلى الرياض | B6: ='ترحيل تبوك إلى الرياض'!G30 | C6: ='ترحيل تبوك إلى الرياض'!I30 | D6: ='ترحيل تبوك إلى الرياض'!J30 | E6: دعم تشغيلي من أبو مازن
A7: سندات بدون تفصيل أصناف (على أبو مازن) | B7: ='سندات بدون تفصيل أصناف'!F10 | C7: ='سندات بدون تفصيل أصناف'!G10 | E7: تحتاج أصناف أو اعتماد القيمة
A9: ملاحظات:
A10: 1) الأصناف (فينكا – زينيا – امرانتس – بيتونيا – سيلوزيا – فضية – ماري جولد – سالفيا – هيبوستس – الزهور الموسمية) موحدة 0.50 للطرفين في كل العقود والمسحوبات.
A11: 2) باقي الأصناف: السعر الموحد يُدخل في "قائمة الأسعار الموحدة" (الخانة الصفراء) – وإذا تُركت فارغة يُستخدم السعر المسجل بالسند.
A12: 3) عقود أبو خالد قبل 1-11-2025 مشمولة بتسوية 62,937 فلا يُحتسب لها فرق. عقد عرعر WHK-2364 مسعّر أصلاً 0.50.
A13: 4) الترحيل من الرياض إلى تبوك = مديونية على أبو مازن، ومن تبوك إلى الرياض = دعم تشغيلي من أبو مازن.
A14: 5) أُلغي PO-213 (بيتونيا 6,000) وخُصمت 17,900 فينكا مفقودة من الطلب 58991، وسلفة رائد الخير (ISV-0075) مستبعدة.
A15: 6) تكاليف الشحن الخارجي لأوامر ما قبل الفترة تحمّلتها نسما (11,300) ولا تُحمّل على أي طرف.

Sheet قائمة الأسعار الموحدة
A1: قائمة الأسعار الموحدة للطرفين (بدون ضريبة) – الأصناف المستهدفة ثابتة 0.50 – الخانات الصفراء للإدخال
A2: م | B2: مفتاح الصنف | C2: الأسماء كما وردت بالسندات | D2: الأسعار الحالية بالسندات | E2: السعر الموحد | F2: الحالة | G2: يظهر في | H2: إجمالي الكمية | I2: أقل سعر باع به لأبو خالد
A3: 1 | B3: امرانتس | C3: زهور امرانتس | D3: 0.5 | E3: 0.5 | F3: موحد 0.50 (قرارك) | G3: عقود أبو خالد + مسحوبات تبوك من الرياض | H3: 8700 | I3: 0.5
A4: 2 | B4: بيتونيا | C4: زهور بيتونيا | D4: 0.5 / 0.7 / 0.75 | E4: 0.5 | F4: موحد 0.50 (قرارك) | G4: عقود أبو خالد + مسحوبات تبوك من الرياض + ترحيل تبوك للرياض | H4: 259147 | I4: 0.5
A5: 3 | B5: زينيا | C5: زهور زينيا | D5: 0.5 | E5: 0.5 | F5: موحد 0.50 (قرارك) | G5: عقود أبو خالد + مسحوبات تبوك من الرياض | H5: 69275 | I5: 0.5
A6: 4 | B6: سالفيا مركن 9 | C6: زهور سالفيا مركن 9 / زهور سالفيا مركن9 سم | D6: 0.5 / 0.6 / 0.75 | E6: 0.5 | F6: موحد 0.50 (قرارك) | G6: عقود أبو خالد + مسحوبات تبوك من الرياض | H6: 6337 | I6: 0.5
A7: 5 | B7: سيلوزيا | C7: زهور سيلوزيا | D7: 0.5 | E7: 0.5 | F7: موحد 0.50 (قرارك) | G7: عقود أبو خالد | H7: 3000 | I7: 0.5
A8: 6 | B8: فضيه | C8: زهور فضية | D8: 0.5 | E8: 0.5 | F8: موحد 0.50 (قرارك) | G8: مسحوبات تبوك من الرياض | H8: 300 | I8: —
A9: 7 | B9: فينكا ابيض | C9: فينكا أبيض | D9: — | E9: 0.5 | F9: موحد 0.50 (قرارك) | G9: مسحوبات قبل الفترة | H9: 9000 | I9: —
A10: 8 | B10: فينكا ابيض نقطه حمراء | C10: فينكا أبيض نقطة حمراء | D10: — | E10: 0.5 | F10: موحد 0.50 (قرارك) | G10: مسحوبات قبل الفترة | H10: 3875 | I10: —
A11: 9 | B11: فينكا احمر | C11: فينكا أحمر | D11: — | E11: 0.5 | F11: موحد 0.50 (قرارك) | G11: مسحوبات قبل الفترة | H11: 11000 | I11: —
A12: 10 | B12: فينكا احمر بنقطه | C12: فينكا أحمر بنقطة | D12: — | E12: 0.5 | F12: موحد 0.50 (قرارك) | G12: مسحوبات قبل الفترة | H12: 3000 | I12: —
A13: 11 | B13: فينكا ازرق | C13: فينكا أزرق | D13: — | E13: 0.5 | F13: موحد 0.50 (قرارك) | G13: مسحوبات قبل الفترة | H13: 5000 | I13: —
A14: 12 | B14: فينكا روزا | C14: زهور فينكا روزا | D14: 0.5 / 0.55 | E14: 0.5 | F14: موحد 0.50 (قرارك) | G14: عقود أبو خالد + مسحوبات تبوك من الرياض | H14: 190390 | I14: 0.55
A15: 13 | B15: فينكا مشمشي | C15: فينكا مشمشي | D15: — | E15: 0.5 | F15: موحد 0.50 (قرارك) | G15: مسحوبات قبل الفترة | H15: 5000 | I15: —
A16: 14 | B16: ماري جولد | C16: زهور مارى جولد / زهور ماري جولد / مارى جولد | D16: 0.5 / 0.7 | E16: 0.5 | F16: موحد 0.50 (قرارك) | G16: عقود أبو خالد + مسحوبات تبوك من الرياض | H16: 15425 | I16: 0.7
A17: 15 | B17: ماري جولد فرنسي | C17: زهور ماري جولد فرنسى | D17: 0.5 | E17: 0.5 | F17: موحد 0.50 (قرارك) | G17: مسحوبات تبوك من الرياض | H17: 250 | I17: —
A18: 16 | B18: موسميه | C18: زهور موسمية (SEASONAL FLOWERS) / زهور موسمية – غير شامل التوصيل | D18: — | E18: 0.5 | F18: موحد 0.50 (قرارك) | G18: مسحوبات قبل الفترة | H18: 66000 | I18: —
A19: 17 | B19: هيبوستس | C19: زهور هيبوستس / زهور هيبوستس مركن9 سم / هيبوستس | D19: 0.55 / 0.7 / 2.5 | E19: 0.5 | F19: موحد 0.50 (قرارك) | G19: عقود أبو خالد + مسحوبات تبوك من الرياض | H19: 4575 | I19: 0.7
A20: 18 | B20: اشجار تيسبيسيا 2- 3 متر | C20: أشجار تيسبيسيا 2-3 متر | D20: 60 | E20: 60 | F20: معتمد (قرارك) | G20: عقود أبو خالد | H20: 4 | I20: 60
A21: 19 | B21: اقحوان افريقي مركن 12 | C21: اقحوان افريقى مركن 12 / زهور اقحوان افريقى مركن12 سم / زهور اقحوان افريقي مركن 12 | D21: 3.25 | E21: 3.25 | F21: معتمد (قرارك) | G21: عقود أبو خالد + مسحوبات تبوك من الرياض | H21: 7010 | I21: 3.25
A22: 20 | B22: اقحوان افريقي مركن 9 | C22: زهور اقحوان افريقي مركن 9 / زهور اقحوان افريقي مركن9 سم | D22: 1.5 / 2 | E22: 1.5 | F22: معتمد (قرارك) | G22: عقود أبو خالد + مسحوبات تبوك من الرياض | H22: 5975 | I22: 1.5
A23: 21 | B23: اقحوان افريقي هولندي مركن 12 | C23: زهور اقحوان افريقي هولندي مركن 12 | D23: 3.25 | E23: 3 | F23: معتمد (قرارك) | G23: مسحوبات تبوك من الرياض | H23: 1875 | I23: —
A24: 22 | B24: اكاسيا جلوكا من 1 - 2 متر | C24: اكاسيا جلوكا من 1 - 2 متر | D24: 25 | E24: 12 | F24: معتمد (قرارك) | G24: مسحوبات تبوك من الرياض | H24: 172 | I24: —
A25: 23 | B25: اكاليفا | C25: اكاليفا / اكاليفيا | D25: 2.5 | E25: 3 | F25: معتمد (قرارك) | G25: مسحوبات تبوك من الرياض + ترحيل تبوك للرياض | H25: 120 | I25: —
A26: 24 | B26: اليسوم | C26: زهور اليسوم / زهور اليسوم مركن9 سم | D26: 0.5 | E26: 0.5 | F26: معتمد (قرارك) | G26: عقود أبو خالد + مسحوبات تبوك من الرياض + ترحيل تبوك للرياض | H26: 5275 | I26: 0.5
A27: 25 | B27: بانستيم اخضر | C27: بانستيم اخضر | D27: 2.5 | E27: 3 | F27: معتمد (قرارك) | G27: مسحوبات تبوك من الرياض | H27: 150 | I27: —
A28: 26 | B28: بوتنج سويل 70 لتر | C28: بوتنج سويل 70 لتر | D28: 46 | E28: 64 | F28: معتمد (قرارك) | G28: مسحوبات تبوك من الرياض | H28: 10 | I28: —
A29: 27 | B29: بيرلايت 100 لتر | C29: بيرلايت 100 لتر | D29: 32.5 | E29: 25 | F29: معتمد (قرارك) | G29: مسحوبات تبوك من الرياض + ترحيل تبوك للرياض | H29: 125 | I29: —
A30: 28 | B30: تجيل كروي مركن 9 | C30: تجيل كروي مركن 9 سم | D30: 1.1 | E30: 0.9 | F30: معتمد (قرارك) | G30: مسحوبات تبوك من الرياض | H30: 2400 | I30: —
A31: 29 | B31: تراديسكانتيا مركن 19 علاقي | C31: تراديسكانتيا مركن 19 علاقي | D31: 10 | F31: يحتاج تسعير | G31: مسحوبات تبوك من الرياض | H31: 515 | I31: —
A32: 30 | B32: تيكوماريا 50 | C32: تيكوماريا / تيكوماريا 50 سم / تيكوماريا50 سم | D32: 2.5 / 4 | E32: 3 | F32: معتمد (قرارك) | G32: عقود أبو خالد + مسحوبات تبوك من الرياض + ترحيل تبوك للرياض | H32: 3530 | I32: 4
A33: 31 | B33: جازانيا | C33: زهور جازانيا | D33: 0.5 | E33: 0.5 | F33: معتمد (قرارك) | G33: عقود أبو خالد + مسحوبات تبوك من الرياض | H33: 5525 | I33: 0.5
A34: 32 | B34: جهنميه بلدي 1 متر | C34: جهنمية بلدي1 متر | D34: 6 | E34: 4 | F34: معتمد (قرارك) | G34: مسحوبات تبوك من الرياض | H34: 10 | I34: —
A35: 33 | B35: جهنميه بلدي 50 | C35: جهنمية بلدى واحد عود 50سم / جهنمية بلدي 50 سم | D35: 2.5 / 5 | E35: 3 | F35: معتمد (قرارك) | G35: مسحوبات تبوك من الرياض + ترحيل تبوك للرياض | H35: 600 | I35: —
A36: 34 | B36: جهنميه تايلاندي مركن 25 | C36: جهنميه تايلاندى مركن 25 | D36: 250 | E36: 200 | F36: معتمد (قرارك) | G36: مسحوبات تبوك من الرياض | H36: 10 | I36: —
A37: 35 | B37: جهنميه كرويه تايلندي صغير | C37: جهنمية كروية تايلندي صغير | D37: 250 | E37: 200 | F37: معتمد (قرارك) | G37: مسحوبات تبوك من الرياض | H37: 2 | I37: —
A38: 36 | B38: جهنميه كرويه تايلندي كبير | C38: جهنمية كروية تايلندي كبير | D38: 300 | E38: 230 | F38: معتمد (قرارك) | G38: مسحوبات تبوك من الرياض | H38: 5 | I38: —
A39: 37 | B39: جيرانيوم مركن 12 | C39: جيرانيوم مركن 12 / زهور جيرانيوم مركن 12 / زهور جيرانيوم مركن12 سم | D39: 3 / 3.75 | E39: 3 | F39: معتمد (قرارك) | G39: عقود أبو خالد + مسحوبات تبوك من الرياض | H39: 20355 | I39: 3
A40: 38 | B40: جيرانيوم مركن 9 | C40: زهور جرانيوم مركن9 سم / زهور جيرانيوم مركن 9 | D40: 1.25 / 1.4 / 1.5 | E40: 1.25 | F40: معتمد (قرارك) | G40: عقود أبو خالد + مسحوبات تبوك من الرياض | H40: 41825 | I40: 1.25
...

Sheet فرق أسعار أبو خالد
A1: عقود أبو خالد – إعادة التسعير بالسعر الموحد والفرق المرتجع لصالح أبو خالد (عقود نوفمبر 2025 وما بعدها)
A2: م | B2: التاريخ | C2: السند | D2: الفاتورة | E2: الصنف | F2: الكمية | G2: السعر المسجل | H2: الإجمالي المسجل | I2: السعر الموحد | J2: الإجمالي الموحد | K2: الفرق (المسجل − الموحد) | L2: ملاحظة
A3: 1 | B3: 45957 | C3: WHK-2656 | D3: RN-INV#26 | E3: زهور بيتونيا | F3: 1200 | G3: 0.75 | H3: =IF(G3="","",F3*G3) | I3: =IFERROR(IF(VLOOKUP("بيتونيا",'قائمة الأسعار الموحدة'!$B$3:$E$69,4,FALSE)="",G3,VLOOKUP("بيتونيا",'قائمة الأسعار الموحدة'!$B$3:$E$69,4,FALSE)),G3) | J3: =IF(I3="","",F3*I3) | K3: 0 | L3: قبل 1-11-2025 – مشمول بتسوية 62,937 (لا يُحتسب فرق)
A4: 2 | B4: 45963 | C4: WHK-2712 | D4: RN-INV#31 | E4: زهور بيتونيا | F4: 1500 | G4: 0.75 | H4: =IF(G4="","",F4*G4) | I4: =IFERROR(IF(VLOOKUP("بيتونيا",'قائمة الأسعار الموحدة'!$B$3:$E$69,4,FALSE)="",G4,VLOOKUP("بيتونيا",'قائمة الأسعار الموحدة'!$B$3:$E$69,4,FALSE)),G4) | J4: =IF(I4="","",F4*I4) | K4: =IF(OR(H4="",J4=""),"",H4-J4)
A5: 3 | B5: 45966 | C5: WHK-2776 | D5: RN-INV#35 | E5: زهور بيتونيا | F5: 1075 | G5: 0.7 | H5: =IF(G5="","",F5*G5) | I5: =IFERROR(IF(VLOOKUP("بيتونيا",'قائمة الأسعار الموحدة'!$B$3:$E$69,4,FALSE)="",G5,VLOOKUP("بيتونيا",'قائمة الأسعار الموحدة'!$B$3:$E$69,4,FALSE)),G5) | J5: =IF(I5="","",F5*I5) | K5: =IF(OR(H5="",J5=""),"",H5-J5)
A6: 4 | B6: 45967 | C6: WHK-2787 | D6: RN-INV#37 | E6: زهور بيتونيا | F6: 450 | G6: 0.75 | H6: =IF(G6="","",F6*G6) | I6: =IFERROR(IF(VLOOKUP("بيتونيا",'قائمة الأسعار الموحدة'!$B$3:$E$69,4,FALSE)="",G6,VLOOKUP("بيتونيا",'قائمة الأسعار الموحدة'!$B$3:$E$69,4,FALSE)),G6) | J6: =IF(I6="","",F6*I6) | K6: =IF(OR(H6="",J6=""),"",H6-J6)
A7: 5 | B7: 45969 | C7: WHK-2804 | D7: RN-INV#39 | E7: زهور سالفيا مركن9 سم | F7: 2725 | G7: 0.75 | H7: =IF(G7="","",F7*G7) | I7: =IFERROR(IF(VLOOKUP("سالفيا مركن 9",'قائمة الأسعار الموحدة'!$B$3:$E$69,4,FALSE)="",G7,VLOOKUP("سالفيا مركن 9",'قائمة الأسعار الموحدة'!$B$3:$E$69,4,FALSE)),G7) | J7: =IF(I7="","",F7*I7) | K7: =IF(OR(H7="",J7=""),"",H7-J7)
A8: 6 | B8: 45969 | C8: WHK-2804 | D8: RN-INV#39 | E8: زهور بيتونيا | F8: 825 | G8: 0.75 | H8: =IF(G8="","",F8*G8) | I8: =IFERROR(IF(VLOOKUP("بيتونيا",'قائمة الأسعار الموحدة'!$B$3:$E$69,4,FALSE)="",G8,VLOOKUP("بيتونيا",'قائمة الأسعار الموحدة'!$B$3:$E$69,4,FALSE)),G8) | J8: =IF(I8="","",F8*I8) | K8: =IF(OR(H8="",J8=""),"",H8-J8)
A9: 7 | B9: 45969 | C9: WHK-2804 | D9: RN-INV#39 | E9: زهور اقحوان افريقى مركن12 سم | F9: 3750 | G9: 3.25 | H9: =IF(G9="","",F9*G9) | I9: =IFERROR(IF(VLOOKUP("اقحوان افريقي مركن 12",'قائمة الأسعار الموحدة'!$B$3:$E$69,4,FALSE)="",G9,VLOOKUP("اقحوان افريقي مركن 12",'قائمة الأسعار الموحدة'!$B$3:$E$69,4,FALSE)),G9) | J9: =IF(I9="","",F9*I9) | K9: =IF(OR(H9="",J9=""),"",H9-J9)
A10: 8 | B10: 45971 | C10: WHK-2835 | D10: RN-INV#43 | E10: زهور بيتونيا | F10: 3250 | G10: 0.75 | H10: =IF(G10="","",F10*G10) | I10: =IFERROR(IF(VLOOKUP("بيتونيا",'قائمة الأسعار الموحدة'!$B$3:$E$69,4,FALSE)="",G10,VLOOKUP("بيتونيا",'قائمة الأسعار الموحدة'!$B$3:$E$69,4,FALSE)),G10) | J10: =IF(I10="","",F10*I10) | K10: =IF(OR(H10="",J10=""),"",H10-J10)
A11: 9 | B11: 45971 | C11: WHK-2835 | D11: RN-INV#43 | E11: زهور جرانيوم مركن9 سم | F11: 900 | G11: 1.4 | H11: =IF(G11="","",F11*G11) | I11: =IFERROR(IF(VLOOKUP("جيرانيوم مركن 9",'قائمة الأسعار الموحدة'!$B$3:$E$69,4,FALSE)="",G11,VLOOKUP("جيرانيوم مركن 9",'قائمة الأسعار الموحدة'!$B$3:$E$69,4,FALSE)),G11) | J11: =IF(I11="","",F11*I11) | K11: =IF(OR(H11="",J11=""),"",H11-J11)
A12: 10 | B12: 45971 | C12: WHK-2835 | D12: RN-INV#43 | E12: زهور جيرانيوم مركن12 سم | F12: 500 | G12: 3 | H12: =IF(G12="","",F12*G12) | I12: =IFERROR(IF(VLOOKUP("جيرانيوم مركن 12",'قائمة الأسعار الموحدة'!$B$3:$E$69,4,FALSE)="",G12,VLOOKUP("جيرانيوم مركن 12",'قائمة الأسعار الموحدة'!$B$3:$E$69,4,FALSE)),G12) | J12: =IF(I12="","",F12*I12) | K12: =IF(OR(H12="",J12=""),"",H12-J12)
A13: 11 | B13: 45971 | C13: WHK-2835 | D13: RN-INV#43 | E13: زهور جيرانيوم هولندى مركن12 سم | F13: 500 | G13: 3.75 | H13: =IF(G13="","",F13*G13) | I13: =IFERROR(IF(VLOOKUP("جيرانيوم هولندي مركن 12",'قائمة الأسعار الموحدة'!$B$3:$E$69,4,FALSE)="",G13,VLOOKUP("جيرانيوم هولندي مركن 12",'قائمة الأسعار الموحدة'!$B$3:$E$69,4,FALSE)),G13) | J13: =IF(I13="","",F13*I13) | K13: =IF(OR(H13="",J13=""),"",H13-J13)
A14: 12 | B14: 45971 | C14: WHK-2835 | D14: RN-INV#43 | E14: زهور هيبوستس مركن9 سم | F14: 500 | G14: 0.7 | H14: =IF(G14="","",F14*G14) | I14: =IFERROR(IF(VLOOKUP("هيبوستس",'قائمة الأسعار الموحدة'!$B$3:$E$69,4,FALSE)="",G14,VLOOKUP("هيبوستس",'قائمة الأسعار الموحدة'!$B$3:$E$69,4,FALSE)),G14) | J14: =IF(I14="","",F14*I14) | K14: =IF(OR(H14="",J14=""),"",H14-J14)
A15: 13 | B15: 45971 | C15: WHK-2835 | D15: RN-INV#43 | E15: زهور اقحوان افريقى مركن12 سم | F15: 500 | G15: 3.25 | H15: =IF(G15="","",F15*G15) | I15: =IFERROR(IF(VLOOKUP("اقحوان افريقي مركن 12",'قائمة الأسعار الموحدة'!$B$3:$E$69,4,FALSE)="",G15,VLOOKUP("اقحوان افريقي مركن 12",'قائمة الأسعار الموحدة'!$B$3:$E$69,4,FALSE)),G15) | J15: =IF(I15="","",F15*I15) | K15: =IF(OR(H15="",J15=""),"",H15-J15)
A16: 14 | B16: 45972 | C16: WHK-2853 | D16: RN-INV#46 | E16: زهور بيتونيا | F16: 10000 | G16: 0.75 | H16: =IF(G16="","",F16*G16) | I16: =IFERROR(IF(VLOOKUP("بيتونيا",'قائمة الأسعار الموحدة'!$B$3:$E$69,4,FALSE)="",G16,VLOOKUP("بيتونيا",'قائمة الأسعار الموحدة'!$B$3:$E$69,4,FALSE)),G16) | J16: =IF(I16="","",F16*I16) | K16: =IF(OR(H16="",J16=""),"",H16-J16)
A17: 15 | B17: 45973 | C17: WHK-2868 | D17: RN-INV#47 | E17: زهور بيتونيا | F17: 2000 | G17: 0.75 | H17: =IF(G17="","",F17*G17) | I17: =IFERROR(IF(VLOOKUP("بيتونيا",'قائمة الأسعار الموحدة'!$B$3:$E$69,4,FALSE)="",G17,VLOOKUP("بيتونيا",'قائمة الأسعار الموحدة'!$B$3:$E$69,4,FALSE)),G17) | J17: =IF(I17="","",F17*I17) | K17: =IF(OR(H17="",J17=""),"",H17-J17)
A18: 16 | B18: 45974 | C18: WHK-2881 | D18: RN-INV#49 | E18: زهور جيرانيوم هولندى مركن12 سم | F18: 510 | G18: 3.45 | H18: =IF(G18="","",F18*G18) | I18: =IFERROR(IF(VLOOKUP("جيرانيوم هولندي مركن 12",'قائمة الأسعار الموحدة'!$B$3:$E$69,4,FALSE)="",G18,VLOOKUP("جيرانيوم هولندي مركن 12",'قائمة الأسعار الموحدة'!$B$3:$E$69,4,FALSE)),G18) | J18: =IF(I18="","",F18*I18) | K18: =IF(OR(H18="",J18=""),"",H18-J18)
A19: 17 | B19: 45978 | C19: WHK-2912 | D19: RN-INV#52 | E19: زهور بيتونيا | F19: 2600 | G19: 0.75 | H19: =IF(G19="","",F19*G19) | I19: =IFERROR(IF(VLOOKUP("بيتونيا",'قائمة الأسعار الموحدة'!$B$3:$E$69,4,FALSE)="",G19,VLOOKUP("بيتونيا",'قائمة الأسعار الموحدة'!$B$3:$E$69,4,FALSE)),G19) | J19: =IF(I19="","",F19*I19) | K19: =IF(OR(H19="",J19=""),"",H19-J19)
A20: 18 | B20: 45978 | C20: WHK-2912 | D20: RN-INV#52 | E20: زهور جرانيوم مركن9 سم | F20: 500 | G20: 1.4 | H20: =IF(G20="","",F20*G20) | I20: =IFERROR(IF(VLOOKUP("جيرانيوم مركن 9",'قائمة الأسعار الموحدة'!$B$3:$E$69,4,FALSE)="",G20,VLOOKUP("جيرانيوم مركن 9",'قائمة الأسعار الموحدة'!$B$3:$E$69,4,FALSE)),G20) | J20: =IF(I20="","",F20*I20) | K20: =IF(OR(H20="",J20=""),"",H20-J20)
A21: 19 | B21: 45981 | C21: WHK-2948 | D21: RN-INV#55 | E21: زهور بيتونيا | F21: 1300 | G21: 0.75 | H21: =IF(G21="","",F21*G21) | I21: =IFERROR(IF(VLOOKUP("بيتونيا",'قائمة الأسعار الموحدة'!$B$3:$E$69,4,FALSE)="",G21,VLOOKUP("بيتونيا",'قائمة الأسعار الموحدة'!$B$3:$E$69,4,FALSE)),G21) | J21: =IF(I21="","",F21*I21) | K21: =IF(OR(H21="",J21=""),"",H21-J21)
A22: 20 | B22: 45981 | C22: WHK-2948 | D22: RN-INV#55 | E22: زهور جرانيوم مركن9 سم | F22: 400 | G22: 1.4 | H22: =IF(G22="","",F22*G22) | I22: =IFERROR(IF(VLOOKUP("جيرانيوم مركن 9",'قائمة الأسعار الموحدة'!$B$3:$E$69,4,FALSE)="",G22,VLOOKUP("جيرانيوم مركن 9",'قائمة الأسعار الموحدة'!$B$3:$E$69,4,FALSE)),G22) | J22: =IF(I22="","",F22*I22) | K22: =IF(OR(H22="",J22=""),"",H22-J22)
A23: 21 | B23: 45984 | C23: WHK-2971 | D23: RN-INV#61 | E23: زهور بيتونيا | F23: 8700 | G23: 0.7 | H23: =IF(G23="","",F23*G23) | I23: =IFERROR(IF(VLOOKUP("بيتونيا",'قائمة الأسعار الموحدة'!$B$3:$E$69,4,FALSE)="",G23,VLOOKUP("بيتونيا",'قائمة الأسعار الموحدة'!$B$3:$E$69,4,FALSE)),G23) | J23: =IF(I23="","",F23*I23) | K23: =IF(OR(H23="",J23=""),"",H23-J23)
A24: 22 | B24: 45985 | C24: WHK-2995 | D24: RN-INV#64 | E24: زهور بيتونيا | F24: 6000 | G24: 0.7 | H24: =IF(G24="","",F24*G24) | I24: =IFERROR(IF(VLOOKUP("بيتونيا",'قائمة الأسعار الموحدة'!$B$3:$E$69,4,FALSE)="",G24,VLOOKUP("بيتونيا",'قائمة الأسعار الموحدة'!$B$3:$E$69,4,FALSE)),G24) | J24: =IF(I24="","",F24*I24) | K24: =IF(OR(H24="",J24=""),"",H24-J24)
A25: 23 | B25: 45988 | C25: WHK-3029 | D25: RN-INV#68 | E25: زهور مارى جولد | F25: 225 | G25: 0.7 | H25: =IF(G25="","",F25*G25) | I25: =IFERROR(IF(VLOOKUP("ماري جولد",'قائمة الأسعار الموحدة'!$B$3:$E$69,4,FALSE)="",G25,VLOOKUP("ماري جولد",'قائمة الأسعار الموحدة'!$B$3:$E$69,4,FALSE)),G25) | J25: =IF(I25="","",F25*I25) | K25: =IF(OR(H25="",J25=""),"",H25-J25)
A26: 24 | B26: 45996 | C26: WHK-3135 | D26: RN-INV#78 | E26: زهور بيتونيا | F26: 2400 | G26: 0.7 | H26: =IF(G26="","",F26*G26) | I26: =IFERROR(IF(VLOOKUP("بيتونيا",'قائمة الأسعار الموحدة'!$B$3:$E$69,4,FALSE)="",G26,VLOOKUP("بيتونيا",'قائمة الأسعار الموحدة'!$B$3:$E$69,4,FALSE)),G26) | J26: =IF(I26="","",F26*I26) | K26: =IF(OR(H26="",J26=""),"",H26-J26)
A27: 25 | B27: 46006 | C27: WHK-3243 | D27: RN-INV#89 | E27: زهور جرانيوم مركن9 سم | F27: 1500 | G27: 1.25 | H27: =IF(G27="","",F27*G27) | I27: =IFERROR(IF(VLOOKUP("جيرانيوم مركن 9",'قائمة الأسعار الموحدة'!$B$3:$E$69,4,FALSE)="",G27,VLOOKUP("جيرانيوم مركن 9",'قائمة الأسعار الموحدة'!$B$3:$E$69,4,FALSE)),G27) | J27: =IF(I27="","",F27*I27) | K27: =IF(OR(H27="",J27=""),"",H27-J27)
A28: 26 | B28: 46021 | C28: WHK-3400 | D28: RN-INV#103 | E28: حجر ديكوري أبيض لامع 1:3 سم (10 كجم) | F28: 5 | G28: 25 | H28: =IF(G28="","",F28*G28) | I28: =IFERROR(IF(VLOOKUP("حجر ديكوري ابيض لامع 1: 3",'قائمة الأسعار الموحدة'!$B$3:$E$69,4,FALSE)="",G28,VLOOKUP("حجر ديكوري ابيض لامع 1: 3",'قائمة الأسعار الموحدة'!$B$3:$E$69,4,FALSE)),G28) | J28: =IF(I28="","",F28*I28) | K28: =IF(OR(H28="",J28=""),"",H28-J28)
A29: 27 | B29: 46021 | C29: WHK-3400 | D29: RN-INV#103 | E29: حجر ديكوري أحمر لامع 1:3 سم (10 كجم) | F29: 5 | G29: 25 | H29: =IF(G29="","",F29*G29) | I29: =IFERROR(IF(VLOOKUP("حجر ديكوري احمر لامع 1: 3",'قائمة الأسعار الموحدة'!$B$3:$E$69,4,FALSE)="",G29,VLOOKUP("حجر ديكوري احمر لامع 1: 3",'قائمة الأسعار الموحدة'!$B$3:$E$69,4,FALSE)),G29) | J29: =IF(I29="","",F29*I29) | K29: =IF(OR(H29="",J29=""),"",H29-J29)
A30: 28 | B30: 46021 | C30: WHK-3400 | D30: RN-INV#103 | E30: حجر ديكوري أبيض مطفي 3:5 سم (10 كجم) | F30: 5 | G30: 13 | H30: =IF(G30="","",F30*G30) | I30: =IFERROR(IF(VLOOKUP("حجر ديكوري ابيض مطفي 3: 5",'قائمة الأسعار الموحدة'!$B$3:$E$69,4,FALSE)="",G30,VLOOKUP("حجر ديكوري ابيض مطفي 3: 5",'قائمة الأسعار الموحدة'!$B$3:$E$69,4,FALSE)),G30) | J30: =IF(I30="","",F30*I30) | K30: =IF(OR(H30="",J30=""),"",H30-J30)
A31: 29 | B31: 46021 | C31: WHK-3400 | D31: RN-INV#103 | E31: حجر ديكوري أسود لامع 1:3 سم (10 كجم) | F31: 5 | G31: 25 | H31: =IF(G31="","",F31*G31) | I31: =IFERROR(IF(VLOOKUP("حجر ديكوري اسود لامع 1: 3",'قائمة الأسعار الموحدة'!$B$3:$E$69,4,FALSE)="",G31,VLOOKUP("حجر ديكوري اسود لامع 1: 3",'قائمة الأسعار الموحدة'!$B$3:$E$69,4,FALSE)),G31) | J31: =IF(I31="","",F31*I31) | K31: =IF(OR(H31="",J31=""),"",H31-J31)
A32: 30 | B32: 46021 | C32: WHK-3400 | D32: RN-INV#103 | E32: حجر ديكوري أصفر مطفي 1:3 سم (10 كجم) | F32: 5 | G32: 13 | H32: =IF(G32="","",F32*G32) | I32: =IFERROR(IF(VLOOKUP("حجر ديكوري اصفر مطفي 1: 3",'قائمة الأسعار الموحدة'!$B$3:$E$69,4,FALSE)="",G32,VLOOKUP("حجر ديكوري اصفر مطفي 1: 3",'قائمة الأسعار الموحدة'!$B$3:$E$69,4,FALSE)),G32) | J32: =IF(I32="","",F32*I32) | K32: =IF(OR(H32="",J32=""),"",H32-J32)
A33: 31 | B33: 46058 | C33: WHK-3758 | D33: RN-INV#140 | E33: زهور بيتونيا | F33: 35600 | G33: 0.5 | H33: =IF(G33="","",F33*G33) | I33: =IFERROR(IF(VLOOKUP("بيتونيا",'قائمة الأسعار الموحدة'!$B$3:$E$69,4,FALSE)="",G33,VLOOKUP("بيتونيا",'قائمة الأسعار الموحدة'!$B$3:$E$69,4,FALSE)),G33) | J33: =IF(I33="","",F33*I33) | K33: =IF(OR(H33="",J33=""),"",H33-J33)
A34: 32 | B34: 46058 | C34: WHK-3758 | D34: RN-INV#140 | E34: زهور سالفيا مركن9 سم | F34: 3000 | G34: 0.5 | H34: =IF(G34="","",F34*G34) | I34: =IFERROR(IF(VLOOKUP("سالفيا مركن 9",'قائمة الأسعار الموحدة'!$B$3:$E$69,4,FALSE)="",G34,VLOOKUP("سالفيا مركن 9",'قائمة الأسعار الموحدة'!$B$3:$E$69,4,FALSE)),G34) | J34: =IF(I34="","",F34*I34) | K34: =IF(OR(H34="",J34=""),"",H34-J34)
A35: 33 | B35: 46058 | C35: WHK-3758 | D35: RN-INV#140 | E35: زهور قرنفل صيني مركن9 سم | F35: 2000 | G35: 0.5 | H35: =IF(G35="","",F35*G35) | I35: =IFERROR(IF(VLOOKUP("قرنفل صيني",'قائمة الأسعار الموحدة'!$B$3:$E$69,4,FALSE)="",G35,VLOOKUP("قرنفل صيني",'قائمة الأسعار الموحدة'!$B$3:$E$69,4,FALSE)),G35) | J35: =IF(I35="","",F35*I35) | K35: =IF(OR(H35="",J35=""),"",H35-J35)
A36: 34 | B36: 46058 | C36: WHK-3760 | D36: RN-INV#141 | E36: زهور بيتونيا | F36: 55450 | G36: 0.5 | H36: =IF(G36="","",F36*G36) | I36: =IFERROR(IF(VLOOKUP("بيتونيا",'قائمة الأسعار الموحدة'!$B$3:$E$69,4,FALSE)="",G36,VLOOKUP("بيتونيا",'قائمة الأسعار الموحدة'!$B$3:$E$69,4,FALSE)),G36) | J36: =IF(I36="","",F36*I36) | K36: =IF(OR(H36="",J36=""),"",H36-J36)
A37: 35 | B37: 46058 | C37: WHK-3760 | D37: RN-INV#141 | E37: زهور سالفيا مركن9 سم | F37: 300 | G37: 0.5 | H37: =IF(G37="","",F37*G37) | I37: =IFERROR(IF(VLOOKUP("سالفيا مركن 9",'قائمة الأسعار الموحدة'!$B$3:$E$69,4,FALSE)="",G37,VLOOKUP("سالفيا مركن 9",'قائمة الأسعار الموحدة'!$B$3:$E$69,4,FALSE)),G37) | J37: =IF(I37="","",F37*I37) | K37: =IF(OR(H37="",J37=""),"",H37-J37)
A38: 36 | B38: 46058 | C38: WHK-3760 | D38: RN-INV#141 | E38: زهور اليسوم مركن9 سم | F38: 200 | G38: 0.5 | H38: =IF(G38="","",F38*G38) | I38: =IFERROR(IF(VLOOKUP("اليسوم",'قائمة الأسعار الموحدة'!$B$3:$E$69,4,FALSE)="",G38,VLOOKUP("اليسوم",'قائمة الأسعار الموحدة'!$B$3:$E$69,4,FALSE)),G38) | J38: =IF(I38="","",F38*I38) | K38: =IF(OR(H38="",J38=""),"",H38-J38)
A39: 37 | B39: 46058 | C39: WHK-3760 | D39: RN-INV#141 | E39: زهور قرنفل صيني مركن9 سم | F39: 300 | G39: 0.5 | H39: =IF(G39="","",F39*G39) | I39: =IFERROR(IF(VLOOKUP("قرنفل صيني",'قائمة الأسعار الموحدة'!$B$3:$E$69,4,FALSE)="",G39,VLOOKUP("قرنفل صيني",'قائمة الأسعار الموحدة'!$B$3:$E$69,4,FALSE)),G39) | J39: =IF(I39="","",F39*I39) | K39: =IF(OR(H39="",J39=""),"",H39-J39)
A40: 38 | B40: 46058 | C40: WHK-3760 | D40: RN-INV#141 | E40: زهور ملفوف براسيكا مركن9 سم | F40: 50 | G40: 0.5 | H40: =IF(G40="","",F40*G40) | I40: =IFERROR(IF(VLOOKUP("ملفوف مركن 9",'قائمة الأسعار الموحدة'!$B$3:$E$69,4,FALSE)="",G40,VLOOKUP("ملفوف مركن 9",'قائمة الأسعار الموحدة'!$B$3:$E$69,4,FALSE)),G40) | J40: =IF(I40="","",F40*I40) | K40: =IF(OR(H40="",J40=""),"",H40-J40)
...

Sheet مسحوبات نسما من الرياض
A1: مسحوبات تبوك (نسما) من مزرعة الرياض بالسعر الموحد = مديونية على أبو مازن
A2: م | B2: التاريخ | C2: السند | D2: الصنف | E2: الكمية | F2: السعر المسجل | G2: الإجمالي المسجل | H2: السعر الموحد | I2: الإجمالي الموحد | J2: الفرق (المسجل − الموحد) | K2: ملاحظة
A3: 1 | B3: 45906 | C3: RNP-2113 | D3: مارى جولد | E3: 10000 | F3: 0.5 | G3: =IF(F3="","",E3*F3) | H3: =IFERROR(IF(VLOOKUP("ماري جولد",'قائمة الأسعار الموحدة'!$B$3:$E$69,4,FALSE)="",F3,VLOOKUP("ماري جولد",'قائمة الأسعار الموحدة'!$B$3:$E$69,4,FALSE)),F3) | I3: =IF(H3="","",E3*H3) | J3: =IF(OR(G3="",I3=""),"",G3-I3)
A4: 2 | B4: 45926 | C4: RNP-2293 | D4: زهور بيتونيا | E4: 6500 | F4: 0.5 | G4: =IF(F4="","",E4*F4) | H4: =IFERROR(IF(VLOOKUP("بيتونيا",'قائمة الأسعار الموحدة'!$B$3:$E$69,4,FALSE)="",F4,VLOOKUP("بيتونيا",'قائمة الأسعار الموحدة'!$B$3:$E$69,4,FALSE)),F4) | I4: =IF(H4="","",E4*H4) | J4: =IF(OR(G4="",I4=""),"",G4-I4)
A5: 3 | B5: 45926 | C5: RNP-2293 | D5: زهور جيرانيوم مركن 12 | E5: 500 | F5: 3.75 | G5: =IF(F5="","",E5*F5) | H5: =IFERROR(IF(VLOOKUP("جيرانيوم مركن 12",'قائمة الأسعار الموحدة'!$B$3:$E$69,4,FALSE)="",F5,VLOOKUP("جيرانيوم مركن 12",'قائمة الأسعار الموحدة'!$B$3:$E$69,4,FALSE)),F5) | I5: =IF(H5="","",E5*H5) | J5: =IF(OR(G5="",I5=""),"",G5-I5)
A6: 4 | B6: 45926 | C6: RNP-2293 | D6: زهور ماري جولد فرنسى | E6: 250 | F6: 0.5 | G6: =IF(F6="","",E6*F6) | H6: =IFERROR(IF(VLOOKUP("ماري جولد فرنسي",'قائمة الأسعار الموحدة'!$B$3:$E$69,4,FALSE)="",F6,VLOOKUP("ماري جولد فرنسي",'قائمة الأسعار الموحدة'!$B$3:$E$69,4,FALSE)),F6) | I6: =IF(H6="","",E6*H6) | J6: =IF(OR(G6="",I6=""),"",G6-I6)
A7: 5 | B7: 45926 | C7: RNP-2367 | D7: حجر اصفر مطفى | E7: 1 | F7: 10.5 | G7: =IF(F7="","",E7*F7) | H7: =IFERROR(IF(VLOOKUP("حجر ديكوري اصفر مطفي 1: 3",'قائمة الأسعار الموحدة'!$B$3:$E$69,4,FALSE)="",F7,VLOOKUP("حجر ديكوري اصفر مطفي 1: 3",'قائمة الأسعار الموحدة'!$B$3:$E$69,4,FALSE)),F7) | I7: =IF(H7="","",E7*H7) | J7: =IF(OR(G7="",I7=""),"",G7-I7)
A8: 6 | B8: 45937 | C8: RNP-2395 | D8: سكندابسس مركن 19 علاقي | E8: 2000 | F8: 10 | G8: =IF(F8="","",E8*F8) | H8: =IFERROR(IF(VLOOKUP("سكندابسس مركن 19 علاقي",'قائمة الأسعار الموحدة'!$B$3:$E$69,4,FALSE)="",F8,VLOOKUP("سكندابسس مركن 19 علاقي",'قائمة الأسعار الموحدة'!$B$3:$E$69,4,FALSE)),F8) | I8: =IF(H8="","",E8*H8) | J8: =IF(OR(G8="",I8=""),"",G8-I8)
A9: 7 | B9: 45937 | C9: RNP-2395 | D9: هيدرا علاقي مركن 19 | E9: 188 | F9: 10 | G9: =IF(F9="","",E9*F9) | H9: =IFERROR(IF(VLOOKUP("هيدرا علاقي مركن 19",'قائمة الأسعار الموحدة'!$B$3:$E$69,4,FALSE)="",F9,VLOOKUP("هيدرا علاقي مركن 19",'قائمة الأسعار الموحدة'!$B$3:$E$69,4,FALSE)),F9) | I9: =IF(H9="","",E9*H9) | J9: =IF(OR(G9="",I9=""),"",G9-I9)
A10: 8 | B10: 45937 | C10: RNP-2395 | D10: اقحوان افريقى مركن 12 | E10: 2010 | F10: 3.25 | G10: =IF(F10="","",E10*F10) | H10: =IFERROR(IF(VLOOKUP("اقحوان افريقي مركن 12",'قائمة الأسعار الموحدة'!$B$3:$E$69,4,FALSE)="",F10,VLOOKUP("اقحوان افريقي مركن 12",'قائمة الأسعار الموحدة'!$B$3:$E$69,4,FALSE)),F10) | I10: =IF(H10="","",E10*H10) | J10: =IF(OR(G10="",I10=""),"",G10-I10)
A11: 9 | B11: 45937 | C11: RNP-2395 | D11: هيبوستس | E11: 1500 | F11: 2.5 | G11: =IF(F11="","",E11*F11) | H11: =IFERROR(IF(VLOOKUP("هيبوستس",'قائمة الأسعار الموحدة'!$B$3:$E$69,4,FALSE)="",F11,VLOOKUP("هيبوستس",'قائمة الأسعار الموحدة'!$B$3:$E$69,4,FALSE)),F11) | I11: =IF(H11="","",E11*H11) | J11: =IF(OR(G11="",I11=""),"",G11-I11)
A12: 10 | B12: 45937 | C12: RNP-2395 | D12: زهور جيرانيوم مركن 12 | E12: 1005 | F12: 3.75 | G12: =IF(F12="","",E12*F12) | H12: =IFERROR(IF(VLOOKUP("جيرانيوم مركن 12",'قائمة الأسعار الموحدة'!$B$3:$E$69,4,FALSE)="",F12,VLOOKUP("جيرانيوم مركن 12",'قائمة الأسعار الموحدة'!$B$3:$E$69,4,FALSE)),F12) | I12: =IF(H12="","",E12*H12) | J12: =IF(OR(G12="",I12=""),"",G12-I12)
A13: 11 | B13: 45937 | C13: RNP-2395 | D13: زهور جيرانيوم مركن 9 | E13: 1000 | F13: 1.5 | G13: =IF(F13="","",E13*F13) | H13: =IFERROR(IF(VLOOKUP("جيرانيوم مركن 9",'قائمة الأسعار الموحدة'!$B$3:$E$69,4,FALSE)="",F13,VLOOKUP("جيرانيوم مركن 9",'قائمة الأسعار الموحدة'!$B$3:$E$69,4,FALSE)),F13) | I13: =IF(H13="","",E13*H13) | J13: =IF(OR(G13="",I13=""),"",G13-I13)
A14: 12 | B14: 45937 | C14: RNP-2395 | D14: جهنميه تايلاندى مركن 25 | E14: 10 | F14: 250 | G14: =IF(F14="","",E14*F14) | H14: =IFERROR(IF(VLOOKUP("جهنميه تايلاندي مركن 25",'قائمة الأسعار الموحدة'!$B$3:$E$69,4,FALSE)="",F14,VLOOKUP("جهنميه تايلاندي مركن 25",'قائمة الأسعار الموحدة'!$B$3:$E$69,4,FALSE)),F14) | I14: =IF(H14="","",E14*H14) | J14: =IF(OR(G14="",I14=""),"",G14-I14)
A15: 13 | B15: 45937 | C15: RNP-2395 | D15: تراديسكانتيا مركن 19 علاقي | E15: 220 | F15: 10 | G15: =IF(F15="","",E15*F15) | H15: =IFERROR(IF(VLOOKUP("تراديسكانتيا مركن 19 علاقي",'قائمة الأسعار الموحدة'!$B$3:$E$69,4,FALSE)="",F15,VLOOKUP("تراديسكانتيا مركن 19 علاقي",'قائمة الأسعار الموحدة'!$B$3:$E$69,4,FALSE)),F15) | I15: =IF(H15="","",E15*H15) | J15: =IF(OR(G15="",I15=""),"",G15-I15)
A16: 14 | B16: 45947 | C16: RNP-2512 | D16: زهور ماري جولد | E16: 1100 | F16: 0.5 | G16: =IF(F16="","",E16*F16) | H16: =IFERROR(IF(VLOOKUP("ماري جولد",'قائمة الأسعار الموحدة'!$B$3:$E$69,4,FALSE)="",F16,VLOOKUP("ماري جولد",'قائمة الأسعار الموحدة'!$B$3:$E$69,4,FALSE)),F16) | I16: =IF(H16="","",E16*H16) | J16: =IF(OR(G16="",I16=""),"",G16-I16)
A17: 15 | B17: 45947 | C17: RNP-2512 | D17: زهور بيتونيا | E17: 3600 | F17: 0.5 | G17: =IF(F17="","",E17*F17) | H17: =IFERROR(IF(VLOOKUP("بيتونيا",'قائمة الأسعار الموحدة'!$B$3:$E$69,4,FALSE)="",F17,VLOOKUP("بيتونيا",'قائمة الأسعار الموحدة'!$B$3:$E$69,4,FALSE)),F17) | I17: =IF(H17="","",E17*H17) | J17: =IF(OR(G17="",I17=""),"",G17-I17)
A18: 16 | B18: 45947 | C18: RNP-2512 | D18: بوتنج سويل 70 لتر | E18: 10 | F18: 46 | G18: =IF(F18="","",E18*F18) | H18: =IFERROR(IF(VLOOKUP("بوتنج سويل 70 لتر",'قائمة الأسعار الموحدة'!$B$3:$E$69,4,FALSE)="",F18,VLOOKUP("بوتنج سويل 70 لتر",'قائمة الأسعار الموحدة'!$B$3:$E$69,4,FALSE)),F18) | I18: =IF(H18="","",E18*H18) | J18: =IF(OR(G18="",I18=""),"",G18-I18)
A19: 17 | B19: 45954 | C19: RNP-2608 | D19: زهور بيتونيا | E19: 20000 | F19: 0.5 | G19: =IF(F19="","",E19*F19) | H19: =IFERROR(IF(VLOOKUP("بيتونيا",'قائمة الأسعار الموحدة'!$B$3:$E$69,4,FALSE)="",F19,VLOOKUP("بيتونيا",'قائمة الأسعار الموحدة'!$B$3:$E$69,4,FALSE)),F19) | I19: =IF(H19="","",E19*H19) | J19: =IF(OR(G19="",I19=""),"",G19-I19)
A20: 18 | B20: 45962 | C20: RNP-2704 | D20: زهور اقحوان افريقي مركن 12 | E20: 750 | F20: 3.25 | G20: =IF(F20="","",E20*F20) | H20: =IFERROR(IF(VLOOKUP("اقحوان افريقي مركن 12",'قائمة الأسعار الموحدة'!$B$3:$E$69,4,FALSE)="",F20,VLOOKUP("اقحوان افريقي مركن 12",'قائمة الأسعار الموحدة'!$B$3:$E$69,4,FALSE)),F20) | I20: =IF(H20="","",E20*H20) | J20: =IF(OR(G20="",I20=""),"",G20-I20)
A21: 19 | B21: 45962 | C21: RNP-2704 | D21: زهور قرنفل صيني | E21: 250 | F21: 0.5 | G21: =IF(F21="","",E21*F21) | H21: =IFERROR(IF(VLOOKUP("قرنفل صيني",'قائمة الأسعار الموحدة'!$B$3:$E$69,4,FALSE)="",F21,VLOOKUP("قرنفل صيني",'قائمة الأسعار الموحدة'!$B$3:$E$69,4,FALSE)),F21) | I21: =IF(H21="","",E21*H21) | J21: =IF(OR(G21="",I21=""),"",G21-I21)
A22: 20 | B22: 45962 | C22: RNP-2704 | D22: لانتانا لبناني صغير | E22: 40 | F22: 2.5 | G22: =IF(F22="","",E22*F22) | H22: =IFERROR(IF(VLOOKUP("لانتانا لبناني صغير",'قائمة الأسعار الموحدة'!$B$3:$E$69,4,FALSE)="",F22,VLOOKUP("لانتانا لبناني صغير",'قائمة الأسعار الموحدة'!$B$3:$E$69,4,FALSE)),F22) | I22: =IF(H22="","",E22*H22) | J22: =IF(OR(G22="",I22=""),"",G22-I22)
A23: 21 | B23: 45962 | C23: RNP-2704 | D23: بانستيم اخضر | E23: 150 | F23: 2.5 | G23: =IF(F23="","",E23*F23) | H23: =IFERROR(IF(VLOOKUP("بانستيم اخضر",'قائمة الأسعار الموحدة'!$B$3:$E$69,4,FALSE)="",F23,VLOOKUP("بانستيم اخضر",'قائمة الأسعار الموحدة'!$B$3:$E$69,4,FALSE)),F23) | I23: =IF(H23="","",E23*H23) | J23: =IF(OR(G23="",I23=""),"",G23-I23)
A24: 22 | B24: 45964 | C24: RNP-2748 | D24: زهور جيرانيوم مركن 9 | E24: 625 | F24: 1.5 | G24: =IF(F24="","",E24*F24) | H24: =IFERROR(IF(VLOOKUP("جيرانيوم مركن 9",'قائمة الأسعار الموحدة'!$B$3:$E$69,4,FALSE)="",F24,VLOOKUP("جيرانيوم مركن 9",'قائمة الأسعار الموحدة'!$B$3:$E$69,4,FALSE)),F24) | I24: =IF(H24="","",E24*H24) | J24: =IF(OR(G24="",I24=""),"",G24-I24)
A25: 23 | B25: 45969 | C25: RNP-2805 | D25: زهور جيرانيوم مركن 9 | E25: 30000 | F25: 1.5 | G25: =IF(F25="","",E25*F25) | H25: =IFERROR(IF(VLOOKUP("جيرانيوم مركن 9",'قائمة الأسعار الموحدة'!$B$3:$E$69,4,FALSE)="",F25,VLOOKUP("جيرانيوم مركن 9",'قائمة الأسعار الموحدة'!$B$3:$E$69,4,FALSE)),F25) | I25: =IF(H25="","",E25*H25) | J25: =IF(OR(G25="",I25=""),"",G25-I25)
A26: 24 | B26: 45969 | C26: RNP-2805 | D26: زهور هيبوستس | E26: 1000 | F26: 0.55 | G26: =IF(F26="","",E26*F26) | H26: =IFERROR(IF(VLOOKUP("هيبوستس",'قائمة الأسعار الموحدة'!$B$3:$E$69,4,FALSE)="",F26,VLOOKUP("هيبوستس",'قائمة الأسعار الموحدة'!$B$3:$E$69,4,FALSE)),F26) | I26: =IF(H26="","",E26*H26) | J26: =IF(OR(G26="",I26=""),"",G26-I26)
A27: 25 | B27: 45999 | C27: RNP-3160 | D27: كمبوست 10 ك | E27: 19 | F27: 2 | G27: =IF(F27="","",E27*F27) | H27: =IFERROR(IF(VLOOKUP("كمبوست 10 ك",'قائمة الأسعار الموحدة'!$B$3:$E$69,4,FALSE)="",F27,VLOOKUP("كمبوست 10 ك",'قائمة الأسعار الموحدة'!$B$3:$E$69,4,FALSE)),F27) | I27: =IF(H27="","",E27*H27) | J27: =IF(OR(G27="",I27=""),"",G27-I27)
A28: 26 | B28: 45999 | C28: RNP-3165 | D28: زهور اليسوم | E28: 175 | F28: 0.5 | G28: =IF(F28="","",E28*F28) | H28: =IFERROR(IF(VLOOKUP("اليسوم",'قائمة الأسعار الموحدة'!$B$3:$E$69,4,FALSE)="",F28,VLOOKUP("اليسوم",'قائمة الأسعار الموحدة'!$B$3:$E$69,4,FALSE)),F28) | I28: =IF(H28="","",E28*H28) | J28: =IF(OR(G28="",I28=""),"",G28-I28)
A29: 27 | B29: 46011 | C29: RNP-3276 | D29: زهور ماري جولد | E29: 1500 | F29: 0.5 | G29: =IF(F29="","",E29*F29) | H29: =IFERROR(IF(VLOOKUP("ماري جولد",'قائمة الأسعار الموحدة'!$B$3:$E$69,4,FALSE)="",F29,VLOOKUP("ماري جولد",'قائمة الأسعار الموحدة'!$B$3:$E$69,4,FALSE)),F29) | I29: =IF(H29="","",E29*H29) | J29: =IF(OR(G29="",I29=""),"",G29-I29)
A30: 28 | B30: 46011 | C30: RNP-3276 | D30: زهور بيتونيا | E30: 5885 | F30: 0.5 | G30: =IF(F30="","",E30*F30) | H30: =IFERROR(IF(VLOOKUP("بيتونيا",'قائمة الأسعار الموحدة'!$B$3:$E$69,4,FALSE)="",F30,VLOOKUP("بيتونيا",'قائمة الأسعار الموحدة'!$B$3:$E$69,4,FALSE)),F30) | I30: =IF(H30="","",E30*H30) | J30: =IF(OR(G30="",I30=""),"",G30-I30)
A31: 29 | B31: 46011 | C31: RNP-3276 | D31: اكاسيا جلوكا من 1 - 2 متر | E31: 16 | F31: 25 | G31: =IF(F31="","",E31*F31) | H31: =IFERROR(IF(VLOOKUP("اكاسيا جلوكا من 1 - 2 متر",'قائمة الأسعار الموحدة'!$B$3:$E$69,4,FALSE)="",F31,VLOOKUP("اكاسيا جلوكا من 1 - 2 متر",'قائمة الأسعار الموحدة'!$B$3:$E$69,4,FALSE)),F31) | I31: =IF(H31="","",E31*H31) | J31: =IF(OR(G31="",I31=""),"",G31-I31)
A32: 30 | B32: 46026 | C32: RNP-3432 | D32: جيرانيوم مركن 12 | E32: 17900 | F32: 3 | G32: =IF(F32="","",E32*F32) | H32: =IFERROR(IF(VLOOKUP("جيرانيوم مركن 12",'قائمة الأسعار الموحدة'!$B$3:$E$69,4,FALSE)="",F32,VLOOKUP("جيرانيوم مركن 12",'قائمة الأسعار الموحدة'!$B$3:$E$69,4,FALSE)),F32) | I32: =IF(H32="","",E32*H32) | J32: =IF(OR(G32="",I32=""),"",G32-I32)
A33: 31 | B33: 46026 | C33: RNP-3432 | D33: زهور اليسوم | E33: 2000 | F33: 0.5 | G33: =IF(F33="","",E33*F33) | H33: =IFERROR(IF(VLOOKUP("اليسوم",'قائمة الأسعار الموحدة'!$B$3:$E$69,4,FALSE)="",F33,VLOOKUP("اليسوم",'قائمة الأسعار الموحدة'!$B$3:$E$69,4,FALSE)),F33) | I33: =IF(H33="","",E33*H33) | J33: =IF(OR(G33="",I33=""),"",G33-I33)
A34: 32 | B34: 46026 | C34: RNP-3433 | D34: زهور جيرانيوم مركن 9 | E34: 1400 | F34: 1.5 | G34: =IF(F34="","",E34*F34) | H34: =IFERROR(IF(VLOOKUP("جيرانيوم مركن 9",'قائمة الأسعار الموحدة'!$B$3:$E$69,4,FALSE)="",F34,VLOOKUP("جيرانيوم مركن 9",'قائمة الأسعار الموحدة'!$B$3:$E$69,4,FALSE)),F34) | I34: =IF(H34="","",E34*H34) | J34: =IF(OR(G34="",I34=""),"",G34-I34)
A35: 33 | B35: 46026 | C35: RNP-3433 | D35: زهور بيتونيا | E35: 1000 | F35: 0.5 | G35: =IF(F35="","",E35*F35) | H35: =IFERROR(IF(VLOOKUP("بيتونيا",'قائمة الأسعار الموحدة'!$B$3:$E$69,4,FALSE)="",F35,VLOOKUP("بيتونيا",'قائمة الأسعار الموحدة'!$B$3:$E$69,4,FALSE)),F35) | I35: =IF(H35="","",E35*H35) | J35: =IF(OR(G35="",I35=""),"",G35-I35)
A36: 34 | B36: 46026 | C36: RNP-3433 | D36: زهور ماري جولد | E36: 600 | F36: 0.5 | G36: =IF(F36="","",E36*F36) | H36: =IFERROR(IF(VLOOKUP("ماري جولد",'قائمة الأسعار الموحدة'!$B$3:$E$69,4,FALSE)="",F36,VLOOKUP("ماري جولد",'قائمة الأسعار الموحدة'!$B$3:$E$69,4,FALSE)),F36) | I36: =IF(H36="","",E36*H36) | J36: =IF(OR(G36="",I36=""),"",G36-I36)
A37: 35 | B37: 46026 | C37: RNP-3433 | D37: زهور اليسوم | E37: 2000 | F37: 0.5 | G37: =IF(F37="","",E37*F37) | H37: =IFERROR(IF(VLOOKUP("اليسوم",'قائمة الأسعار الموحدة'!$B$3:$E$69,4,FALSE)="",F37,VLOOKUP("اليسوم",'قائمة الأسعار الموحدة'!$B$3:$E$69,4,FALSE)),F37) | I37: =IF(H37="","",E37*H37) | J37: =IF(OR(G37="",I37=""),"",G37-I37)
A38: 36 | B38: 46026 | C38: RNT-3434 | D38: زهور ماري جولد | E38: 2000 | F38: 0.5 | G38: =IF(F38="","",E38*F38) | H38: =IFERROR(IF(VLOOKUP("ماري جولد",'قائمة الأسعار الموحدة'!$B$3:$E$69,4,FALSE)="",F38,VLOOKUP("ماري جولد",'قائمة الأسعار الموحدة'!$B$3:$E$69,4,FALSE)),F38) | I38: =IF(H38="","",E38*H38) | J38: =IF(OR(G38="",I38=""),"",G38-I38)
A39: 37 | B39: 46029 | C39: RNP-3491 | D39: زهور بيتونيا | E39: 2200 | F39: 0.5 | G39: =IF(F39="","",E39*F39) | H39: =IFERROR(IF(VLOOKUP("بيتونيا",'قائمة الأسعار الموحدة'!$B$3:$E$69,4,FALSE)="",F39,VLOOKUP("بيتونيا",'قائمة الأسعار الموحدة'!$B$3:$E$69,4,FALSE)),F39) | I39: =IF(H39="","",E39*H39) | J39: =IF(OR(G39="",I39=""),"",G39-I39)
A40: 38 | B40: 46029 | C40: RNP-3491 | D40: زهور اليسوم | E40: 700 | F40: 0.5 | G40: =IF(F40="","",E40*F40) | H40: =IFERROR(IF(VLOOKUP("اليسوم",'قائمة الأسعار الموحدة'!$B$3:$E$69,4,FALSE)="",F40,VLOOKUP("اليسوم",'قائمة الأسعار الموحدة'!$B$3:$E$69,4,FALSE)),F40) | I40: =IF(H40="","",E40*H40) | J40: =IF(OR(G40="",I40=""),"",G40-I40)
...

Sheet ترحيل تبوك إلى الرياض
A1: الترحيل من تبوك إلى مزرعة الرياض بالسعر الموحد = دعم تشغيلي من أبو مازن
A2: م | B2: التاريخ | C2: السند | D2: الصنف | E2: الكمية | F2: السعر المسجل | G2: الإجمالي المسجل | H2: السعر الموحد | I2: الإجمالي الموحد | J2: الفرق (المسجل − الموحد) | K2: ملاحظة
A3: 1 | B3: 45874 | C3: TNR-1867 | D3: حجر ديكورى ابيض مطفى 3:5سم-10كجم | E3: 598 | F3: 10 | G3: =IF(F3="","",E3*F3) | H3: =IFERROR(IF(VLOOKUP("حجر ديكوري ابيض مطفي 3: 5",'قائمة الأسعار الموحدة'!$B$3:$E$69,4,FALSE)="",F3,VLOOKUP("حجر ديكوري ابيض مطفي 3: 5",'قائمة الأسعار الموحدة'!$B$3:$E$69,4,FALSE)),F3) | I3: =IF(H3="","",E3*H3) | J3: =IF(OR(G3="",I3=""),"",G3-I3) | K3: تاريخ مصحح من 2026 إلى 2025
A4: 2 | B4: 45874 | C4: TNR-1867 | D4: ابيض لامع | E4: 11 | F4: 18 | G4: =IF(F4="","",E4*F4) | H4: =IFERROR(IF(VLOOKUP("حجر ديكوري ابيض لامع 1: 3",'قائمة الأسعار الموحدة'!$B$3:$E$69,4,FALSE)="",F4,VLOOKUP("حجر ديكوري ابيض لامع 1: 3",'قائمة الأسعار الموحدة'!$B$3:$E$69,4,FALSE)),F4) | I4: =IF(H4="","",E4*H4) | J4: =IF(OR(G4="",I4=""),"",G4-I4) | K4: تاريخ مصحح من 2026 إلى 2025
A5: 3 | B5: 45874 | C5: TNR-1867 | D5: اسود لامع | E5: 9 | F5: 18 | G5: =IF(F5="","",E5*F5) | H5: =IFERROR(IF(VLOOKUP("حجر ديكوري اسود لامع 1: 3",'قائمة الأسعار الموحدة'!$B$3:$E$69,4,FALSE)="",F5,VLOOKUP("حجر ديكوري اسود لامع 1: 3",'قائمة الأسعار الموحدة'!$B$3:$E$69,4,FALSE)),F5) | I5: =IF(H5="","",E5*H5) | J5: =IF(OR(G5="",I5=""),"",G5-I5) | K5: تاريخ مصحح من 2026 إلى 2025
A6: 4 | B6: 45874 | C6: TNR-1867 | D6: احمر لامع | E6: 10 | F6: 18 | G6: =IF(F6="","",E6*F6) | H6: =IFERROR(IF(VLOOKUP("حجر ديكوري احمر لامع 1: 3",'قائمة الأسعار الموحدة'!$B$3:$E$69,4,FALSE)="",F6,VLOOKUP("حجر ديكوري احمر لامع 1: 3",'قائمة الأسعار الموحدة'!$B$3:$E$69,4,FALSE)),F6) | I6: =IF(H6="","",E6*H6) | J6: =IF(OR(G6="",I6=""),"",G6-I6) | K6: تاريخ مصحح من 2026 إلى 2025
A7: 5 | B7: 45874 | C7: TNR-1867 | D7: احمر مطفى | E7: 70 | F7: 10 | G7: =IF(F7="","",E7*F7) | H7: =IFERROR(IF(VLOOKUP("حجر ديكوري احمر مطفي",'قائمة الأسعار الموحدة'!$B$3:$E$69,4,FALSE)="",F7,VLOOKUP("حجر ديكوري احمر مطفي",'قائمة الأسعار الموحدة'!$B$3:$E$69,4,FALSE)),F7) | I7: =IF(H7="","",E7*H7) | J7: =IF(OR(G7="",I7=""),"",G7-I7) | K7: تاريخ مصحح من 2026 إلى 2025
A8: 6 | B8: 45874 | C8: TNR-1867 | D8: اصفر مطفى | E8: 196 | F8: 10 | G8: =IF(F8="","",E8*F8) | H8: =IFERROR(IF(VLOOKUP("حجر ديكوري اصفر مطفي 1: 3",'قائمة الأسعار الموحدة'!$B$3:$E$69,4,FALSE)="",F8,VLOOKUP("حجر ديكوري اصفر مطفي 1: 3",'قائمة الأسعار الموحدة'!$B$3:$E$69,4,FALSE)),F8) | I8: =IF(H8="","",E8*H8) | J8: =IF(OR(G8="",I8=""),"",G8-I8) | K8: تاريخ مصحح من 2026 إلى 2025
A9: 7 | B9: 45969 | C9: TNR-2792 | D9: جهنمية بلدى واحد عود 50سم | E9: 300 | F9: 2.5 | G9: =IF(F9="","",E9*F9) | H9: =IFERROR(IF(VLOOKUP("جهنميه بلدي 50",'قائمة الأسعار الموحدة'!$B$3:$E$69,4,FALSE)="",F9,VLOOKUP("جهنميه بلدي 50",'قائمة الأسعار الموحدة'!$B$3:$E$69,4,FALSE)),F9) | I9: =IF(H9="","",E9*H9) | J9: =IF(OR(G9="",I9=""),"",G9-I9)
A10: 8 | B10: 45969 | C10: TNR-2792 | D10: وايتكس 50 سم | E10: 400 | F10: 2.5 | G10: =IF(F10="","",E10*F10) | H10: =IFERROR(IF(VLOOKUP("وايتكس 50",'قائمة الأسعار الموحدة'!$B$3:$E$69,4,FALSE)="",F10,VLOOKUP("وايتكس 50",'قائمة الأسعار الموحدة'!$B$3:$E$69,4,FALSE)),F10) | I10: =IF(H10="","",E10*H10) | J10: =IF(OR(G10="",I10=""),"",G10-I10)
A11: 9 | B11: 45969 | C11: TNR-2792 | D11: دورانتا اخضر | E11: 300 | F11: 2.5 | G11: =IF(F11="","",E11*F11) | H11: =IFERROR(IF(VLOOKUP("دورانتا اخضر",'قائمة الأسعار الموحدة'!$B$3:$E$69,4,FALSE)="",F11,VLOOKUP("دورانتا اخضر",'قائمة الأسعار الموحدة'!$B$3:$E$69,4,FALSE)),F11) | I11: =IF(H11="","",E11*H11) | J11: =IF(OR(G11="",I11=""),"",G11-I11)
A12: 10 | B12: 45969 | C12: TNR-2792 | D12: لانتانا لبناني صغير | E12: 100 | F12: 2.5 | G12: =IF(F12="","",E12*F12) | H12: =IFERROR(IF(VLOOKUP("لانتانا لبناني صغير",'قائمة الأسعار الموحدة'!$B$3:$E$69,4,FALSE)="",F12,VLOOKUP("لانتانا لبناني صغير",'قائمة الأسعار الموحدة'!$B$3:$E$69,4,FALSE)),F12) | I12: =IF(H12="","",E12*H12) | J12: =IF(OR(G12="",I12=""),"",G12-I12)
A13: 11 | B13: 45969 | C13: TNR-2792 | D13: رويليا | E13: 300 | F13: 2.5 | G13: =IF(F13="","",E13*F13) | H13: =IFERROR(IF(VLOOKUP("رويليا",'قائمة الأسعار الموحدة'!$B$3:$E$69,4,FALSE)="",F13,VLOOKUP("رويليا",'قائمة الأسعار الموحدة'!$B$3:$E$69,4,FALSE)),F13) | I13: =IF(H13="","",E13*H13) | J13: =IF(OR(G13="",I13=""),"",G13-I13)
A14: 12 | B14: 45981 | C14: TNR-2938 | D14: زهور بيتونيا | E14: 8850 | F14: 0.5 | G14: =IF(F14="","",E14*F14) | H14: =IFERROR(IF(VLOOKUP("بيتونيا",'قائمة الأسعار الموحدة'!$B$3:$E$69,4,FALSE)="",F14,VLOOKUP("بيتونيا",'قائمة الأسعار الموحدة'!$B$3:$E$69,4,FALSE)),F14) | I14: =IF(H14="","",E14*H14) | J14: =IF(OR(G14="",I14=""),"",G14-I14)
A15: 13 | B15: 45981 | C15: TNR-2938 | D15: زهور اليسوم | E15: 200 | F15: 0.5 | G15: =IF(F15="","",E15*F15) | H15: =IFERROR(IF(VLOOKUP("اليسوم",'قائمة الأسعار الموحدة'!$B$3:$E$69,4,FALSE)="",F15,VLOOKUP("اليسوم",'قائمة الأسعار الموحدة'!$B$3:$E$69,4,FALSE)),F15) | I15: =IF(H15="","",E15*H15) | J15: =IF(OR(G15="",I15=""),"",G15-I15)
A16: 14 | B16: 46002 | C16: TNR-3201 | D16: حجر ديكورى ابيض مطفى 3:5سم-10كجم | E16: 320 | F16: 10 | G16: =IF(F16="","",E16*F16) | H16: =IFERROR(IF(VLOOKUP("حجر ديكوري ابيض مطفي 3: 5",'قائمة الأسعار الموحدة'!$B$3:$E$69,4,FALSE)="",F16,VLOOKUP("حجر ديكوري ابيض مطفي 3: 5",'قائمة الأسعار الموحدة'!$B$3:$E$69,4,FALSE)),F16) | I16: =IF(H16="","",E16*H16) | J16: =IF(OR(G16="",I16=""),"",G16-I16)
A17: 15 | B17: 46025 | C17: اذن صرف 319 | D17: دورانتا اخضر | E17: 1200 | F17: 2.5 | G17: =IF(F17="","",E17*F17) | H17: =IFERROR(IF(VLOOKUP("دورانتا اخضر",'قائمة الأسعار الموحدة'!$B$3:$E$69,4,FALSE)="",F17,VLOOKUP("دورانتا اخضر",'قائمة الأسعار الموحدة'!$B$3:$E$69,4,FALSE)),F17) | I17: =IF(H17="","",E17*H17) | J17: =IF(OR(G17="",I17=""),"",G17-I17)
A18: 16 | B18: 46025 | C18: اذن صرف 319 | D18: تيكوماريا | E18: 740 | F18: 2.5 | G18: =IF(F18="","",E18*F18) | H18: =IFERROR(IF(VLOOKUP("تيكوماريا 50",'قائمة الأسعار الموحدة'!$B$3:$E$69,4,FALSE)="",F18,VLOOKUP("تيكوماريا 50",'قائمة الأسعار الموحدة'!$B$3:$E$69,4,FALSE)),F18) | I18: =IF(H18="","",E18*H18) | J18: =IF(OR(G18="",I18=""),"",G18-I18)
A19: 17 | B19: 46025 | C19: اذن صرف 319 | D19: اكاليفيا | E19: 60 | F19: 2.5 | G19: =IF(F19="","",E19*F19) | H19: =IFERROR(IF(VLOOKUP("اكاليفا",'قائمة الأسعار الموحدة'!$B$3:$E$69,4,FALSE)="",F19,VLOOKUP("اكاليفا",'قائمة الأسعار الموحدة'!$B$3:$E$69,4,FALSE)),F19) | I19: =IF(H19="","",E19*H19) | J19: =IF(OR(G19="",I19=""),"",G19-I19)
A20: 18 | B20: 46025 | C20: اذن صرف 319 | D20: حجر ديكورى ابيض مطفى 3:5سم-10كجم | E20: 200 | F20: 10 | G20: =IF(F20="","",E20*F20) | H20: =IFERROR(IF(VLOOKUP("حجر ديكوري ابيض مطفي 3: 5",'قائمة الأسعار الموحدة'!$B$3:$E$69,4,FALSE)="",F20,VLOOKUP("حجر ديكوري ابيض مطفي 3: 5",'قائمة الأسعار الموحدة'!$B$3:$E$69,4,FALSE)),F20) | I20: =IF(H20="","",E20*H20) | J20: =IF(OR(G20="",I20=""),"",G20-I20)
A21: 19 | C21: فرق PO الشجيرات | D21: جهنمية بلدى واحد عود 50سم | E21: 270 | F21: 2.5 | G21: =IF(F21="","",E21*F21) | H21: =IFERROR(IF(VLOOKUP("جهنميه بلدي 50",'قائمة الأسعار الموحدة'!$B$3:$E$69,4,FALSE)="",F21,VLOOKUP("جهنميه بلدي 50",'قائمة الأسعار الموحدة'!$B$3:$E$69,4,FALSE)),F21) | I21: =IF(H21="","",E21*H21) | J21: =IF(OR(G21="",I21=""),"",G21-I21) | K21: صافي ما باعته الرياض من براد الشجيرات
A22: 20 | C22: فرق PO الشجيرات | D22: دورانتا اخضر | E22: 10 | F22: 2.5 | G22: =IF(F22="","",E22*F22) | H22: =IFERROR(IF(VLOOKUP("دورانتا اخضر",'قائمة الأسعار الموحدة'!$B$3:$E$69,4,FALSE)="",F22,VLOOKUP("دورانتا اخضر",'قائمة الأسعار الموحدة'!$B$3:$E$69,4,FALSE)),F22) | I22: =IF(H22="","",E22*H22) | J22: =IF(OR(G22="",I22=""),"",G22-I22) | K22: صافي ما باعته الرياض من براد الشجيرات
A23: 21 | C23: فرق PO الشجيرات | D23: لانتانا لبناني صغير | E23: 60 | F23: 2.5 | G23: =IF(F23="","",E23*F23) | H23: =IFERROR(IF(VLOOKUP("لانتانا لبناني صغير",'قائمة الأسعار الموحدة'!$B$3:$E$69,4,FALSE)="",F23,VLOOKUP("لانتانا لبناني صغير",'قائمة الأسعار الموحدة'!$B$3:$E$69,4,FALSE)),F23) | I23: =IF(H23="","",E23*H23) | J23: =IF(OR(G23="",I23=""),"",G23-I23) | K23: صافي ما باعته الرياض من براد الشجيرات
A24: 22 | C24: فرق PO الشجيرات | D24: رويليا | E24: 206 | F24: 2.5 | G24: =IF(F24="","",E24*F24) | H24: =IFERROR(IF(VLOOKUP("رويليا",'قائمة الأسعار الموحدة'!$B$3:$E$69,4,FALSE)="",F24,VLOOKUP("رويليا",'قائمة الأسعار الموحدة'!$B$3:$E$69,4,FALSE)),F24) | I24: =IF(H24="","",E24*H24) | J24: =IF(OR(G24="",I24=""),"",G24-I24) | K24: صافي ما باعته الرياض من براد الشجيرات
A25: 23 | C25: فرق PO الشجيرات | D25: تيكوماريا | E25: 72 | F25: 2.5 | G25: =IF(F25="","",E25*F25) | H25: =IFERROR(IF(VLOOKUP("تيكوماريا 50",'قائمة الأسعار الموحدة'!$B$3:$E$69,4,FALSE)="",F25,VLOOKUP("تيكوماريا 50",'قائمة الأسعار الموحدة'!$B$3:$E$69,4,FALSE)),F25) | I25: =IF(H25="","",E25*H25) | J25: =IF(OR(G25="",I25=""),"",G25-I25) | K25: صافي ما باعته الرياض من براد الشجيرات
A26: 24 | C26: فرق PO الشجيرات | D26: فل بلدى | E26: 50 | F26: 2.5 | G26: =IF(F26="","",E26*F26) | H26: =IFERROR(IF(VLOOKUP("فل بلدي",'قائمة الأسعار الموحدة'!$B$3:$E$69,4,FALSE)="",F26,VLOOKUP("فل بلدي",'قائمة الأسعار الموحدة'!$B$3:$E$69,4,FALSE)),F26) | I26: =IF(H26="","",E26*H26) | J26: =IF(OR(G26="",I26=""),"",G26-I26) | K26: صافي ما باعته الرياض من براد الشجيرات
A27: 25 | C27: فرق PO الشجيرات | D27: ياسمين ازرق 50 سم | E27: 150 | F27: 2.5 | G27: =IF(F27="","",E27*F27) | H27: =IFERROR(IF(VLOOKUP("ياسمين ازرق",'قائمة الأسعار الموحدة'!$B$3:$E$69,4,FALSE)="",F27,VLOOKUP("ياسمين ازرق",'قائمة الأسعار الموحدة'!$B$3:$E$69,4,FALSE)),F27) | I27: =IF(H27="","",E27*H27) | J27: =IF(OR(G27="",I27=""),"",G27-I27) | K27: صافي ما باعته الرياض من براد الشجيرات
A28: 26 | B28: 46231 | C28: TRF-0188 | D28: بيرلايت 100 لتر | E28: 25 | F28: 32.5 | G28: =IF(F28="","",E28*F28) | H28: =IFERROR(IF(VLOOKUP("بيرلايت 100 لتر",'قائمة الأسعار الموحدة'!$B$3:$E$69,4,FALSE)="",F28,VLOOKUP("بيرلايت 100 لتر",'قائمة الأسعار الموحدة'!$B$3:$E$69,4,FALSE)),F28) | I28: =IF(H28="","",E28*H28) | J28: =IF(OR(G28="",I28=""),"",G28-I28) | K28: سند بالنظام لم يدرجه المحاسب – أُضيف
A29: 27 | B29: 45976 | C29: TNR-2689 / TNR-2888 | D29: زهور بيتونيا | E29: 69625 | F29: 0.5 | G29: =IF(F29="","",E29*F29) | H29: =IFERROR(IF(VLOOKUP("بيتونيا",'قائمة الأسعار الموحدة'!$B$3:$E$69,4,FALSE)="",F29,VLOOKUP("بيتونيا",'قائمة الأسعار الموحدة'!$B$3:$E$69,4,FALSE)),F29) | I29: =IF(H29="","",E29*H29) | J29: =IF(OR(G29="",I29=""),"",G29-I29) | K29: بيتونيا عقد عرعر المحوّلة من تبوك (72,625 − 3,000 تالف)
D30: الإجمالي | E30: =SUM(E3:E29) | G30: =SUM(G3:G29) | I30: =SUM(I3:I29) | J30: =SUM(J3:J29)

Sheet مسحوبات نسما قبل الفترة
A1: مسحوبات تبوك من الرياض قبل 30-7-2025 (أوامر P00480–P00523) بالسعر الموحد = مديونية على أبو مازن
A2: م | B2: التاريخ | C2: السند | D2: الصنف | E2: الكمية | F2: السعر المسجل | G2: الإجمالي المسجل | H2: السعر الموحد | I2: الإجمالي الموحد | J2: الفرق (المسجل − الموحد) | K2: ملاحظة
A3: 1 | B3: 45845 | C3: P00480 | D3: فينكا أبيض نقطة حمراء | E3: 3875 | G3: =IF(F3="","",E3*F3) | H3: =IFERROR(IF(VLOOKUP("فينكا ابيض نقطه حمراء",'قائمة الأسعار الموحدة'!$B$3:$E$69,4,FALSE)="",F3,VLOOKUP("فينكا ابيض نقطه حمراء",'قائمة الأسعار الموحدة'!$B$3:$E$69,4,FALSE)),F3) | I3: =IF(H3="","",E3*H3) | J3: =IF(OR(G3="",I3=""),"",G3-I3) | K3: شحن خارجي تحمّلته نسما 1,400 ريال – لا يُحمّل على أي طرف
A4: 2 | B4: 45845 | C4: P00480 | D4: فينكا أحمر بنقطة | E4: 3000 | G4: =IF(F4="","",E4*F4) | H4: =IFERROR(IF(VLOOKUP("فينكا احمر بنقطه",'قائمة الأسعار الموحدة'!$B$3:$E$69,4,FALSE)="",F4,VLOOKUP("فينكا احمر بنقطه",'قائمة الأسعار الموحدة'!$B$3:$E$69,4,FALSE)),F4) | I4: =IF(H4="","",E4*H4) | J4: =IF(OR(G4="",I4=""),"",G4-I4) | K4: شحن خارجي تحمّلته نسما 1,400 ريال – لا يُحمّل على أي طرف
A5: 3 | B5: 45845 | C5: P00481 | D5: فينكا أحمر | E5: 5000 | G5: =IF(F5="","",E5*F5) | H5: =IFERROR(IF(VLOOKUP("فينكا احمر",'قائمة الأسعار الموحدة'!$B$3:$E$69,4,FALSE)="",F5,VLOOKUP("فينكا احمر",'قائمة الأسعار الموحدة'!$B$3:$E$69,4,FALSE)),F5) | I5: =IF(H5="","",E5*H5) | J5: =IF(OR(G5="",I5=""),"",G5-I5) | K5: شحن خارجي تحمّلته نسما 1,400 ريال – لا يُحمّل على أي طرف
A6: 4 | B6: 45845 | C6: P00481 | D6: فينكا أزرق | E6: 5000 | G6: =IF(F6="","",E6*F6) | H6: =IFERROR(IF(VLOOKUP("فينكا ازرق",'قائمة الأسعار الموحدة'!$B$3:$E$69,4,FALSE)="",F6,VLOOKUP("فينكا ازرق",'قائمة الأسعار الموحدة'!$B$3:$E$69,4,FALSE)),F6) | I6: =IF(H6="","",E6*H6) | J6: =IF(OR(G6="",I6=""),"",G6-I6) | K6: شحن خارجي تحمّلته نسما 1,400 ريال – لا يُحمّل على أي طرف
A7: 5 | B7: 45845 | C7: P00481 | D7: فينكا أبيض | E7: 3000 | G7: =IF(F7="","",E7*F7) | H7: =IFERROR(IF(VLOOKUP("فينكا ابيض",'قائمة الأسعار الموحدة'!$B$3:$E$69,4,FALSE)="",F7,VLOOKUP("فينكا ابيض",'قائمة الأسعار الموحدة'!$B$3:$E$69,4,FALSE)),F7) | I7: =IF(H7="","",E7*H7) | J7: =IF(OR(G7="",I7=""),"",G7-I7) | K7: شحن خارجي تحمّلته نسما 1,400 ريال – لا يُحمّل على أي طرف
A8: 6 | B8: 45845 | C8: P00481 | D8: فينكا مشمشي | E8: 5000 | G8: =IF(F8="","",E8*F8) | H8: =IFERROR(IF(VLOOKUP("فينكا مشمشي",'قائمة الأسعار الموحدة'!$B$3:$E$69,4,FALSE)="",F8,VLOOKUP("فينكا مشمشي",'قائمة الأسعار الموحدة'!$B$3:$E$69,4,FALSE)),F8) | I8: =IF(H8="","",E8*H8) | J8: =IF(OR(G8="",I8=""),"",G8-I8) | K8: شحن خارجي تحمّلته نسما 1,400 ريال – لا يُحمّل على أي طرف
A9: 7 | B9: 45854 | C9: P00508 | D9: فينكا أحمر | E9: 6000 | G9: =IF(F9="","",E9*F9) | H9: =IFERROR(IF(VLOOKUP("فينكا احمر",'قائمة الأسعار الموحدة'!$B$3:$E$69,4,FALSE)="",F9,VLOOKUP("فينكا احمر",'قائمة الأسعار الموحدة'!$B$3:$E$69,4,FALSE)),F9) | I9: =IF(H9="","",E9*H9) | J9: =IF(OR(G9="",I9=""),"",G9-I9) | K9: شحن خارجي تحمّلته نسما 1,700 ريال – لا يُحمّل على أي طرف
A10: 8 | B10: 45854 | C10: P00508 | D10: فينكا أبيض | E10: 6000 | G10: =IF(F10="","",E10*F10) | H10: =IFERROR(IF(VLOOKUP("فينكا ابيض",'قائمة الأسعار الموحدة'!$B$3:$E$69,4,FALSE)="",F10,VLOOKUP("فينكا ابيض",'قائمة الأسعار الموحدة'!$B$3:$E$69,4,FALSE)),F10) | I10: =IF(H10="","",E10*H10) | J10: =IF(OR(G10="",I10=""),"",G10-I10) | K10: شحن خارجي تحمّلته نسما 1,700 ريال – لا يُحمّل على أي طرف
A11: 9 | B11: 45856 | C11: P00519 | D11: زهور موسمية (SEASONAL FLOWERS) | E11: 42000 | G11: =IF(F11="","",E11*F11) | H11: =IFERROR(IF(VLOOKUP("موسميه",'قائمة الأسعار الموحدة'!$B$3:$E$69,4,FALSE)="",F11,VLOOKUP("موسميه",'قائمة الأسعار الموحدة'!$B$3:$E$69,4,FALSE)),F11) | I11: =IF(H11="","",E11*H11) | J11: =IF(OR(G11="",I11=""),"",G11-I11) | K11: شحن خارجي تحمّلته نسما 3,800 ريال – لا يُحمّل على أي طرف
A12: 10 | B12: 45856 | C12: P00522 | D12: زهور موسمية – غير شامل التوصيل | E12: 15000 | G12: =IF(F12="","",E12*F12) | H12: =IFERROR(IF(VLOOKUP("موسميه",'قائمة الأسعار الموحدة'!$B$3:$E$69,4,FALSE)="",F12,VLOOKUP("موسميه",'قائمة الأسعار الموحدة'!$B$3:$E$69,4,FALSE)),F12) | I12: =IF(H12="","",E12*H12) | J12: =IF(OR(G12="",I12=""),"",G12-I12) | K12: شحن خارجي تحمّلته نسما 3,000 ريال – لا يُحمّل على أي طرف
A13: 11 | B13: 45856 | C13: P00523 | D13: زهور موسمية (SEASONAL FLOWERS) | E13: 9000 | G13: =IF(F13="","",E13*F13) | H13: =IFERROR(IF(VLOOKUP("موسميه",'قائمة الأسعار الموحدة'!$B$3:$E$69,4,FALSE)="",F13,VLOOKUP("موسميه",'قائمة الأسعار الموحدة'!$B$3:$E$69,4,FALSE)),F13) | I13: =IF(H13="","",E13*H13) | J13: =IF(OR(G13="",I13=""),"",G13-I13) | K13: البراد على جرين تاون – الحمولة 15,000 وقُبل 9,000
D14: الإجمالي | E14: =SUM(E3:E13) | G14: =SUM(G3:G13) | I14: =SUM(I3:I13) | J14: =SUM(J3:J13)

Sheet سندات بدون تفصيل أصناف
A1: سندات مسحوبات/ترحيل بالنظام بدون تفصيل أصناف – لا يمكن إعادة تسعيرها إلا بإدخال الأصناف
A2: م | B2: الاتجاه | C2: السند | D2: التاريخ | E2: الجهة | F2: القيمة بالنظام (شاملة الضريبة) | G2: القيمة المعتمدة (يدوي) | H2: ملاحظة
A3: 1 | B3: الرياض ← تبوك (على أبو مازن) | C3: RNT-2166 | D3: 45887 | E3: TRANSACTIONS BETWEEN RIYADH-TABUK | F3: 7475 | H3: غير مدرج بشيت المحاسب – أرسل الأصناف أو اعتمد القيمة
A4: 2 | B4: الرياض ← تبوك (على أبو مازن) | C4: RNT-2141 | D4: 45909 | E4: TRANSACTIONS BETWEEN RIYADH-TABUK | F4: 8855 | H4: غير مدرج بشيت المحاسب – أرسل الأصناف أو اعتمد القيمة
A5: 3 | B5: الرياض ← تبوك (على أبو مازن) | C5: RNT-3077 | D5: 45992 | E5: TRANSACTIONS BETWEEN RIYADH-TABUK | F5: 4305.03 | H5: غير مدرج بشيت المحاسب – أرسل الأصناف أو اعتمد القيمة
A6: 4 | B6: الرياض ← تبوك (على أبو مازن) | C6: RNT-3346 | D6: 46016 | E6: TRANSACTIONS BETWEEN RIYADH-TABUK | F6: 1765.25 | H6: غير مدرج بشيت المحاسب – أرسل الأصناف أو اعتمد القيمة
A7: 5 | B7: الرياض ← تبوك (على أبو مازن) | C7: RNP-2297 | D7: 45926 | E7: NESMA ELSHARQ-PROJECTS | F7: 5433.75 | H7: غير مدرج بشيت المحاسب – أرسل الأصناف أو اعتمد القيمة
A8: 6 | B8: الرياض ← تبوك (على أبو مازن) | C8: RNP-2427 | D8: 45938 | E8: NESMA ELSHARQ-PROJECTS | F8: 7078.25 | H8: غير مدرج بشيت المحاسب – أرسل الأصناف أو اعتمد القيمة
A9: 7 | B9: الرياض ← تبوك (على أبو مازن) | C9: RNP-1787 | D9: 45873 | E9: WHOLESALE DEPARTMENT RIYADH | F9: 20872.5 | H9: غير مدرج بشيت المحاسب – أرسل الأصناف أو اعتمد القيمة
E10: الإجمالي | F10: =SUM(F3:F9) | G10: =SUM(G3:G9)
