Workbook

Sheet الملخص
A1: ملخص حركات المواد – مزرعة الرياض
A2: الفترة الكاملة: من 30-7-2025 إلى 31-7-2026 – سجل الحركات (النظام القديم) + النظام الجديد (يونيو–يوليو 2026) بعد المراجعة مع السندات وملف التفصيل.
A4: الرمز | B4: نوع الحركة | C4: عدد – النظام القديم | D4: قيمة النظام القديم | E4: عدد – النظام الجديد | F4: قيمة النظام الجديد | G4: إجمالي العدد | H4: الإجمالي للفترة | I4: عقود بتفصيل بنود | J4: قيمة العقود المفصّلة
A5: TNR | B5: ترحيل من تبوك إلى الرياض | C5: =COUNTIFS('سجل العقود'!B2:B255,"TNR",'سجل العقود'!I2:I255,"النظام القديم",'سجل العقود'!J2:J255,"نعم") | D5: =SUMIFS('سجل العقود'!H2:H255,'سجل العقود'!B2:B255,"TNR",'سجل العقود'!I2:I255,"النظام القديم",'سجل العقود'!J2:J255,"نعم") | E5: =COUNTIFS('سجل العقود'!B2:B255,"TNR",'سجل العقود'!I2:I255,"النظام الجديد",'سجل العقود'!J2:J255,"نعم") | F5: =SUMIFS('سجل العقود'!H2:H255,'سجل العقود'!B2:B255,"TNR",'سجل العقود'!I2:I255,"النظام الجديد",'سجل العقود'!J2:J255,"نعم") | G5: =C5+E5 | H5: =D5+F5 | I5: 3 | J5: 16660.63
A6: RNT | B6: ترحيل من الرياض إلى تبوك | C6: =COUNTIFS('سجل العقود'!B2:B255,"RNT",'سجل العقود'!I2:I255,"النظام القديم",'سجل العقود'!J2:J255,"نعم") | D6: =SUMIFS('سجل العقود'!H2:H255,'سجل العقود'!B2:B255,"RNT",'سجل العقود'!I2:I255,"النظام القديم",'سجل العقود'!J2:J255,"نعم") | E6: =COUNTIFS('سجل العقود'!B2:B255,"RNT",'سجل العقود'!I2:I255,"النظام الجديد",'سجل العقود'!J2:J255,"نعم") | F6: =SUMIFS('سجل العقود'!H2:H255,'سجل العقود'!B2:B255,"RNT",'سجل العقود'!I2:I255,"النظام الجديد",'سجل العقود'!J2:J255,"نعم") | G6: =C6+E6 | H6: =D6+F6 | I6: 5 | J6: 46750.38
A7: RNP | B7: ترحيل إلى قسم المشاريع تبوك | C7: =COUNTIFS('سجل العقود'!B2:B255,"RNP",'سجل العقود'!I2:I255,"النظام القديم",'سجل العقود'!J2:J255,"نعم") | D7: =SUMIFS('سجل العقود'!H2:H255,'سجل العقود'!B2:B255,"RNP",'سجل العقود'!I2:I255,"النظام القديم",'سجل العقود'!J2:J255,"نعم") | E7: =COUNTIFS('سجل العقود'!B2:B255,"RNP",'سجل العقود'!I2:I255,"النظام الجديد",'سجل العقود'!J2:J255,"نعم") | F7: =SUMIFS('سجل العقود'!H2:H255,'سجل العقود'!B2:B255,"RNP",'سجل العقود'!I2:I255,"النظام الجديد",'سجل العقود'!J2:J255,"نعم") | G7: =C7+E7 | H7: =D7+F7 | I7: 25 | J7: 139835.86
A8: RNO | B8: صرف مواد للإنتاج – مزرعة الرياض | C8: =COUNTIFS('سجل العقود'!B2:B255,"RNO",'سجل العقود'!I2:I255,"النظام القديم",'سجل العقود'!J2:J255,"نعم") | D8: =SUMIFS('سجل العقود'!H2:H255,'سجل العقود'!B2:B255,"RNO",'سجل العقود'!I2:I255,"النظام القديم",'سجل العقود'!J2:J255,"نعم") | E8: =COUNTIFS('سجل العقود'!B2:B255,"RNO",'سجل العقود'!I2:I255,"النظام الجديد",'سجل العقود'!J2:J255,"نعم") | F8: =SUMIFS('سجل العقود'!H2:H255,'سجل العقود'!B2:B255,"RNO",'سجل العقود'!I2:I255,"النظام الجديد",'سجل العقود'!J2:J255,"نعم") | G8: =C8+E8 | H8: =D8+F8 | I8: 37 | J8: 169491.16
A9: RNL | B9: كميات هالكة ومفقودة | C9: =COUNTIFS('سجل العقود'!B2:B255,"RNL",'سجل العقود'!I2:I255,"النظام القديم",'سجل العقود'!J2:J255,"نعم") | D9: =SUMIFS('سجل العقود'!H2:H255,'سجل العقود'!B2:B255,"RNL",'سجل العقود'!I2:I255,"النظام القديم",'سجل العقود'!J2:J255,"نعم") | E9: =COUNTIFS('سجل العقود'!B2:B255,"RNL",'سجل العقود'!I2:I255,"النظام الجديد",'سجل العقود'!J2:J255,"نعم") | F9: =SUMIFS('سجل العقود'!H2:H255,'سجل العقود'!B2:B255,"RNL",'سجل العقود'!I2:I255,"النظام الجديد",'سجل العقود'!J2:J255,"نعم") | G9: =C9+E9 | H9: =D9+F9 | I9: 20 | J9: 42103.69
B10: الإجمالي | C10: =SUM(C5:C9) | D10: =SUM(D5:D9) | E10: =SUM(E5:E9) | F10: =SUM(F5:F9) | G10: =SUM(G5:G9) | H10: =SUM(H5:H9) | I10: =SUM(I5:I9) | J10: =SUM(J5:J9)
A12: ملاحظات المراجعة:
A13: 1) مراجعة السندات: ملف تفصيل النظام الجديد فيه 50 سنداً. سندات الصرف للإنتاج RNO (20) والهالك RNL (12) مطابقة تماماً للأرشيف في العدد والقيمة وعدد البنود.
A14: 2) ⚠ ترحيلات المشاريع RNP في الأرشيف كانت سندين فقط، بينما ملف التفصيل فيه 18 سنداً – أُضيف 17 سنداً ناقصاً بقيمة 75,138.00 (من ISV-0004 إلى ISV-0128). السند ISV-0075 (4-7-2026 بقيمة 2,750) موجود بالأرشيف فقط بدون تفصيل.
A15: 3) ⚠ مرجع الطلب NS-REQ-008 مستخدم في سندين: ISV-0011 (14-6 بقيمة 1,100) و ISV-0016 (17-6 بقيمة 825) – يلزم التأكد أنهما صرفان مختلفان.
A16: 4) ⚠ سندات التحويل TRF: قيم الأرشيف تختلف عن السندات الأصلية، وتم اعتماد السند: TRF-0107 (أرشيف 32,149.00 / سند 28,146.25)، TRF-0122 (7,080.00 / 7,038.00)، TRF-0120 (7,375.00 / 7,331.25)، TRF-0188 (937.50 / 934.38).
A17: 5) صنف سيسبانيا OD373: خرج 250 من الرياض لتبوك (TRF-0107 في 11-7)، ثم رجع 250 من تبوك للرياض (TRF-0120 في 14-7 الساعة 9:35)، ثم خرج 240 مرة أخرى لتبوك (TRF-0122 في 14-7 الساعة 9:52) مع مرتجع 10 حبات مكسورة. الصافي المحوّل لتبوك 240 حبة – يلزم التأكد أن التحويل الأول لم يُلغَ.
A18: 6) السند TRF-0107 تاريخه على السند 2026-11-07 وهو 11-7-2026 (مقلوب).
A19: 7) سجل الحركات (النظام القديم) ينتهي عند 22-2-2026 والنظام الجديد يبدأ 13-6-2026 – لا توجد حركات من 23-2-2026 إلى 12-6-2026.
A20: 8) العقد RNO-3832 (13-2-2026): مجموع البنود 5,274.48 وإجمالي العقد 5,550.48 – فرق 276.00.
A21: 9) رقم العقد RNP-1787 مكرر لحركتين (25-7-2025 بقيمة 18,975 قبل الفترة، و 4-8-2025 بقيمة 20,872.50). وحركات قبل 30-7-2025 غير محسوبة (بالرمادي).
A22: 10) السند ISV-0061 حالته مرتجع جزئي ولا يوضح النظام الكمية المرتجعة.

Sheet سجل العقود
A1: م | B1: نوع الحركة | C1: البيان | D1: رقم العقد / السند | E1: التاريخ | F1: الجهة / المرجع | G1: عدد البنود | H1: القيمة | I1: المصدر | J1: محسوب بالفترة | K1: ملاحظة
A2: 1 | B2: TNR | C2: ترحيل من تبوك إلى الرياض | D2: TNR-1867 | E2: 45874 | F2: TRANSACTIONS BETWEEN RIYADH -TABUK NURSERY | H2: 12165.28 | I2: النظام القديم | J2: نعم | K2: بدون تفصيل بنود في السجل
A3: 2 | B3: TNR | C3: ترحيل من تبوك إلى الرياض | D3: TNR-2689 | E3: 45959 | F3: WHOLESALE DEPARTMENT TABUK NURSERY | H3: 22137.5 | I3: النظام القديم | J3: نعم | K3: بدون تفصيل بنود في السجل
A4: 3 | B4: TNR | C4: ترحيل من تبوك إلى الرياض | D4: TNR-2792 | E4: 45967 | F4: TRANSACTIONS BETWEEN RIYADH -TABUK NURSERY | H4: 6828.13 | I4: النظام القديم | J4: نعم | K4: بدون تفصيل بنود في السجل
A5: 4 | B5: TNR | C5: ترحيل من تبوك إلى الرياض | D5: TNR-2888 | E5: 45976 | F5: WHOLESALE DEPARTMENT TABUK NURSERY | H5: 23797.81 | I5: النظام القديم | J5: نعم | K5: بدون تفصيل بنود في السجل
A6: 5 | B6: TNR | C6: ترحيل من تبوك إلى الرياض | D6: TNR-2938 | E6: 45980 | F6: TRANSACTIONS BETWEEN RIYADH -TABUK NURSERY | H6: 5724.13 | I6: النظام القديم | J6: نعم | K6: بدون تفصيل بنود في السجل
A7: 6 | B7: TNR | C7: ترحيل من تبوك إلى الرياض | D7: TNR-3201 | E7: 46001 | F7: TRANSACTIONS BETWEEN RIYADH -TABUK NURSERY | H7: 4232 | I7: النظام القديم | J7: نعم | K7: بدون تفصيل بنود في السجل
A8: 7 | B8: TNR | C8: ترحيل من تبوك إلى الرياض | D8: TNR-3441 | E8: 46023 | F8: TRANSACTIONS BETWEEN RIYADH - TABUK NURSERY | G8: 4 | H8: 8395 | I8: النظام القديم | J8: نعم
A9: 8 | B9: TNR | C9: ترحيل من تبوك إلى الرياض | D9: TRF-0120 | E9: 46217 | F9: تبوك ← الرياض | G9: 1 | H9: 7331.25 | I9: النظام الجديد | J9: نعم | K9: قيمة السند (PDF): 7,331.25 = 6,375.00 + ضريبة 15% | ملاحظة السند: تحويل مزرعة الرياض | ⚠ قيمة الأرشيف 7,375.00 تختلف عن السند 7,331.25 (فرق 43.75) – تم اعتماد السند
A10: 9 | B10: TNR | C10: ترحيل من تبوك إلى الرياض | D10: TRF-0188 | E10: 46231 | F10: تبوك ← الرياض | G10: 1 | H10: 934.38 | I10: النظام الجديد | J10: نعم | K10: قيمة السند (PDF): 934.38 = 812.50 + ضريبة 15% | ملاحظة السند: تحويل إلى مزرعة الرياض | ⚠ قيمة الأرشيف 937.50 تختلف عن السند 934.38 (فرق 3.12) – تم اعتماد السند
A11: 10 | B11: RNT | C11: ترحيل من الرياض إلى تبوك | D11: RNT-1789 | E11: 45863 | F11: TRANSACTIONS BETWEEN RIYADH -TABUK NURSERY | H11: 5483.2 | I11: النظام القديم | J11: لا | K11: قبل بداية الفترة 30-7-2025 – غير محسوب | بدون تفصيل بنود في السجل
A12: 11 | B12: RNT | C12: ترحيل من الرياض إلى تبوك | D12: RNT-2166 | E12: 45887 | F12: TRANSACTIONS BETWEEN RIYADH -TABUK NURSERY | H12: 7475 | I12: النظام القديم | J12: نعم | K12: بدون تفصيل بنود في السجل
A13: 12 | B13: RNT | C13: ترحيل من الرياض إلى تبوك | D13: RNT-2141 | E13: 45909 | F13: TRANSACTIONS BETWEEN RIYADH -TABUK NURSERY | H13: 8855 | I13: النظام القديم | J13: نعم | K13: بدون تفصيل بنود في السجل
A14: 13 | B14: RNT | C14: ترحيل من الرياض إلى تبوك | D14: RNT-2395 | E14: 45938 | F14: TRANSACTIONS BETWEEN RIYADH -TABUK NURSERY | H14: 34535.65 | I14: النظام القديم | J14: نعم | K14: بدون تفصيل بنود في السجل
A15: 14 | B15: RNT | C15: ترحيل من الرياض إلى تبوك | D15: RNT-3077 | E15: 45992 | F15: TRANSACTIONS BETWEEN RIYADH -TABUK NURSERY | H15: 4305.03 | I15: النظام القديم | J15: نعم | K15: بدون تفصيل بنود في السجل
A16: 15 | B16: RNT | C16: ترحيل من الرياض إلى تبوك | D16: RNT-3346 | E16: 46016 | F16: TRANSACTIONS BETWEEN RIYADH -TABUK NURSERY | H16: 1765.25 | I16: النظام القديم | J16: نعم | K16: بدون تفصيل بنود في السجل
A17: 16 | B17: RNT | C17: ترحيل من الرياض إلى تبوك | D17: RNT-3434 | E17: 46026 | F17: TRANSACTIONS BETWEEN RIYADH - TABUK NURSERY | G17: 1 | H17: 1380 | I17: النظام القديم | J17: نعم
A18: 17 | B18: RNT | C18: ترحيل من الرياض إلى تبوك | D18: RNT-3604 | E18: 46042 | F18: TRANSACTIONS BETWEEN RIYADH - TABUK NURSERY | G18: 3 | H18: 8504.25 | I18: النظام القديم | J18: نعم
A19: 18 | B19: RNT | C19: ترحيل من الرياض إلى تبوك | D19: RNT-3805 | E19: 46064 | F19: TRANSACTIONS BETWEEN RIYADH - TABUK NURSERY | G19: 6 | H19: 1681.88 | I19: النظام القديم | J19: نعم
A20: 19 | B20: RNT | C20: ترحيل من الرياض إلى تبوك | D20: TRF-0107 | E20: 46214 | F20: الرياض ← تبوك (Order 205) | G20: 9 | H20: 28146.25 | I20: النظام الجديد | J20: نعم | K20: قيمة السند (PDF): 28,146.25 = 24,475.00 + ضريبة 15% | ملاحظة السند: تحويل الشجيرات من الرياض إلى تبوك | ⚠ قيمة الأرشيف 32,149.00 تختلف عن السند 28,146.25 (فرق 4,002.75) – تم اعتماد السند
A21: 20 | B21: RNT | C21: ترحيل من الرياض إلى تبوك | D21: TRF-0122 | E21: 46217 | F21: الرياض ← تبوك (Order 2035) | G21: 1 | H21: 7038 | I21: النظام الجديد | J21: نعم | K21: قيمة السند (PDF): 7,038.00 = 6,120.00 + ضريبة 15% | ملاحظة السند: تحويل سيسبانيا لتبوك عدد 250 وعمل مرتجع 10 حبة مكسور | ⚠ قيمة الأرشيف 7,080.00 تختلف عن السند 7,038.00 (فرق 42.00) – تم اعتماد السند
A22: 21 | B22: RNP | C22: ترحيل إلى قسم المشاريع تبوك | D22: RNP-1787 | E22: 45863 | F22: NESMA ELSHARQ COMPANY-PROJECTS | H22: 18975 | I22: النظام القديم | J22: لا | K22: رقم العقد مكرر لحركتين مختلفتين | قبل بداية الفترة 30-7-2025 – غير محسوب | بدون تفصيل بنود في السجل
A23: 22 | B23: RNP | C23: ترحيل إلى قسم المشاريع تبوك | D23: RNP-1787 | E23: 45873 | F23: WHOLESALE DEPARTMENT RIYADH NURSERY | H23: 20872.5 | I23: النظام القديم | J23: نعم | K23: رقم العقد مكرر لحركتين مختلفتين | بدون تفصيل بنود في السجل
A24: 23 | B24: RNP | C24: ترحيل إلى قسم المشاريع تبوك | D24: RNP-2113 | E24: 45906 | F24: NESMA ELSHARQ COMPANY-PROJECTS | H24: 6325 | I24: النظام القديم | J24: نعم | K24: بدون تفصيل بنود في السجل
A25: 24 | B25: RNP | C25: ترحيل إلى قسم المشاريع تبوك | D25: RNP-2293 | E25: 45926 | F25: NESMA ELSHARQ COMPANY-PROJECTS | H25: 25300 | I25: النظام القديم | J25: نعم | K25: بدون تفصيل بنود في السجل
A26: 25 | B26: RNP | C26: ترحيل إلى قسم المشاريع تبوك | D26: RNP-2297 | E26: 45926 | F26: NESMA ELSHARQ COMPANY-PROJECTS | H26: 5433.75 | I26: النظام القديم | J26: نعم | K26: بدون تفصيل بنود في السجل
A27: 26 | B27: RNP | C27: ترحيل إلى قسم المشاريع تبوك | D27: RNP-2367 | E27: 45935 | F27: NESMA ELSHARQ COMPANY-PROJECTS | H27: 13.8 | I27: النظام القديم | J27: نعم | K27: بدون تفصيل بنود في السجل
A28: 27 | B28: RNP | C28: ترحيل إلى قسم المشاريع تبوك | D28: RNP-2427 | E28: 45938 | F28: NESMA ELSHARQ COMPANY-PROJECTS | H28: 7078.25 | I28: النظام القديم | J28: نعم | K28: بدون تفصيل بنود في السجل
A29: 28 | B29: RNP | C29: ترحيل إلى قسم المشاريع تبوك | D29: RNP-2512 | E29: 45947 | F29: NESMA ELSHARQ COMPANY-PROJECTS | H29: 3565 | I29: النظام القديم | J29: نعم | K29: بدون تفصيل بنود في السجل
A30: 29 | B30: RNP | C30: ترحيل إلى قسم المشاريع تبوك | D30: RNP-2608 | E30: 45954 | F30: NESMA ELSHARQ COMPANY-PROJECTS | H30: 12650 | I30: النظام القديم | J30: نعم | K30: بدون تفصيل بنود في السجل
A31: 30 | B31: RNP | C31: ترحيل إلى قسم المشاريع تبوك | D31: RNP-2704 | E31: 45962 | F31: NESMA ELSHARQ COMPANY-PROJECTS | H31: 2443.75 | I31: النظام القديم | J31: نعم | K31: بدون تفصيل بنود في السجل
A32: 31 | B32: RNP | C32: ترحيل إلى قسم المشاريع تبوك | D32: RNP-2748 | E32: 45964 | F32: NESMA ELSHARQ COMPANY-PROJECTS | H32: 646.88 | I32: النظام القديم | J32: نعم | K32: بدون تفصيل بنود في السجل
A33: 32 | B33: RNP | C33: ترحيل إلى قسم المشاريع تبوك | D33: RNP-2805 | E33: 45969 | F33: NESMA ELSHARQ COMPANY-PROJECTS | H33: 31740 | I33: النظام القديم | J33: نعم | K33: بدون تفصيل بنود في السجل
... A36: 35 | B36: RNP | C36: ترحيل إلى قسم المشاريع تبوك | D36: RNP-3276 | E36: 46011 | F36: NESMA ELSHARQ COMPANY-PROJECTS | H36: 5180.46 | I36: النظام القديم | J36: نعم | K36: بدون تفصيل بنود في السجل
A37: 36 | B37: RNP | C37: ترحيل إلى قسم المشاريع تبوك | D37: RNP-3432 | E37: 46026 | F37: NESMA ELSHARQ COMPANY- PROJECTS | G37: 2 | H37: 42435 | I37: النظام القديم | J37: نعم
A38: 37 | B38: RNP | C38: ترحيل إلى قسم المشاريع تبوك | D38: RNP-3433 | E38: 46026 | F38: NESMA ELSHARQ COMPANY- PROJECTS | G38: 4 | H38: 3760.5 | I38: النظام القديم | J38: نعم
A39: 38 | B39: RNP | C39: ترحيل إلى قسم المشاريع تبوك | D39: RNP-3491 | E39: 46029 | F39: NESMA ELSHARQ COMPANY- PROJECTS | G39: 3 | H39: 5284.25 | I39: النظام القديم | J39: نعم
A40: 39 | B40: RNP | C40: ترحيل إلى قسم المشاريع تبوك | D40: RNP-3520 | E40: 46033 | F40: NESMA ELSHARQ COMPANY- PROJECTS | G40: 1 | H40: 3795 | I40: النظام القديم | J40: نعم
A41: 40 | B41: RNP | C41: ترحيل إلى قسم المشاريع تبوك | D41: RNP-3586 | E41: 46039 | F41: NESMA ELSHARQ COMPANY-PROJECTS | H41: 97.75 | I41: النظام القديم | J41: نعم | K41: بدون تفصيل بنود في السجل
A42: 41 | B42: RNP | C42: ترحيل إلى قسم المشاريع تبوك | D42: RNP-3613 | E42: 46042 | F42: NESMA ELSHARQ COMPANY-PROJECTS | H42: 2708.25 | I42: النظام القديم | J42: نعم | K42: بدون تفصيل بنود في السجل
...

Sheet تفصيل البنود
A1: نوع الحركة | B1: رقم العقد | C1: التاريخ | D1: المصدر | E1: كود الصنف | F1: اسم الصنف | G1: الكمية | H1: الوحدة | I1: سعر الوحدة | J1: الإجمالي
A2: TNR | B2: TNR-3441 | C2: 46023 | D2: النظام القديم | E2: TN-OD456 | F2: دورانتا أخضر | G2: 1200 | H2: EA | I2: 2.5 | J2: 3450
A3: TNR | B3: TNR-3441 | C3: 46023 | D3: النظام القديم | E3: TN-OD454 | F3: تيكوماريا 50 سم | G3: 740 | H3: EA | I3: 2.5 | J3: 2127.5
A4: TNR | B4: TNR-3441 | C4: 46023 | D4: النظام القديم | E4: TN-OD458 | F4: اكاليفا | G4: 6 | H4: EA | I4: 25 | J4: 172.5
A5: TNR | B5: TNR-3441 | C5: 46023 | D5: النظام القديم | E5: TN-NPB | F5: حجر ديكورى ابيض مطفى :35 سم - 10 كجم | G5: 200 | H5: EA | I5: 11.5 | J5: 2645
B6: إجمالي TNR-3441 | G6: =SUM(G2:G5) | J6: =SUM(J2:J5)
A7: TNR | B7: TRF-0120 | C7: 46217 | D7: النظام الجديد | E7: OD373 | F7: سيسبانيا 1-2 متر | G7: 250 | H7: EA | I7: 25.5 | J7: 7331.25
B8: إجمالي TRF-0120 | G8: =SUM(G7:G7) | J8: =SUM(J7:J7)
A9: TNR | B9: TRF-0188 | C9: 46231 | D9: النظام الجديد | E9: FR368 | F9: بيرلايت 100 لتر | G9: 25 | H9: EA | I9: 32.5 | J9: 934.37
B10: إجمالي TRF-0188 | G10: =SUM(G9:G9) | J10: =SUM(J9:J9)
A11: RNT | B11: RNT-3434 | C11: 46026 | D11: النظام القديم | E11: RN-OD561 | F11: زهور مارى جولد | G11: 2000 | H11: EA | I11: 0.6 | J11: 1380
B12: إجمالي RNT-3434 | G12: =SUM(G11:G11) | J12: =SUM(J11:J11)
A13: RNT | B13: RNT-3604 | C13: 46042 | D13: النظام القديم | E13: RN-ID1501 | F13: ترادسكانتيا ان اس مركن19 سم عالقى | G13: 270 | H13: EA | I13: 8.5 | J13: 2639.25
A14: RNT | B14: RNT-3604 | C14: 46042 | D14: النظام القديم | E14: RN-OD694 | F14: كالنشو هولندى مركن12 سم | G14: 1500 | H14: EA | I14: 3 | J14: 5175
A15: RNT | B15: RNT-3604 | C15: 46042 | D15: النظام القديم | E15: RN-OD641 | F15: زهور قرنفل صيني مركن9 سم | G15: 1000 | H15: EA | I15: 0.6 | J15: 690
B16: إجمالي RNT-3604 | G16: =SUM(G13:G15) | J16: =SUM(J13:J15)
A17: RNT | B17: RNT-3805 | C17: 46064 | D17: النظام القديم | E17: RN-OD696 | F17: زهور اقحوان افريقي مركن9 سم | G17: 150 | H17: EA | I17: 1.5 | J17: 258.75
A18: RNT | B18: RNT-3805 | C18: 46064 | D18: النظام القديم | E18: RN-OD695 | F18: زهور اقحوان افريقي هولندى مركن12 سم | G18: 90 | H18: EA | I18: 3 | J18: 310.5
A19: RNT | B19: RNT-3805 | C19: 46064 | D19: النظام القديم | E19: RN-OD636 | F19: زهور منثور مركن9 سم | G19: 150 | H19: EA | I19: 0.55 | J19: 94.875
A20: RNT | B20: RNT-3805 | C20: 46064 | D20: النظام القديم | E20: RN-OD693 | F20: زهور جيرانيوم هولندى مركن12 سم | G20: 180 | H20: EA | I20: 3 | J20: 621
A21: RNT | B21: RNT-3805 | C21: 46064 | D21: النظام القديم | E21: RN-OD639 | F21: زهور قرنفل امريكي مركن12 سم | G21: 90 | H21: EA | I21: 2.5 | J21: 258.75
A22: RNT | B22: RNT-3805 | C22: 46064 | D22: النظام القديم | E22: RN-OD643 | F22: زهور سينيراريا مركن12 سم | G22: 48 | H22: EA | I22: 2.5 | J22: 138
B23: إجمالي RNT-3805 | G23: =SUM(G17:G22) | J23: =SUM(J17:J22)
A24: RNT | B24: TRF-0107 | C24: 46214 | D24: النظام الجديد | E24: ID1500 | F24: سكندابسس ان اس مركن 19 سم علاقي | G24: 300 | H24: EA | I24: 9.5 | J24: 3277.5
A25: RNT | B25: TRF-0107 | C25: 46214 | D25: النظام الجديد | E25: ID1504 | F25: هيدرا علاقي ان اس مركن 19 سم | G25: 100 | H25: EA | I25: 7 | J25: 805
A26: RNT | B26: TRF-0107 | C26: 46214 | D26: النظام الجديد | E26: OD373 | F26: سيسبانيا 1-2 متر | G26: 250 | H26: EA | I26: 25.5 | J26: 7331.25
A27: RNT | B27: TRF-0107 | C27: 46214 | D27: النظام الجديد | E27: OD456 | F27: دورانتا أخضر | G27: 1290 | H27: EA | I27: 2.5 | J27: 3708.75
A28: RNT | B28: TRF-0107 | C28: 46214 | D28: النظام الجديد | E28: OD458 | F28: اكاليفا | G28: 60 | H28: EA | I28: 2.5 | J28: 172.5
A29: RNT | B29: TRF-0107 | C29: 46214 | D29: النظام الجديد | E29: OD467 | F29: فل بلدي | G29: 450 | H29: EA | I29: 2.5 | J29: 1293.75
A30: RNT | B30: TRF-0107 | C30: 46214 | D30: النظام الجديد | E30: OD454 | F30: تيكوماريا 50 سم | G30: 2384 | H30: EA | I30: 2.5 | J30: 6854
A31: RNT | B31: TRF-0107 | C31: 46214 | D31: النظام الجديد | E31: OD491 | F31: ياسمين أزرق | G31: 580 | H31: EA | I31: 2.5 | J31: 1667.5
A32: RNT | B32: TRF-0107 | C32: 46214 | D32: النظام الجديد | E32: OD703 | F32: تجيل كروي مركن 9 سم | G32: 2400 | H32: EA | I32: 1.1 | J32: 3036
B33: إجمالي TRF-0107 | G33: =SUM(G24:G32) | J33: =SUM(J24:J32)
A34: RNT | B34: TRF-0122 | C34: 46217 | D34: النظام الجديد | E34: OD373 | F34: سيسبانيا 1-2 متر | G34: 240 | H34: EA | I34: 25.5 | J34: 7038
B35: إجمالي TRF-0122 | G35: =SUM(G34:G34) | J35: =SUM(J34:J34)
A36: RNP | B36: RNP-3432 | C36: 46026 | D36: النظام القديم | E36: RN-OD620 | F36: زهور جيرانيوم مركن12 سم | G36: 17900 | H36: EA | I36: 2 | J36: 41170
A37: RNP | B37: RNP-3432 | C37: 46026 | D37: النظام القديم | E37: RN-OD642 | F37: زهور اليسوم مركن9 سم | G37: 2000 | H37: EA | I37: 0.55 | J37: 1265
B38: إجمالي RNP-3432 | G38: =SUM(G36:G37) | J38: =SUM(J36:J37)
A39: RNP | B39: RNP-3433 | C39: 46026 | D39: النظام القديم | E39: RN-OD603 | F39: زهور جرانيوم مركن9 سم | G39: 1400 | H39: EA | I39: 0.9 | J39: 1449
A40: RNP | B40: RNP-3433 | C40: 46026 | D40: النظام القديم | E40: RN-OD560 | F40: زهور بيتونيا | G40: 1000 | H40: EA | I40: 0.55 | J40: 632.5
...

Sheet الكميات حسب الصنف
A1: نوع الحركة | B1: البيان | C1: كود الصنف | D1: اسم الصنف | E1: إجمالي الكمية | F1: إجمالي القيمة | G1: عدد العقود
A2: TNR | B2: ترحيل من تبوك إلى الرياض | C2: FR368 | D2: بيرلايت 100 لتر | E2: 25 | F2: 934.37 | G2: 1
A3: TNR | B3: ترحيل من تبوك إلى الرياض | C3: NPB | D3: حجر ديكورى ابيض مطفى :35 سم - 10 كجم | E3: 200 | F3: 2645 | G3: 1
A4: TNR | B4: ترحيل من تبوك إلى الرياض | C4: OD373 | D4: سيسبانيا 1-2 متر | E4: 250 | F4: 7331.25 | G4: 1
A5: TNR | B5: ترحيل من تبوك إلى الرياض | C5: OD454 | D5: تيكوماريا 50 سم | E5: 740 | F5: 2127.5 | G5: 1
A6: TNR | B6: ترحيل من تبوك إلى الرياض | C6: OD456 | D6: دورانتا أخضر | E6: 1200 | F6: 3450 | G6: 1
A7: TNR | B7: ترحيل من تبوك إلى الرياض | C7: OD458 | D7: اكاليفا | E7: 6 | F7: 172.5 | G7: 1
B8: إجمالي ترحيل من تبوك إلى الرياض | E8: =SUM(E2:E7) | F8: =SUM(F2:F7)
A9: RNT | B9: ترحيل من الرياض إلى تبوك | C9: ID1500 | D9: سكندابسس ان اس مركن 19 سم علاقي | E9: 300 | F9: 3277.5 | G9: 1
A10: RNT | B10: ترحيل من الرياض إلى تبوك | C10: ID1501 | D10: ترادسكانتيا ان اس مركن19 سم عالقى | E10: 270 | F10: 2639.25 | G10: 1
A11: RNT | B11: ترحيل من الرياض إلى تبوك | C11: ID1504 | D11: هيدرا علاقي ان اس مركن 19 سم | E11: 100 | F11: 805 | G11: 1
A12: RNT | B12: ترحيل من الرياض إلى تبوك | C12: OD373 | D12: سيسبانيا 1-2 متر | E12: 490 | F12: 14369.25 | G12: 2
A13: RNT | B13: ترحيل من الرياض إلى تبوك | C13: OD454 | D13: تيكوماريا 50 سم | E13: 2384 | F13: 6854 | G13: 1
A14: RNT | B14: ترحيل من الرياض إلى تبوك | C14: OD456 | D14: دورانتا أخضر | E14: 1290 | F14: 3708.75 | G14: 1
A15: RNT | B15: ترحيل من الرياض إلى تبوك | C15: OD458 | D15: اكاليفا | E15: 60 | F15: 172.5 | G15: 1
A16: RNT | B16: ترحيل من الرياض إلى تبوك | C16: OD467 | D16: فل بلدي | E16: 450 | F16: 1293.75 | G16: 1
A17: RNT | B17: ترحيل من الرياض إلى تبوك | C17: OD491 | D17: ياسمين أزرق | E17: 580 | F17: 1667.5 | G17: 1
A18: RNT | B18: ترحيل من الرياض إلى تبوك | C18: OD561 | D18: زهور مارى جولد | E18: 2000 | F18: 1380 | G18: 1
A19: RNT | B19: ترحيل من الرياض إلى تبوك | C19: OD636 | D19: زهور منثور مركن9 سم | E19: 150 | F19: 94.88 | G19: 1
A20: RNT | B20: ترحيل من الرياض إلى تبوك | C20: OD639 | D20: زهور قرنفل امريكي مركن12 سم | E20: 90 | F20: 258.75 | G20: 1
... A27: RNT | B27: ترحيل من الرياض إلى تبوك | C27: OD703 | D27: تجيل كروي مركن 9 سم | E27: 2400 | F27: 3036 | G27: 1
B28: إجمالي ترحيل من الرياض إلى تبوك | E28: =SUM(E9:E27) | F28: =SUM(F9:F27)
A29: RNP | B29: ترحيل إلى قسم المشاريع تبوك | C29: ID1501 | D29: ترادسكانتيا ان اس مركن 19 سم علاقى | E29: 25 | F29: 237.5 | G29: 1
A30: RNP | B30: ترحيل إلى قسم المشاريع تبوك | C30: OD371 | D30: اكاسيا جلوكا 1-2 متر | E30: 156 | F30: 3978 | G30: 2
A31: RNP | B31: ترحيل إلى قسم المشاريع تبوك | C31: OD404 | D31: فيكس بندا 50 سم | E31: 10 | F31: 25 | G31: 1
A32: RNP | B32: ترحيل إلى قسم المشاريع تبوك | C32: OD411 | D32: ياسمين هندي كبير | E32: 20 | F32: 747.5 | G32: 1
A33: RNP | B33: ترحيل إلى قسم المشاريع تبوك | C33: OD454 | D33: تيكوماريا 50 سم | E33: 250 | F33: 625 | G33: 1
A34: RNP | B34: ترحيل إلى قسم المشاريع تبوك | C34: OD456 | D34: دورانتا اخضر | E34: 1200 | F34: 3450 | G34: 1
A35: RNP | B35: ترحيل إلى قسم المشاريع تبوك | C35: OD462 | D35: رويليا | E35: 94 | F35: 235 | G35: 1
A36: RNP | B36: ترحيل إلى قسم المشاريع تبوك | C36: OD479 | D36: جهنمية بلدى واحد عود 1 متر | E36: 10 | F36: 60 | G36: 1
A37: RNP | B37: ترحيل إلى قسم المشاريع تبوك | C37: OD486 | D37: جهنمية كروية تايلندى صغير | E37: 2 | F37: 463 | G37: 1
A38: RNP | B38: ترحيل إلى قسم المشاريع تبوك | C38: OD487 | D38: جهنمية كروية تايلندى كبير | E38: 5 | F38: 1312.5 | G38: 1
A39: RNP | B39: ترحيل إلى قسم المشاريع تبوك | C39: OD501 | D39: نخيل سايكس 40 سم | E39: 3 | F39: 1191 | G39: 1
A40: RNP | B40: ترحيل إلى قسم المشاريع تبوك | C40: OD560 | D40: زهور بيتونيا | E40: 9512 | F40: 6016.34 | G40: 4
... A66: RNP | B66: ترحيل إلى قسم المشاريع تبوك | C66: SF99 | D66: فينكا روزا مركن 9 سم أحمر نقطة بيضاء | E66: 2450 | F66: 1347.5 | G66: 4
B67: إجمالي ترحيل إلى قسم المشاريع تبوك | E67: =SUM(E29:E66) | F67: =SUM(F29:F66)
A68: RNO | B68: صرف مواد للإنتاج – مزرعة الرياض | C68: FR1004 | D68: حديد مخلبي 16 كجم | E68: 3 | F68: 207 | G68: 3
A69: RNO | B69: صرف مواد للإنتاج – مزرعة الرياض | C69: FR1017 | D69: بوتنج سويل 70 لتر (KLAS) | E69: 87 | F69: 4429.8 | G69: 8
A70: RNO | B70: صرف مواد للإنتاج – مزرعة الرياض | C70: FR1018 | D70: فيرموكلايت 100 لتر | E70: 11 | F70: 903.75 | G70: 6
A71: RNO | B71: صرف مواد للإنتاج – مزرعة الرياض | C71: FR1022 | D71: اجري فير شيلات حديد 6% 1 كجم | E71: 4 | F71: 172 | G71: 4
...
